Workbook

Sheet 설정
A1: 예비고1 반편성고사 — 설정
A2: 노란 칸만 입력하세요. 반 이름·정원·반영비율·단원명을 바꾸면 모든 시트에 자동 반영됩니다. 정답·배점·단원·난이도는 '공수1', '공수2' 시트 위쪽(2~5행)에서 입력합니다.
A4: ① 반 설정
A5: 반 | B5: 반 이름 | C5: 정원(명)
A6: 1반(성적순) | B6: 심화반 | C6: 20 | E6: 총점 석차 순으로 1반 정원만큼 → 1반, 다음 정원만큼 → 2반, 나머지 → 3반. 동점자가 경계에 걸리면 모두 위 반으로 들어갑니다.
A7: 2반(성적순) | B7: 정규반 | C7: 20
A8: 3반(성적순) | B8: 기본반 | C8: 20
A9: 합계 | C9: =SUM(C6:C8) -> 60
A11: ② 점수 반영
B12: 항목 | C12: 값
B13: 공통수학1 반영비율 | C13: 1 | E13: 환산총점 = 공수1 점수×비율 + 공수2 점수×비율
B14: 공통수학2 반영비율 | C14: 1 | E14: 예) 공수1을 더 중시하려면 1.5 / 1 처럼 입력
B15: 경계 범위(점) | C15: 5 | E15: 반 컷 점수와의 차이가 이 값 이내면 '경계'로 표시 → 상담·재검토 대상
A17: ③ 단원 목록 · 출제 설계 확인
A18: 과목 | B18: 단원 | C18: 문항 수 | D18: 배점 합 | E18: 포함 내용(2022 개정)
A19: 공통수학1 | B19: 다항식 | C19: =COUNTIF(공수1!$D$4:$W$4,B19) -> 5 | D19: =SUMIF(공수1!$D$4:$W$4,B19,공수1!$D$3:$W$3) -> 25 | E19: 다항식의 연산, 나머지정리, 인수분해
A20: 공통수학1 | B20: 방정식과 부등식 | C20: =COUNTIF(공수1!$D$4:$W$4,B20) -> 8 | D20: =SUMIF(공수1!$D$4:$W$4,B20,공수1!$D$3:$W$3) -> 40 | E20: 복소수, 이차방정식, 이차함수, 여러 가지 방정식·부등식
A21: 공통수학1 | B21: 경우의 수 | C21: =COUNTIF(공수1!$D$4:$W$4,B21) -> 4 | D21: =SUMIF(공수1!$D$4:$W$4,B21,공수1!$D$3:$W$3) -> 20 | E21: 합·곱의 법칙, 순열, 조합
A22: 공통수학1 | B22: 행렬 | C22: =COUNTIF(공수1!$D$4:$W$4,B22) -> 3 | D22: =SUMIF(공수1!$D$4:$W$4,B22,공수1!$D$3:$W$3) -> 15 | E22: 행렬과 그 연산
A23: 공통수학1 | B23: 합계 | C23: =SUM(C19:C22) -> 20 | D23: =SUM(D19:D22) -> 100 | E23: ← 문항 수 20, 배점 합 100인지 확인
A24: 공통수학2 | B24: 도형의 방정식 | C24: =COUNTIF(공수2!$D$4:$W$4,B24) -> 8 | D24: =SUMIF(공수2!$D$4:$W$4,B24,공수2!$D$3:$W$3) -> 40 | E24: 평면좌표, 직선·원의 방정식, 도형의 이동
A25: 공통수학2 | B25: 집합과 명제 | C25: =COUNTIF(공수2!$D$4:$W$4,B25) -> 6 | D25: =SUMIF(공수2!$D$4:$W$4,B25,공수2!$D$3:$W$3) -> 30 | E25: 집합, 명제
A26: 공통수학2 | B26: 함수와 그래프 | C26: =COUNTIF(공수2!$D$4:$W$4,B26) -> 6 | D26: =SUMIF(공수2!$D$4:$W$4,B26,공수2!$D$3:$W$3) -> 30 | E26: 함수, 합성·역함수, 유리·무리함수
A27: 공통수학2 | B27: 합계 | C27: =SUM(C24:C26) -> 20 | D27: =SUM(D24:D26) -> 100 | E27: ← 문항 수 20, 배점 합 100인지 확인

Sheet 학생명단
A1: 학생 명단
A2: 노란 칸에 학생 정보를 입력하세요. 여기 입력한 순서(행)가 공수1·공수2·반배정 시트의 행과 그대로 연결됩니다. 7행은 예시이니 지우고 사용하세요.
A6: No | B6: 이름 | C6: 학교 | D6: 구분 | E6: 연락처 | F6: 비고
A7: 1 | B7: 홍길동(예시) | C7: OO중 | D7: 외부 | E7: 010-0000-0000 | F7: 예시 행 — 삭제 후 사용
A8: 2
A9: 3
A10: 4
A11: 5
A12: 6
A13: 7
A14: 8
A15: 9
A16: 10
A17: 11
A18: 12
A19: 13
... A86: 80

Sheet 공수1
A1: 공통수학1 채점표 | D1: ① 2~5행(노란 칸)에 정답·배점·단원·난이도 입력 ② 학생 행에 학생이 쓴 답을 그대로 입력(객관식 1~5, 단답형 0~999) → 틀린 답은 빨간 칸, 점수 자동 계산. 결시생은 비워두면 미응시 처리.
A2: 정답 ▶
A3: 배점 ▶ | D3: 5 | E3: 5 | F3: 5 | G3: 5 | H3: 5 | I3: 5 | J3: 5 | K3: 5 | L3: 5 | M3: 5 | N3: 5 | O3: 5 | P3: 5 | Q3: 5 | R3: 5 | S3: 5 | T3: 5 | U3: 5 | V3: 5 | W3: 5 | X3: =COUNT(D2:W2) -> 0 | Y3: =SUM(D3:W3) -> 100 | Z3: =SUMIF($D$4:$W$4,Z$6,$D$3:$W$3) -> 25 | AA3: =SUMIF($D$4:$W$4,AA$6,$D$3:$W$3) -> 40 | AB3: =SUMIF($D$4:$W$4,AB$6,$D$3:$W$3) -> 20 | AC3: =SUMIF($D$4:$W$4,AC$6,$D$3:$W$3) -> 15
A4: 단원 ▶ | D4: 다항식 | E4: 다항식 | F4: 다항식 | G4: 다항식 | H4: 다항식 | I4: 방정식과 부등식 | J4: 방정식과 부등식 | K4: 방정식과 부등식 | L4: 방정식과 부등식 | M4: 방정식과 부등식 | N4: 방정식과 부등식 | O4: 방정식과 부등식 | P4: 방정식과 부등식 | Q4: 경우의 수 | R4: 경우의 수 | S4: 경우의 수 | T4: 경우의 수 | U4: 행렬 | V4: 행렬 | W4: 행렬
A5: 난이도 ▶ | D5: 하 | E5: 하 | F5: 하 | G5: 하 | H5: 하 | I5: 중 | J5: 중 | K5: 중 | L5: 중 | M5: 중 | N5: 중 | O5: 상 | P5: 상 | Q5: 상 | R5: 하 | S5: 중 | T5: 중 | U5: 상 | V5: 상 | W5: 최상 | X5: 정답입력수▲ | Y5: 만점 ▲ | Z5: 만점 ▲ | AA5: 만점 ▲ | AB5: 만점 ▲ | AC5: 만점 ▲
A6: No | B6: 이름 | C6: 학교 | D6: 1 객관식 | E6: 2 객관식 | F6: 3 객관식 | G6: 4 객관식 | H6: 5 객관식 | I6: 6 객관식 | J6: 7 객관식 | K6: 8 객관식 | L6: 9 객관식 | M6: 10 객관식 | N6: 11 객관식 | O6: 12 객관식 | P6: 13 객관식 | Q6: 14 객관식 | R6: 15 단답형 | S6: 16 단답형 | T6: 17 단답형 | U6: 18 단답형 | V6: 19 단답형 | W6: 20 단답형 | X6: 맞힌 개수 | Y6: 총점 | Z6: =설정!B19 -> 다항식 | AA6: =설정!B20 -> 방정식과 부등식 | AB6: =설정!B21 -> 경우의 수 | AC6: =설정!B22 -> 행렬
A7: 1 | B7: =IF(학생명단!B7="","",학생명단!B7) -> 홍길동(예시) | C7: =IF(학생명단!C7="","",학생명단!C7) -> OO중 | X7: =IF(COUNTA(D7:W7)=0,"",SUMPRODUCT((D7:W7=$D$2:$W$2)*(D7:W7<>""))) | Y7: =IF(COUNTA(D7:W7)=0,"",SUMPRODUCT((D7:W7=$D$2:$W$2)*(D7:W7<>"")*$D$3:$W$3)) | Z7: =IF($Y7="","",SUMPRODUCT(($D7:$W7=$D$2:$W$2)*($D7:$W7<>"")*$D$3:$W$3*($D$4:$W$4=Z$6))) | AA7: =IF($Y7="","",SUMPRODUCT(($D7:$W7=$D$2:$W$2)*($D7:$W7<>"")*$D$3:$W$3*($D$4:$W$4=AA$6))) | AB7: =IF($Y7="","",SUMPRODUCT(($D7:$W7=$D$2:$W$2)*($D7:$W7<>"")*$D$3:$W$3*($D$4:$W$4=AB$6))) | AC7: =IF($Y7="","",SUMPRODUCT(($D7:$W7=$D$2:$W$2)*($D7:$W7<>"")*$D$3:$W$3*($D$4:$W$4=AC$6)))
A8: 2 | B8: =IF(학생명단!B8="","",학생명단!B8) | C8: =IF(학생명단!C8="","",학생명단!C8) | X8: =IF(COUNTA(D8:W8)=0,"",SUMPRODUCT((D8:W8=$D$2:$W$2)*(D8:W8<>""))) | Y8: =IF(COUNTA(D8:W8)=0,"",SUMPRODUCT((D8:W8=$D$2:$W$2)*(D8:W8<>"")*$D$3:$W$3)) | Z8: =IF($Y8="","",SUMPRODUCT(($D8:$W8=$D$2:$W$2)*($D8:$W8<>"")*$D$3:$W$3*($D$4:$W$4=Z$6))) | AA8: =IF($Y8="","",SUMPRODUCT(($D8:$W8=$D$2:$W$2)*($D8:$W8<>"")*$D$3:$W$3*($D$4:$W$4=AA$6))) | AB8: =IF($Y8="","",SUMPRODUCT(($D8:$W8=$D$2:$W$2)*($D8:$W8<>"")*$D$3:$W$3*($D$4:$W$4=AB$6))) | AC8: =IF($Y8="","",SUMPRODUCT(($D8:$W8=$D$2:$W$2)*($D8:$W8<>"")*$D$3:$W$3*($D$4:$W$4=AC$6)))
A9: 3 | B9: =IF(학생명단!B9="","",학생명단!B9) | C9: =IF(학생명단!C9="","",학생명단!C9) | X9: =IF(COUNTA(D9:W9)=0,"",SUMPRODUCT((D9:W9=$D$2:$W$2)*(D9:W9<>""))) | Y9: =IF(COUNTA(D9:W9)=0,"",SUMPRODUCT((D9:W9=$D$2:$W$2)*(D9:W9<>"")*$D$3:$W$3)) | Z9: =IF($Y9="","",SUMPRODUCT(($D9:$W9=$D$2:$W$2)*($D9:$W9<>"")*$D$3:$W$3*($D$4:$W$4=Z$6))) | AA9: =IF($Y9="","",SUMPRODUCT(($D9:$W9=$D$2:$W$2)*($D9:$W9<>"")*$D$3:$W$3*($D$4:$W$4=AA$6))) | AB9: =IF($Y9="","",SUMPRODUCT(($D9:$W9=$D$2:$W$2)*($D9:$W9<>"")*$D$3:$W$3*($D$4:$W$4=AB$6))) | AC9: =IF($Y9="","",SUMPRODUCT(($D9:$W9=$D$2:$W$2)*($D9:$W9<>"")*$D$3:$W$3*($D$4:$W$4=AC$6)))
A10: 4 | B10: =IF(학생명단!B10="","",학생명단!B10) | C10: =IF(학생명단!C10="","",학생명단!C10) | X10: =IF(COUNTA(D10:W10)=0,"",SUMPRODUCT((D10:W10=$D$2:$W$2)*(D10:W10<>""))) | Y10: =IF(COUNTA(D10:W10)=0,"",SUMPRODUCT((D10:W10=$D$2:$W$2)*(D10:W10<>"")*$D$3:$W$3)) | Z10: =IF($Y10="","",SUMPRODUCT(($D10:$W10=$D$2:$W$2)*($D10:$W10<>"")*$D$3:$W$3*($D$4:$W$4=Z$6))) | AA10: =IF($Y10="","",SUMPRODUCT(($D10:$W10=$D$2:$W$2)*($D10:$W10<>"")*$D$3:$W$3*($D$4:$W$4=AA$6))) | AB10: =IF($Y10="","",SUMPRODUCT(($D10:$W10=$D$2:$W$2)*($D10:$W10<>"")*$D$3:$W$3*($D$4:$W$4=AB$6))) | AC10: =IF($Y10="","",SUMPRODUCT(($D10:$W10=$D$2:$W$2)*($D10:$W10<>"")*$D$3:$W$3*($D$4:$W$4=AC$6)))
A11: 5 | B11: =IF(학생명단!B11="","",학생명단!B11) | C11: =IF(학생명단!C11="","",학생명단!C11) | X11: =IF(COUNTA(D11:W11)=0,"",SUMPRODUCT((D11:W11=$D$2:$W$2)*(D11:W11<>""))) | Y11: =IF(COUNTA(D11:W11)=0,"",SUMPRODUCT((D11:W11=$D$2:$W$2)*(D11:W11<>"")*$D$3:$W$3)) | Z11: =IF($Y11="","",SUMPRODUCT(($D11:$W11=$D$2:$W$2)*($D11:$W11<>"")*$D$3:$W$3*($D$4:$W$4=Z$6))) | AA11: =IF($Y11="","",SUMPRODUCT(($D11:$W11=$D$2:$W$2)*($D11:$W11<>"")*$D$3:$W$3*($D$4:$W$4=AA$6))) | AB11: =IF($Y11="","",SUMPRODUCT(($D11:$W11=$D$2:$W$2)*($D11:$W11<>"")*$D$3:$W$3*($D$4:$W$4=AB$6))) | AC11: =IF($Y11="","",SUMPRODUCT(($D11:$W11=$D$2:$W$2)*($D11:$W11<>"")*$D$3:$W$3*($D$4:$W$4=AC$6)))
A12: 6 | B12: =IF(학생명단!B12="","",학생명단!B12) | C12: =IF(학생명단!C12="","",학생명단!C12) | X12: =IF(COUNTA(D12:W12)=0,"",SUMPRODUCT((D12:W12=$D$2:$W$2)*(D12:W12<>""))) | Y12: =IF(COUNTA(D12:W12)=0,"",SUMPRODUCT((D12:W12=$D$2:$W$2)*(D12:W12<>"")*$D$3:$W$3)) | Z12: =IF($Y12="","",SUMPRODUCT(($D12:$W12=$D$2:$W$2)*($D12:$W12<>"")*$D$3:$W$3*($D$4:$W$4=Z$6))) | AA12: =IF($Y12="","",SUMPRODUCT(($D12:$W12=$D$2:$W$2)*($D12:$W12<>"")*$D$3:$W$3*($D$4:$W$4=AA$6))) | AB12: =IF($Y12="","",SUMPRODUCT(($D12:$W12=$D$2:$W$2)*($D12:$W12<>"")*$D$3:$W$3*($D$4:$W$4=AB$6))) | AC12: =IF($Y12="","",SUMPRODUCT(($D12:$W12=$D$2:$W$2)*($D12:$W12<>"")*$D$3:$W$3*($D$4:$W$4=AC$6)))
A13: 7 | B13: =IF(학생명단!B13="","",학생명단!B13) | C13: =IF(학생명단!C13="","",학생명단!C13) | X13: =IF(COUNTA(D13:W13)=0,"",SUMPRODUCT((D13:W13=$D$2:$W$2)*(D13:W13<>""))) | Y13: =IF(COUNTA(D13:W13)=0,"",SUMPRODUCT((D13:W13=$D$2:$W$2)*(D13:W13<>"")*$D$3:$W$3)) | Z13: =IF($Y13="","",SUMPRODUCT(($D13:$W13=$D$2:$W$2)*($D13:$W13<>"")*$D$3:$W$3*($D$4:$W$4=Z$6))) | AA13: =IF($Y13="","",SUMPRODUCT(($D13:$W13=$D$2:$W$2)*($D13:$W13<>"")*$D$3:$W$3*($D$4:$W$4=AA$6))) | AB13: =IF($Y13="","",SUMPRODUCT(($D13:$W13=$D$2:$W$2)*($D13:$W13<>"")*$D$3:$W$3*($D$4:$W$4=AB$6))) | AC13: =IF($Y13="","",SUMPRODUCT(($D13:$W13=$D$2:$W$2)*($D13:$W13<>"")*$D$3:$W$3*($D$4:$W$4=AC$6)))
A14: 8 | B14: =IF(학생명단!B14="","",학생명단!B14) | C14: =IF(학생명단!C14="","",학생명단!C14) | X14: =IF(COUNTA(D14:W14)=0,"",SUMPRODUCT((D14:W14=$D$2:$W$2)*(D14:W14<>""))) | Y14: =IF(COUNTA(D14:W14)=0,"",SUMPRODUCT((D14:W14=$D$2:$W$2)*(D14:W14<>"")*$D$3:$W$3)) | Z14: =IF($Y14="","",SUMPRODUCT(($D14:$W14=$D$2:$W$2)*($D14:$W14<>"")*$D$3:$W$3*($D$4:$W$4=Z$6))) | AA14: =IF($Y14="","",SUMPRODUCT(($D14:$W14=$D$2:$W$2)*($D14:$W14<>"")*$D$3:$W$3*($D$4:$W$4=AA$6))) | AB14: =IF($Y14="","",SUMPRODUCT(($D14:$W14=$D$2:$W$2)*($D14:$W14<>"")*$D$3:$W$3*($D$4:$W$4=AB$6))) | AC14: =IF($Y14="","",SUMPRODUCT(($D14:$W14=$D$2:$W$2)*($D14:$W14<>"")*$D$3:$W$3*($D$4:$W$4=AC$6)))
A15: 9 | B15: =IF(학생명단!B15="","",학생명단!B15) | C15: =IF(학생명단!C15="","",학생명단!C15) | X15: =IF(COUNTA(D15:W15)=0,"",SUMPRODUCT((D15:W15=$D$2:$W$2)*(D15:W15<>""))) | Y15: =IF(COUNTA(D15:W15)=0,"",SUMPRODUCT((D15:W15=$D$2:$W$2)*(D15:W15<>"")*$D$3:$W$3)) | Z15: =IF($Y15="","",SUMPRODUCT(($D15:$W15=$D$2:$W$2)*($D15:$W15<>"")*$D$3:$W$3*($D$4:$W$4=Z$6))) | AA15: =IF($Y15="","",SUMPRODUCT(($D15:$W15=$D$2:$W$2)*($D15:$W15<>"")*$D$3:$W$3*($D$4:$W$4=AA$6))) | AB15: =IF($Y15="","",SUMPRODUCT(($D15:$W15=$D$2:$W$2)*($D15:$W15<>"")*$D$3:$W$3*($D$4:$W$4=AB$6))) | AC15: =IF($Y15="","",SUMPRODUCT(($D15:$W15=$D$2:$W$2)*($D15:$W15<>"")*$D$3:$W$3*($D$4:$W$4=AC$6)))
A16: 10 | B16: =IF(학생명단!B16="","",학생명단!B16) | C16: =IF(학생명단!C16="","",학생명단!C16) | X16: =IF(COUNTA(D16:W16)=0,"",SUMPRODUCT((D16:W16=$D$2:$W$2)*(D16:W16<>""))) | Y16: =IF(COUNTA(D16:W16)=0,"",SUMPRODUCT((D16:W16=$D$2:$W$2)*(D16:W16<>"")*$D$3:$W$3)) | Z16: =IF($Y16="","",SUMPRODUCT(($D16:$W16=$D$2:$W$2)*($D16:$W16<>"")*$D$3:$W$3*($D$4:$W$4=Z$6))) | AA16: =IF($Y16="","",SUMPRODUCT(($D16:$W16=$D$2:$W$2)*($D16:$W16<>"")*$D$3:$W$3*($D$4:$W$4=AA$6))) | AB16: =IF($Y16="","",SUMPRODUCT(($D16:$W16=$D$2:$W$2)*($D16:$W16<>"")*$D$3:$W$3*($D$4:$W$4=AB$6))) | AC16: =IF($Y16="","",SUMPRODUCT(($D16:$W16=$D$2:$W$2)*($D16:$W16<>"")*$D$3:$W$3*($D$4:$W$4=AC$6)))
A17: 11 | B17: =IF(학생명단!B17="","",학생명단!B17) | C17: =IF(학생명단!C17="","",학생명단!C17) | X17: =IF(COUNTA(D17:W17)=0,"",SUMPRODUCT((D17:W17=$D$2:$W$2)*(D17:W17<>""))) | Y17: =IF(COUNTA(D17:W17)=0,"",SUMPRODUCT((D17:W17=$D$2:$W$2)*(D17:W17<>"")*$D$3:$W$3)) | Z17: =IF($Y17="","",SUMPRODUCT(($D17:$W17=$D$2:$W$2)*($D17:$W17<>"")*$D$3:$W$3*($D$4:$W$4=Z$6))) | AA17: =IF($Y17="","",SUMPRODUCT(($D17:$W17=$D$2:$W$2)*($D17:$W17<>"")*$D$3:$W$3*($D$4:$W$4=AA$6))) | AB17: =IF($Y17="","",SUMPRODUCT(($D17:$W17=$D$2:$W$2)*($D17:$W17<>"")*$D$3:$W$3*($D$4:$W$4=AB$6))) | AC17: =IF($Y17="","",SUMPRODUCT(($D17:$W17=$D$2:$W$2)*($D17:$W17<>"")*$D$3:$W$3*($D$4:$W$4=AC$6)))
A18: 12 | B18: =IF(학생명단!B18="","",학생명단!B18) | C18: =IF(학생명단!C18="","",학생명단!C18) | X18: =IF(COUNTA(D18:W18)=0,"",SUMPRODUCT((D18:W18=$D$2:$W$2)*(D18:W18<>""))) | Y18: =IF(COUNTA(D18:W18)=0,"",SUMPRODUCT((D18:W18=$D$2:$W$2)*(D18:W18<>"")*$D$3:$W$3)) | Z18: =IF($Y18="","",SUMPRODUCT(($D18:$W18=$D$2:$W$2)*($D18:$W18<>"")*$D$3:$W$3*($D$4:$W$4=Z$6))) | AA18: =IF($Y18="","",SUMPRODUCT(($D18:$W18=$D$2:$W$2)*($D18:$W18<>"")*$D$3:$W$3*($D$4:$W$4=AA$6))) | AB18: =IF($Y18="","",SUMPRODUCT(($D18:$W18=$D$2:$W$2)*($D18:$W18<>"")*$D$3:$W$3*($D$4:$W$4=AB$6))) | AC18: =IF($Y18="","",SUMPRODUCT(($D18:$W18=$D$2:$W$2)*($D18:$W18<>"")*$D$3:$W$3*($D$4:$W$4=AC$6)))
... A86: 80 | B86: =IF(학생명단!B86="","",학생명단!B86) | C86: =IF(학생명단!C86="","",학생명단!C86) | X86: =IF(COUNTA(D86:W86)=0,"",SUMPRODUCT((D86:W86=$D$2:$W$2)*(D86:W86<>""))) | Y86: =IF(COUNTA(D86:W86)=0,"",SUMPRODUCT((D86:W86=$D$2:$W$2)*(D86:W86<>"")*$D$3:$W$3)) | Z86: =IF($Y86="","",SUMPRODUCT(($D86:$W86=$D$2:$W$2)*($D86:$W86<>"")*$D$3:$W$3*($D$4:$W$4=Z$6))) | AA86: =IF($Y86="","",SUMPRODUCT(($D86:$W86=$D$2:$W$2)*($D86:$W86<>"")*$D$3:$W$3*($D$4:$W$4=AA$6))) | AB86: =IF($Y86="","",SUMPRODUCT(($D86:$W86=$D$2:$W$2)*($D86:$W86<>"")*$D$3:$W$3*($D$4:$W$4=AB$6))) | AC86: =IF($Y86="","",SUMPRODUCT(($D86:$W86=$D$2:$W$2)*($D86:$W86<>"")*$D$3:$W$3*($D$4:$W$4=AC$6)))

Sheet 공수2
A1: 공통수학2 채점표 | D1: ① 2~5행(노란 칸)에 정답·배점·단원·난이도 입력 ② 학생 행에 학생이 쓴 답을 그대로 입력(객관식 1~5, 단답형 0~999) → 틀린 답은 빨간 칸, 점수 자동 계산. 결시생은 비워두면 미응시 처리.
A2: 정답 ▶
A3: 배점 ▶ | D3: 5 | E3: 5 | F3: 5 | G3: 5 | H3: 5 | I3: 5 | J3: 5 | K3: 5 | L3: 5 | M3: 5 | N3: 5 | O3: 5 | P3: 5 | Q3: 5 | R3: 5 | S3: 5 | T3: 5 | U3: 5 | V3: 5 | W3: 5 | X3: =COUNT(D2:W2) -> 0 | Y3: =SUM(D3:W3) -> 100 | Z3: =SUMIF($D$4:$W$4,Z$6,$D$3:$W$3) -> 40 | AA3: =SUMIF($D$4:$W$4,AA$6,$D$3:$W$3) -> 30 | AB3: =SUMIF($D$4:$W$4,AB$6,$D$3:$W$3) -> 30
A4: 단원 ▶ | D4: 도형의 방정식 | E4: 도형의 방정식 | F4: 도형의 방정식 | G4: 도형의 방정식 | H4: 도형의 방정식 | I4: 도형의 방정식 | J4: 도형의 방정식 | K4: 도형의 방정식 | L4: 집합과 명제 | M4: 집합과 명제 | N4: 집합과 명제 | O4: 집합과 명제 | P4: 집합과 명제 | Q4: 집합과 명제 | R4: 함수와 그래프 | S4: 함수와 그래프 | T4: 함수와 그래프 | U4: 함수와 그래프 | V4: 함수와 그래프 | W4: 함수와 그래프
A5: 난이도 ▶ | D5: 하 | E5: 하 | F5: 하 | G5: 하 | H5: 하 | I5: 중 | J5: 중 | K5: 중 | L5: 중 | M5: 중 | N5: 중 | O5: 상 | P5: 상 | Q5: 상 | R5: 하 | S5: 중 | T5: 중 | U5: 상 | V5: 상 | W5: 최상 | X5: 정답입력수▲ | Y5: 만점 ▲ | Z5: 만점 ▲ | AA5: 만점 ▲ | AB5: 만점 ▲
A6: No | B6: 이름 | C6: 학교 | D6: 1 객관식 | E6: 2 객관식 | F6: 3 객관식 | G6: 4 객관식 | H6: 5 객관식 | I6: 6 객관식 | J6: 7 객관식 | K6: 8 객관식 | L6: 9 객관식 | M6: 10 객관식 | N6: 11 객관식 | O6: 12 객관식 | P6: 13 객관식 | Q6: 14 객관식 | R6: 15 단답형 | S6: 16 단답형 | T6: 17 단답형 | U6: 18 단답형 | V6: 19 단답형 | W6: 20 단답형 | X6: 맞힌 개수 | Y6: 총점 | Z6: =설정!B24 -> 도형의 방정식 | AA6: =설정!B25 -> 집합과 명제 | AB6: =설정!B26 -> 함수와 그래프
A7: 1 | B7: =IF(학생명단!B7="","",학생명단!B7) -> 홍길동(예시) | C7: =IF(학생명단!C7="","",학생명단!C7) -> OO중 | X7: =IF(COUNTA(D7:W7)=0,"",SUMPRODUCT((D7:W7=$D$2:$W$2)*(D7:W7<>""))) | Y7: =IF(COUNTA(D7:W7)=0,"",SUMPRODUCT((D7:W7=$D$2:$W$2)*(D7:W7<>"")*$D$3:$W$3)) | Z7: =IF($Y7="","",SUMPRODUCT(($D7:$W7=$D$2:$W$2)*($D7:$W7<>"")*$D$3:$W$3*($D$4:$W$4=Z$6))) | AA7: =IF($Y7="","",SUMPRODUCT(($D7:$W7=$D$2:$W$2)*($D7:$W7<>"")*$D$3:$W$3*($D$4:$W$4=AA$6))) | AB7: =IF($Y7="","",SUMPRODUCT(($D7:$W7=$D$2:$W$2)*($D7:$W7<>"")*$D$3:$W$3*($D$4:$W$4=AB$6)))
A8: 2 | B8: =IF(학생명단!B8="","",학생명단!B8) | C8: =IF(학생명단!C8="","",학생명단!C8) | X8: =IF(COUNTA(D8:W8)=0,"",SUMPRODUCT((D8:W8=$D$2:$W$2)*(D8:W8<>""))) | Y8: =IF(COUNTA(D8:W8)=0,"",SUMPRODUCT((D8:W8=$D$2:$W$2)*(D8:W8<>"")*$D$3:$W$3)) | Z8: =IF($Y8="","",SUMPRODUCT(($D8:$W8=$D$2:$W$2)*($D8:$W8<>"")*$D$3:$W$3*($D$4:$W$4=Z$6))) | AA8: =IF($Y8="","",SUMPRODUCT(($D8:$W8=$D$2:$W$2)*($D8:$W8<>"")*$D$3:$W$3*($D$4:$W$4=AA$6))) | AB8: =IF($Y8="","",SUMPRODUCT(($D8:$W8=$D$2:$W$2)*($D8:$W8<>"")*$D$3:$W$3*($D$4:$W$4=AB$6)))
A9: 3 | B9: =IF(학생명단!B9="","",학생명단!B9) | C9: =IF(학생명단!C9="","",학생명단!C9) | X9: =IF(COUNTA(D9:W9)=0,"",SUMPRODUCT((D9:W9=$D$2:$W$2)*(D9:W9<>""))) | Y9: =IF(COUNTA(D9:W9)=0,"",SUMPRODUCT((D9:W9=$D$2:$W$2)*(D9:W9<>"")*$D$3:$W$3)) | Z9: =IF($Y9="","",SUMPRODUCT(($D9:$W9=$D$2:$W$2)*($D9:$W9<>"")*$D$3:$W$3*($D$4:$W$4=Z$6))) | AA9: =IF($Y9="","",SUMPRODUCT(($D9:$W9=$D$2:$W$2)*($D9:$W9<>"")*$D$3:$W$3*($D$4:$W$4=AA$6))) | AB9: =IF($Y9="","",SUMPRODUCT(($D9:$W9=$D$2:$W$2)*($D9:$W9<>"")*$D$3:$W$3*($D$4:$W$4=AB$6)))
A10: 4 | B10: =IF(학생명단!B10="","",학생명단!B10) | C10: =IF(학생명단!C10="","",학생명단!C10) | X10: =IF(COUNTA(D10:W10)=0,"",SUMPRODUCT((D10:W10=$D$2:$W$2)*(D10:W10<>""))) | Y10: =IF(COUNTA(D10:W10)=0,"",SUMPRODUCT((D10:W10=$D$2:$W$2)*(D10:W10<>"")*$D$3:$W$3)) | Z10: =IF($Y10="","",SUMPRODUCT(($D10:$W10=$D$2:$W$2)*($D10:$W10<>"")*$D$3:$W$3*($D$4:$W$4=Z$6))) | AA10: =IF($Y10="","",SUMPRODUCT(($D10:$W10=$D$2:$W$2)*($D10:$W10<>"")*$D$3:$W$3*($D$4:$W$4=AA$6))) | AB10: =IF($Y10="","",SUMPRODUCT(($D10:$W10=$D$2:$W$2)*($D10:$W10<>"")*$D$3:$W$3*($D$4:$W$4=AB$6)))
A11: 5 | B11: =IF(학생명단!B11="","",학생명단!B11) | C11: =IF(학생명단!C11="","",학생명단!C11) | X11: =IF(COUNTA(D11:W11)=0,"",SUMPRODUCT((D11:W11=$D$2:$W$2)*(D11:W11<>""))) | Y11: =IF(COUNTA(D11:W11)=0,"",SUMPRODUCT((D11:W11=$D$2:$W$2)*(D11:W11<>"")*$D$3:$W$3)) | Z11: =IF($Y11="","",SUMPRODUCT(($D11:$W11=$D$2:$W$2)*($D11:$W11<>"")*$D$3:$W$3*($D$4:$W$4=Z$6))) | AA11: =IF($Y11="","",SUMPRODUCT(($D11:$W11=$D$2:$W$2)*($D11:$W11<>"")*$D$3:$W$3*($D$4:$W$4=AA$6))) | AB11: =IF($Y11="","",SUMPRODUCT(($D11:$W11=$D$2:$W$2)*($D11:$W11<>"")*$D$3:$W$3*($D$4:$W$4=AB$6)))
A12: 6 | B12: =IF(학생명단!B12="","",학생명단!B12) | C12: =IF(학생명단!C12="","",학생명단!C12) | X12: =IF(COUNTA(D12:W12)=0,"",SUMPRODUCT((D12:W12=$D$2:$W$2)*(D12:W12<>""))) | Y12: =IF(COUNTA(D12:W12)=0,"",SUMPRODUCT((D12:W12=$D$2:$W$2)*(D12:W12<>"")*$D$3:$W$3)) | Z12: =IF($Y12="","",SUMPRODUCT(($D12:$W12=$D$2:$W$2)*($D12:$W12<>"")*$D$3:$W$3*($D$4:$W$4=Z$6))) | AA12: =IF($Y12="","",SUMPRODUCT(($D12:$W12=$D$2:$W$2)*($D12:$W12<>"")*$D$3:$W$3*($D$4:$W$4=AA$6))) | AB12: =IF($Y12="","",SUMPRODUCT(($D12:$W12=$D$2:$W$2)*($D12:$W12<>"")*$D$3:$W$3*($D$4:$W$4=AB$6)))
A13: 7 | B13: =IF(학생명단!B13="","",학생명단!B13) | C13: =IF(학생명단!C13="","",학생명단!C13) | X13: =IF(COUNTA(D13:W13)=0,"",SUMPRODUCT((D13:W13=$D$2:$W$2)*(D13:W13<>""))) | Y13: =IF(COUNTA(D13:W13)=0,"",SUMPRODUCT((D13:W13=$D$2:$W$2)*(D13:W13<>"")*$D$3:$W$3)) | Z13: =IF($Y13="","",SUMPRODUCT(($D13:$W13=$D$2:$W$2)*($D13:$W13<>"")*$D$3:$W$3*($D$4:$W$4=Z$6))) | AA13: =IF($Y13="","",SUMPRODUCT(($D13:$W13=$D$2:$W$2)*($D13:$W13<>"")*$D$3:$W$3*($D$4:$W$4=AA$6))) | AB13: =IF($Y13="","",SUMPRODUCT(($D13:$W13=$D$2:$W$2)*($D13:$W13<>"")*$D$3:$W$3*($D$4:$W$4=AB$6)))
A14: 8 | B14: =IF(학생명단!B14="","",학생명단!B14) | C14: =IF(학생명단!C14="","",학생명단!C14) | X14: =IF(COUNTA(D14:W14)=0,"",SUMPRODUCT((D14:W14=$D$2:$W$2)*(D14:W14<>""))) | Y14: =IF(COUNTA(D14:W14)=0,"",SUMPRODUCT((D14:W14=$D$2:$W$2)*(D14:W14<>"")*$D$3:$W$3)) | Z14: =IF($Y14="","",SUMPRODUCT(($D14:$W14=$D$2:$W$2)*($D14:$W14<>"")*$D$3:$W$3*($D$4:$W$4=Z$6))) | AA14: =IF($Y14="","",SUMPRODUCT(($D14:$W14=$D$2:$W$2)*($D14:$W14<>"")*$D$3:$W$3*($D$4:$W$4=AA$6))) | AB14: =IF($Y14="","",SUMPRODUCT(($D14:$W14=$D$2:$W$2)*($D14:$W14<>"")*$D$3:$W$3*($D$4:$W$4=AB$6)))
A15: 9 | B15: =IF(학생명단!B15="","",학생명단!B15) | C15: =IF(학생명단!C15="","",학생명단!C15) | X15: =IF(COUNTA(D15:W15)=0,"",SUMPRODUCT((D15:W15=$D$2:$W$2)*(D15:W15<>""))) | Y15: =IF(COUNTA(D15:W15)=0,"",SUMPRODUCT((D15:W15=$D$2:$W$2)*(D15:W15<>"")*$D$3:$W$3)) | Z15: =IF($Y15="","",SUMPRODUCT(($D15:$W15=$D$2:$W$2)*($D15:$W15<>"")*$D$3:$W$3*($D$4:$W$4=Z$6))) | AA15: =IF($Y15="","",SUMPRODUCT(($D15:$W15=$D$2:$W$2)*($D15:$W15<>"")*$D$3:$W$3*($D$4:$W$4=AA$6))) | AB15: =IF($Y15="","",SUMPRODUCT(($D15:$W15=$D$2:$W$2)*($D15:$W15<>"")*$D$3:$W$3*($D$4:$W$4=AB$6)))
A16: 10 | B16: =IF(학생명단!B16="","",학생명단!B16) | C16: =IF(학생명단!C16="","",학생명단!C16) | X16: =IF(COUNTA(D16:W16)=0,"",SUMPRODUCT((D16:W16=$D$2:$W$2)*(D16:W16<>""))) | Y16: =IF(COUNTA(D16:W16)=0,"",SUMPRODUCT((D16:W16=$D$2:$W$2)*(D16:W16<>"")*$D$3:$W$3)) | Z16: =IF($Y16="","",SUMPRODUCT(($D16:$W16=$D$2:$W$2)*($D16:$W16<>"")*$D$3:$W$3*($D$4:$W$4=Z$6))) | AA16: =IF($Y16="","",SUMPRODUCT(($D16:$W16=$D$2:$W$2)*($D16:$W16<>"")*$D$3:$W$3*($D$4:$W$4=AA$6))) | AB16: =IF($Y16="","",SUMPRODUCT(($D16:$W16=$D$2:$W$2)*($D16:$W16<>"")*$D$3:$W$3*($D$4:$W$4=AB$6)))
A17: 11 | B17: =IF(학생명단!B17="","",학생명단!B17) | C17: =IF(학생명단!C17="","",학생명단!C17) | X17: =IF(COUNTA(D17:W17)=0,"",SUMPRODUCT((D17:W17=$D$2:$W$2)*(D17:W17<>""))) | Y17: =IF(COUNTA(D17:W17)=0,"",SUMPRODUCT((D17:W17=$D$2:$W$2)*(D17:W17<>"")*$D$3:$W$3)) | Z17: =IF($Y17="","",SUMPRODUCT(($D17:$W17=$D$2:$W$2)*($D17:$W17<>"")*$D$3:$W$3*($D$4:$W$4=Z$6))) | AA17: =IF($Y17="","",SUMPRODUCT(($D17:$W17=$D$2:$W$2)*($D17:$W17<>"")*$D$3:$W$3*($D$4:$W$4=AA$6))) | AB17: =IF($Y17="","",SUMPRODUCT(($D17:$W17=$D$2:$W$2)*($D17:$W17<>"")*$D$3:$W$3*($D$4:$W$4=AB$6)))
A18: 12 | B18: =IF(학생명단!B18="","",학생명단!B18) | C18: =IF(학생명단!C18="","",학생명단!C18) | X18: =IF(COUNTA(D18:W18)=0,"",SUMPRODUCT((D18:W18=$D$2:$W$2)*(D18:W18<>""))) | Y18: =IF(COUNTA(D18:W18)=0,"",SUMPRODUCT((D18:W18=$D$2:$W$2)*(D18:W18<>"")*$D$3:$W$3)) | Z18: =IF($Y18="","",SUMPRODUCT(($D18:$W18=$D$2:$W$2)*($D18:$W18<>"")*$D$3:$W$3*($D$4:$W$4=Z$6))) | AA18: =IF($Y18="","",SUMPRODUCT(($D18:$W18=$D$2:$W$2)*($D18:$W18<>"")*$D$3:$W$3*($D$4:$W$4=AA$6))) | AB18: =IF($Y18="","",SUMPRODUCT(($D18:$W18=$D$2:$W$2)*($D18:$W18<>"")*$D$3:$W$3*($D$4:$W$4=AB$6)))
... A86: 80 | B86: =IF(학생명단!B86="","",학생명단!B86) | C86: =IF(학생명단!C86="","",학생명단!C86) | X86: =IF(COUNTA(D86:W86)=0,"",SUMPRODUCT((D86:W86=$D$2:$W$2)*(D86:W86<>""))) | Y86: =IF(COUNTA(D86:W86)=0,"",SUMPRODUCT((D86:W86=$D$2:$W$2)*(D86:W86<>"")*$D$3:$W$3)) | Z86: =IF($Y86="","",SUMPRODUCT(($D86:$W86=$D$2:$W$2)*($D86:$W86<>"")*$D$3:$W$3*($D$4:$W$4=Z$6))) | AA86: =IF($Y86="","",SUMPRODUCT(($D86:$W86=$D$2:$W$2)*($D86:$W86<>"")*$D$3:$W$3*($D$4:$W$4=AA$6))) | AB86: =IF($Y86="","",SUMPRODUCT(($D86:$W86=$D$2:$W$2)*($D86:$W86<>"")*$D$3:$W$3*($D$4:$W$4=AB$6)))

Sheet 반배정
A1: 반 배정
A2: 자동 계산 시트입니다. 'K열 수동조정'에서만 반을 바꿀 수 있고(상담 결과 반영 등), 최종반 = 수동조정이 있으면 그 값, 없으면 자동배정. 주황색 행 = 반 경계 점수대 학생.
P5: 반별 요약
A6: No | B6: 이름 | C6: 학교 | D6: 구분 | E6: 공수1 | F6: 공수2 | G6: 환산총점 | H6: 석차 | I6: 자동배정 | J6: 경계 | K6: 수동조정 | L6: 최종반 | M6: 비고 | N6: 정렬키 | P6: 반 | Q6: 정원 | R6: 자동 인원 | S6: 최종 인원 | T6: 자동컷 (최저점) | U6: 최종 평균 | V6: 재원 | W6: 외부
A7: 1 | B7: =IF(학생명단!B7="","",학생명단!B7) -> 홍길동(예시) | C7: =IF(학생명단!C7="","",학생명단!C7) -> OO중 | D7: =IF(학생명단!D7="","",학생명단!D7) -> 외부 | E7: =공수1!Y7 | F7: =공수2!Y7 | G7: =IF(AND(E7="",F7=""),"",N(E7)*설정!$C$13+N(F7)*설정!$C$14) | H7: =IF(G7="","",COUNTIF($G$7:$G$86,">"&G7)+1) | I7: =IF(H7="","",IF(H7<=설정!$C$6,설정!$B$6,IF(H7<=설정!$C$6+설정!$C$7,설정!$B$7,설정!$B$8))) | J7: =IF(G7="","",IF(OR(AND(ISNUMBER($T$7),ABS(G7-$T$7)<=설정!$C$15),AND(ISNUMBER($T$8),ABS(G7-$T$8)<=설정!$C$15)),"경계","")) | L7: =IF(K7<>"",K7,I7) | M7: =IF(G7="","",IF(E7="","공수1 미응시",IF(F7="","공수2 미응시",""))) | N7: =IF(H7="","",H7+ROW()/100000) | P7: =설정!$B$6 -> 심화반 | Q7: =설정!$C$6 -> 20 | R7: =COUNTIF($I$7:$I$86,P7) -> 0 | S7: =COUNTIF($L$7:$L$86,P7) -> 0 | T7: =IF(R7=0,"",_xlfn.MINIFS($G$7:$G$86,$I$7:$I$86,P7)) | U7: =IFERROR(AVERAGEIF($L$7:$L$86,P7,$G$7:$G$86),"") | V7: =COUNTIFS($L$7:$L$86,P7,$D$7:$D$86,"재원") -> 0 | W7: =COUNTIFS($L$7:$L$86,P7,$D$7:$D$86,"외부") -> 0
A8: 2 | B8: =IF(학생명단!B8="","",학생명단!B8) | C8: =IF(학생명단!C8="","",학생명단!C8) | D8: =IF(학생명단!D8="","",학생명단!D8) | E8: =공수1!Y8 | F8: =공수2!Y8 | G8: =IF(AND(E8="",F8=""),"",N(E8)*설정!$C$13+N(F8)*설정!$C$14) | H8: =IF(G8="","",COUNTIF($G$7:$G$86,">"&G8)+1) | I8: =IF(H8="","",IF(H8<=설정!$C$6,설정!$B$6,IF(H8<=설정!$C$6+설정!$C$7,설정!$B$7,설정!$B$8))) | J8: =IF(G8="","",IF(OR(AND(ISNUMBER($T$7),ABS(G8-$T$7)<=설정!$C$15),AND(ISNUMBER($T$8),ABS(G8-$T$8)<=설정!$C$15)),"경계","")) | L8: =IF(K8<>"",K8,I8) | M8: =IF(G8="","",IF(E8="","공수1 미응시",IF(F8="","공수2 미응시",""))) | N8: =IF(H8="","",H8+ROW()/100000) | P8: =설정!$B$7 -> 정규반 | Q8: =설정!$C$7 -> 20 | R8: =COUNTIF($I$7:$I$86,P8) -> 0 | S8: =COUNTIF($L$7:$L$86,P8) -> 0 | T8: =IF(R8=0,"",_xlfn.MINIFS($G$7:$G$86,$I$7:$I$86,P8)) | U8: =IFERROR(AVERAGEIF($L$7:$L$86,P8,$G$7:$G$86),"") | V8: =COUNTIFS($L$7:$L$86,P8,$D$7:$D$86,"재원") -> 0 | W8: =COUNTIFS($L$7:$L$86,P8,$D$7:$D$86,"외부") -> 0
A9: 3 | B9: =IF(학생명단!B9="","",학생명단!B9) | C9: =IF(학생명단!C9="","",학생명단!C9) | D9: =IF(학생명단!D9="","",학생명단!D9) | E9: =공수1!Y9 | F9: =공수2!Y9 | G9: =IF(AND(E9="",F9=""),"",N(E9)*설정!$C$13+N(F9)*설정!$C$14) | H9: =IF(G9="","",COUNTIF($G$7:$G$86,">"&G9)+1) | I9: =IF(H9="","",IF(H9<=설정!$C$6,설정!$B$6,IF(H9<=설정!$C$6+설정!$C$7,설정!$B$7,설정!$B$8))) | J9: =IF(G9="","",IF(OR(AND(ISNUMBER($T$7),ABS(G9-$T$7)<=설정!$C$15),AND(ISNUMBER($T$8),ABS(G9-$T$8)<=설정!$C$15)),"경계","")) | L9: =IF(K9<>"",K9,I9) | M9: =IF(G9="","",IF(E9="","공수1 미응시",IF(F9="","공수2 미응시",""))) | N9: =IF(H9="","",H9+ROW()/100000) | P9: =설정!$B$8 -> 기본반 | Q9: =설정!$C$8 -> 20 | R9: =COUNTIF($I$7:$I$86,P9) -> 0 | S9: =COUNTIF($L$7:$L$86,P9) -> 0 | T9: =IF(R9=0,"",_xlfn.MINIFS($G$7:$G$86,$I$7:$I$86,P9)) | U9: =IFERROR(AVERAGEIF($L$7:$L$86,P9,$G$7:$G$86),"") | V9: =COUNTIFS($L$7:$L$86,P9,$D$7:$D$86,"재원") -> 0 | W9: =COUNTIFS($L$7:$L$86,P9,$D$7:$D$86,"외부") -> 0
A10: 4 | B10: =IF(학생명단!B10="","",학생명단!B10) | C10: =IF(학생명단!C10="","",학생명단!C10) | D10: =IF(학생명단!D10="","",학생명단!D10) | E10: =공수1!Y10 | F10: =공수2!Y10 | G10: =IF(AND(E10="",F10=""),"",N(E10)*설정!$C$13+N(F10)*설정!$C$14) | H10: =IF(G10="","",COUNTIF($G$7:$G$86,">"&G10)+1) | I10: =IF(H10="","",IF(H10<=설정!$C$6,설정!$B$6,IF(H10<=설정!$C$6+설정!$C$7,설정!$B$7,설정!$B$8))) | J10: =IF(G10="","",IF(OR(AND(ISNUMBER($T$7),ABS(G10-$T$7)<=설정!$C$15),AND(ISNUMBER($T$8),ABS(G10-$T$8)<=설정!$C$15)),"경계","")) | L10: =IF(K10<>"",K10,I10) | M10: =IF(G10="","",IF(E10="","공수1 미응시",IF(F10="","공수2 미응시",""))) | N10: =IF(H10="","",H10+ROW()/100000) | P10: 합계 | Q10: =SUM(Q7:Q9) -> 60 | R10: =SUM(R7:R9) -> 0 | S10: =SUM(S7:S9) -> 0 | U10: =IFERROR(AVERAGE($G$7:$G$86),"") | V10: =SUM(V7:V9) -> 0 | W10: =SUM(W7:W9) -> 0
A11: 5 | B11: =IF(학생명단!B11="","",학생명단!B11) | C11: =IF(학생명단!C11="","",학생명단!C11) | D11: =IF(학생명단!D11="","",학생명단!D11) | E11: =공수1!Y11 | F11: =공수2!Y11 | G11: =IF(AND(E11="",F11=""),"",N(E11)*설정!$C$13+N(F11)*설정!$C$14) | H11: =IF(G11="","",COUNTIF($G$7:$G$86,">"&G11)+1) | I11: =IF(H11="","",IF(H11<=설정!$C$6,설정!$B$6,IF(H11<=설정!$C$6+설정!$C$7,설정!$B$7,설정!$B$8))) | J11: =IF(G11="","",IF(OR(AND(ISNUMBER($T$7),ABS(G11-$T$7)<=설정!$C$15),AND(ISNUMBER($T$8),ABS(G11-$T$8)<=설정!$C$15)),"경계","")) | L11: =IF(K11<>"",K11,I11) | M11: =IF(G11="","",IF(E11="","공수1 미응시",IF(F11="","공수2 미응시",""))) | N11: =IF(H11="","",H11+ROW()/100000)
A12: 6 | B12: =IF(학생명단!B12="","",학생명단!B12) | C12: =IF(학생명단!C12="","",학생명단!C12) | D12: =IF(학생명단!D12="","",학생명단!D12) | E12: =공수1!Y12 | F12: =공수2!Y12 | G12: =IF(AND(E12="",F12=""),"",N(E12)*설정!$C$13+N(F12)*설정!$C$14) | H12: =IF(G12="","",COUNTIF($G$7:$G$86,">"&G12)+1) | I12: =IF(H12="","",IF(H12<=설정!$C$6,설정!$B$6,IF(H12<=설정!$C$6+설정!$C$7,설정!$B$7,설정!$B$8))) | J12: =IF(G12="","",IF(OR(AND(ISNUMBER($T$7),ABS(G12-$T$7)<=설정!$C$15),AND(ISNUMBER($T$8),ABS(G12-$T$8)<=설정!$C$15)),"경계","")) | L12: =IF(K12<>"",K12,I12) | M12: =IF(G12="","",IF(E12="","공수1 미응시",IF(F12="","공수2 미응시",""))) | N12: =IF(H12="","",H12+ROW()/100000) | P12: · 경계 = 1·2반 자동컷 점수와 차이가 '설정' 경계 범위 이내인 학생 · 수동조정한 학생은 최종 인원·평균에 반영됩니다(자동컷은 그대로)
A13: 7 | B13: =IF(학생명단!B13="","",학생명단!B13) | C13: =IF(학생명단!C13="","",학생명단!C13) | D13: =IF(학생명단!D13="","",학생명단!D13) | E13: =공수1!Y13 | F13: =공수2!Y13 | G13: =IF(AND(E13="",F13=""),"",N(E13)*설정!$C$13+N(F13)*설정!$C$14) | H13: =IF(G13="","",COUNTIF($G$7:$G$86,">"&G13)+1) | I13: =IF(H13="","",IF(H13<=설정!$C$6,설정!$B$6,IF(H13<=설정!$C$6+설정!$C$7,설정!$B$7,설정!$B$8))) | J13: =IF(G13="","",IF(OR(AND(ISNUMBER($T$7),ABS(G13-$T$7)<=설정!$C$15),AND(ISNUMBER($T$8),ABS(G13-$T$8)<=설정!$C$15)),"경계","")) | L13: =IF(K13<>"",K13,I13) | M13: =IF(G13="","",IF(E13="","공수1 미응시",IF(F13="","공수2 미응시",""))) | N13: =IF(H13="","",H13+ROW()/100000)
A14: 8 | B14: =IF(학생명단!B14="","",학생명단!B14) | C14: =IF(학생명단!C14="","",학생명단!C14) | D14: =IF(학생명단!D14="","",학생명단!D14) | E14: =공수1!Y14 | F14: =공수2!Y14 | G14: =IF(AND(E14="",F14=""),"",N(E14)*설정!$C$13+N(F14)*설정!$C$14) | H14: =IF(G14="","",COUNTIF($G$7:$G$86,">"&G14)+1) | I14: =IF(H14="","",IF(H14<=설정!$C$6,설정!$B$6,IF(H14<=설정!$C$6+설정!$C$7,설정!$B$7,설정!$B$8))) | J14: =IF(G14="","",IF(OR(AND(ISNUMBER($T$7),ABS(G14-$T$7)<=설정!$C$15),AND(ISNUMBER($T$8),ABS(G14-$T$8)<=설정!$C$15)),"경계","")) | L14: =IF(K14<>"",K14,I14) | M14: =IF(G14="","",IF(E14="","공수1 미응시",IF(F14="","공수2 미응시",""))) | N14: =IF(H14="","",H14+ROW()/100000)
A15: 9 | B15: =IF(학생명단!B15="","",학생명단!B15) | C15: =IF(학생명단!C15="","",학생명단!C15) | D15: =IF(학생명단!D15="","",학생명단!D15) | E15: =공수1!Y15 | F15: =공수2!Y15 | G15: =IF(AND(E15="",F15=""),"",N(E15)*설정!$C$13+N(F15)*설정!$C$14) | H15: =IF(G15="","",COUNTIF($G$7:$G$86,">"&G15)+1) | I15: =IF(H15="","",IF(H15<=설정!$C$6,설정!$B$6,IF(H15<=설정!$C$6+설정!$C$7,설정!$B$7,설정!$B$8))) | J15: =IF(G15="","",IF(OR(AND(ISNUMBER($T$7),ABS(G15-$T$7)<=설정!$C$15),AND(ISNUMBER($T$8),ABS(G15-$T$8)<=설정!$C$15)),"경계","")) | L15: =IF(K15<>"",K15,I15) | M15: =IF(G15="","",IF(E15="","공수1 미응시",IF(F15="","공수2 미응시",""))) | N15: =IF(H15="","",H15+ROW()/100000)
A16: 10 | B16: =IF(학생명단!B16="","",학생명단!B16) | C16: =IF(학생명단!C16="","",학생명단!C16) | D16: =IF(학생명단!D16="","",학생명단!D16) | E16: =공수1!Y16 | F16: =공수2!Y16 | G16: =IF(AND(E16="",F16=""),"",N(E16)*설정!$C$13+N(F16)*설정!$C$14) | H16: =IF(G16="","",COUNTIF($G$7:$G$86,">"&G16)+1) | I16: =IF(H16="","",IF(H16<=설정!$C$6,설정!$B$6,IF(H16<=설정!$C$6+설정!$C$7,설정!$B$7,설정!$B$8))) | J16: =IF(G16="","",IF(OR(AND(ISNUMBER($T$7),ABS(G16-$T$7)<=설정!$C$15),AND(ISNUMBER($T$8),ABS(G16-$T$8)<=설정!$C$15)),"경계","")) | L16: =IF(K16<>"",K16,I16) | M16: =IF(G16="","",IF(E16="","공수1 미응시",IF(F16="","공수2 미응시",""))) | N16: =IF(H16="","",H16+ROW()/100000)
A17: 11 | B17: =IF(학생명단!B17="","",학생명단!B17) | C17: =IF(학생명단!C17="","",학생명단!C17) | D17: =IF(학생명단!D17="","",학생명단!D17) | E17: =공수1!Y17 | F17: =공수2!Y17 | G17: =IF(AND(E17="",F17=""),"",N(E17)*설정!$C$13+N(F17)*설정!$C$14) | H17: =IF(G17="","",COUNTIF($G$7:$G$86,">"&G17)+1) | I17: =IF(H17="","",IF(H17<=설정!$C$6,설정!$B$6,IF(H17<=설정!$C$6+설정!$C$7,설정!$B$7,설정!$B$8))) | J17: =IF(G17="","",IF(OR(AND(ISNUMBER($T$7),ABS(G17-$T$7)<=설정!$C$15),AND(ISNUMBER($T$8),ABS(G17-$T$8)<=설정!$C$15)),"경계","")) | L17: =IF(K17<>"",K17,I17) | M17: =IF(G17="","",IF(E17="","공수1 미응시",IF(F17="","공수2 미응시",""))) | N17: =IF(H17="","",H17+ROW()/100000)
A18: 12 | B18: =IF(학생명단!B18="","",학생명단!B18) | C18: =IF(학생명단!C18="","",학생명단!C18) | D18: =IF(학생명단!D18="","",학생명단!D18) | E18: =공수1!Y18 | F18: =공수2!Y18 | G18: =IF(AND(E18="",F18=""),"",N(E18)*설정!$C$13+N(F18)*설정!$C$14) | H18: =IF(G18="","",COUNTIF($G$7:$G$86,">"&G18)+1) | I18: =IF(H18="","",IF(H18<=설정!$C$6,설정!$B$6,IF(H18<=설정!$C$6+설정!$C$7,설정!$B$7,설정!$B$8))) | J18: =IF(G18="","",IF(OR(AND(ISNUMBER($T$7),ABS(G18-$T$7)<=설정!$C$15),AND(ISNUMBER($T$8),ABS(G18-$T$8)<=설정!$C$15)),"경계","")) | L18: =IF(K18<>"",K18,I18) | M18: =IF(G18="","",IF(E18="","공수1 미응시",IF(F18="","공수2 미응시",""))) | N18: =IF(H18="","",H18+ROW()/100000)
A19: 13 | B19: =IF(학생명단!B19="","",학생명단!B19) | C19: =IF(학생명단!C19="","",학생명단!C19) | D19: =IF(학생명단!D19="","",학생명단!D19) | E19: =공수1!Y19 | F19: =공수2!Y19 | G19: =IF(AND(E19="",F19=""),"",N(E19)*설정!$C$13+N(F19)*설정!$C$14) | H19: =IF(G19="","",COUNTIF($G$7:$G$86,">"&G19)+1) | I19: =IF(H19="","",IF(H19<=설정!$C$6,설정!$B$6,IF(H19<=설정!$C$6+설정!$C$7,설정!$B$7,설정!$B$8))) | J19: =IF(G19="","",IF(OR(AND(ISNUMBER($T$7),ABS(G19-$T$7)<=설정!$C$15),AND(ISNUMBER($T$8),ABS(G19-$T$8)<=설정!$C$15)),"경계","")) | L19: =IF(K19<>"",K19,I19) | M19: =IF(G19="","",IF(E19="","공수1 미응시",IF(F19="","공수2 미응시",""))) | N19: =IF(H19="","",H19+ROW()/100000)
A20: 14 | B20: =IF(학생명단!B20="","",학생명단!B20) | C20: =IF(학생명단!C20="","",학생명단!C20) | D20: =IF(학생명단!D20="","",학생명단!D20) | E20: =공수1!Y20 | F20: =공수2!Y20 | G20: =IF(AND(E20="",F20=""),"",N(E20)*설정!$C$13+N(F20)*설정!$C$14) | H20: =IF(G20="","",COUNTIF($G$7:$G$86,">"&G20)+1) | I20: =IF(H20="","",IF(H20<=설정!$C$6,설정!$B$6,IF(H20<=설정!$C$6+설정!$C$7,설정!$B$7,설정!$B$8))) | J20: =IF(G20="","",IF(OR(AND(ISNUMBER($T$7),ABS(G20-$T$7)<=설정!$C$15),AND(ISNUMBER($T$8),ABS(G20-$T$8)<=설정!$C$15)),"경계","")) | L20: =IF(K20<>"",K20,I20) | M20: =IF(G20="","",IF(E20="","공수1 미응시",IF(F20="","공수2 미응시",""))) | N20: =IF(H20="","",H20+ROW()/100000)
A21: 15 | B21: =IF(학생명단!B21="","",학생명단!B21) | C21: =IF(학생명단!C21="","",학생명단!C21) | D21: =IF(학생명단!D21="","",학생명단!D21) | E21: =공수1!Y21 | F21: =공수2!Y21 | G21: =IF(AND(E21="",F21=""),"",N(E21)*설정!$C$13+N(F21)*설정!$C$14) | H21: =IF(G21="","",COUNTIF($G$7:$G$86,">"&G21)+1) | I21: =IF(H21="","",IF(H21<=설정!$C$6,설정!$B$6,IF(H21<=설정!$C$6+설정!$C$7,설정!$B$7,설정!$B$8))) | J21: =IF(G21="","",IF(OR(AND(ISNUMBER($T$7),ABS(G21-$T$7)<=설정!$C$15),AND(ISNUMBER($T$8),ABS(G21-$T$8)<=설정!$C$15)),"경계","")) | L21: =IF(K21<>"",K21,I21) | M21: =IF(G21="","",IF(E21="","공수1 미응시",IF(F21="","공수2 미응시",""))) | N21: =IF(H21="","",H21+ROW()/100000)
A22: 16 | B22: =IF(학생명단!B22="","",학생명단!B22) | C22: =IF(학생명단!C22="","",학생명단!C22) | D22: =IF(학생명단!D22="","",학생명단!D22) | E22: =공수1!Y22 | F22: =공수2!Y22 | G22: =IF(AND(E22="",F22=""),"",N(E22)*설정!$C$13+N(F22)*설정!$C$14) | H22: =IF(G22="","",COUNTIF($G$7:$G$86,">"&G22)+1) | I22: =IF(H22="","",IF(H22<=설정!$C$6,설정!$B$6,IF(H22<=설정!$C$6+설정!$C$7,설정!$B$7,설정!$B$8))) | J22: =IF(G22="","",IF(OR(AND(ISNUMBER($T$7),ABS(G22-$T$7)<=설정!$C$15),AND(ISNUMBER($T$8),ABS(G22-$T$8)<=설정!$C$15)),"경계","")) | L22: =IF(K22<>"",K22,I22) | M22: =IF(G22="","",IF(E22="","공수1 미응시",IF(F22="","공수2 미응시",""))) | N22: =IF(H22="","",H22+ROW()/100000)
A23: 17 | B23: =IF(학생명단!B23="","",학생명단!B23) | C23: =IF(학생명단!C23="","",학생명단!C23) | D23: =IF(학생명단!D23="","",학생명단!D23) | E23: =공수1!Y23 | F23: =공수2!Y23 | G23: =IF(AND(E23="",F23=""),"",N(E23)*설정!$C$13+N(F23)*설정!$C$14) | H23: =IF(G23="","",COUNTIF($G$7:$G$86,">"&G23)+1) | I23: =IF(H23="","",IF(H23<=설정!$C$6,설정!$B$6,IF(H23<=설정!$C$6+설정!$C$7,설정!$B$7,설정!$B$8))) | J23: =IF(G23="","",IF(OR(AND(ISNUMBER($T$7),ABS(G23-$T$7)<=설정!$C$15),AND(ISNUMBER($T$8),ABS(G23-$T$8)<=설정!$C$15)),"경계","")) | L23: =IF(K23<>"",K23,I23) | M23: =IF(G23="","",IF(E23="","공수1 미응시",IF(F23="","공수2 미응시",""))) | N23: =IF(H23="","",H23+ROW()/100000)
A24: 18 | B24: =IF(학생명단!B24="","",학생명단!B24) | C24: =IF(학생명단!C24="","",학생명단!C24) | D24: =IF(학생명단!D24="","",학생명단!D24) | E24: =공수1!Y24 | F24: =공수2!Y24 | G24: =IF(AND(E24="",F24=""),"",N(E24)*설정!$C$13+N(F24)*설정!$C$14) | H24: =IF(G24="","",COUNTIF($G$7:$G$86,">"&G24)+1) | I24: =IF(H24="","",IF(H24<=설정!$C$6,설정!$B$6,IF(H24<=설정!$C$6+설정!$C$7,설정!$B$7,설정!$B$8))) | J24: =IF(G24="","",IF(OR(AND(ISNUMBER($T$7),ABS(G24-$T$7)<=설정!$C$15),AND(ISNUMBER($T$8),ABS(G24-$T$8)<=설정!$C$15)),"경계","")) | L24: =IF(K24<>"",K24,I24) | M24: =IF(G24="","",IF(E24="","공수1 미응시",IF(F24="","공수2 미응시",""))) | N24: =IF(H24="","",H24+ROW()/100000)
... A86: 80 | B86: =IF(학생명단!B86="","",학생명단!B86) | C86: =IF(학생명단!C86="","",학생명단!C86) | D86: =IF(학생명단!D86="","",학생명단!D86) | E86: =공수1!Y86 | F86: =공수2!Y86 | G86: =IF(AND(E86="",F86=""),"",N(E86)*설정!$C$13+N(F86)*설정!$C$14) | H86: =IF(G86="","",COUNTIF($G$7:$G$86,">"&G86)+1) | I86: =IF(H86="","",IF(H86<=설정!$C$6,설정!$B$6,IF(H86<=설정!$C$6+설정!$C$7,설정!$B$7,설정!$B$8))) | J86: =IF(G86="","",IF(OR(AND(ISNUMBER($T$7),ABS(G86-$T$7)<=설정!$C$15),AND(ISNUMBER($T$8),ABS(G86-$T$8)<=설정!$C$15)),"경계","")) | L86: =IF(K86<>"",K86,I86) | M86: =IF(G86="","",IF(E86="","공수1 미응시",IF(F86="","공수2 미응시",""))) | N86: =IF(H86="","",H86+ROW()/100000)

Sheet 석차순
A1: 석차순 명단 (발표·상담용)
A2: 자동 정렬됩니다. 인쇄 시 그대로 사용하세요.
A6: 석차 | B6: 이름 | C6: 학교 | D6: 구분 | E6: 공수1 | F6: 공수2 | G6: 환산총점 | H6: 최종반 | I6: 경계 | J6: 비고
A7: =IF($L7="","",INDEX(반배정!H$7:H$86,$L7)) | B7: =IF($L7="","",INDEX(반배정!B$7:B$86,$L7)) | C7: =IF($L7="","",INDEX(반배정!C$7:C$86,$L7)) | D7: =IF($L7="","",INDEX(반배정!D$7:D$86,$L7)) | E7: =IF($L7="","",INDEX(반배정!E$7:E$86,$L7)) | F7: =IF($L7="","",INDEX(반배정!F$7:F$86,$L7)) | G7: =IF($L7="","",INDEX(반배정!G$7:G$86,$L7)) | H7: =IF($L7="","",INDEX(반배정!L$7:L$86,$L7)) | I7: =IF($L7="","",INDEX(반배정!J$7:J$86,$L7)) | J7: =IF($L7="","",INDEX(반배정!M$7:M$86,$L7)) | K7: =IFERROR(SMALL(반배정!$N$7:$N$86,1),"") | L7: =IF(K7="","",MATCH(K7,반배정!$N$7:$N$86,0))
A8: =IF($L8="","",INDEX(반배정!H$7:H$86,$L8)) | B8: =IF($L8="","",INDEX(반배정!B$7:B$86,$L8)) | C8: =IF($L8="","",INDEX(반배정!C$7:C$86,$L8)) | D8: =IF($L8="","",INDEX(반배정!D$7:D$86,$L8)) | E8: =IF($L8="","",INDEX(반배정!E$7:E$86,$L8)) | F8: =IF($L8="","",INDEX(반배정!F$7:F$86,$L8)) | G8: =IF($L8="","",INDEX(반배정!G$7:G$86,$L8)) | H8: =IF($L8="","",INDEX(반배정!L$7:L$86,$L8)) | I8: =IF($L8="","",INDEX(반배정!J$7:J$86,$L8)) | J8: =IF($L8="","",INDEX(반배정!M$7:M$86,$L8)) | K8: =IFERROR(SMALL(반배정!$N$7:$N$86,2),"") | L8: =IF(K8="","",MATCH(K8,반배정!$N$7:$N$86,0))
A9: =IF($L9="","",INDEX(반배정!H$7:H$86,$L9)) | B9: =IF($L9="","",INDEX(반배정!B$7:B$86,$L9)) | C9: =IF($L9="","",INDEX(반배정!C$7:C$86,$L9)) | D9: =IF($L9="","",INDEX(반배정!D$7:D$86,$L9)) | E9: =IF($L9="","",INDEX(반배정!E$7:E$86,$L9)) | F9: =IF($L9="","",INDEX(반배정!F$7:F$86,$L9)) | G9: =IF($L9="","",INDEX(반배정!G$7:G$86,$L9)) | H9: =IF($L9="","",INDEX(반배정!L$7:L$86,$L9)) | I9: =IF($L9="","",INDEX(반배정!J$7:J$86,$L9)) | J9: =IF($L9="","",INDEX(반배정!M$7:M$86,$L9)) | K9: =IFERROR(SMALL(반배정!$N$7:$N$86,3),"") | L9: =IF(K9="","",MATCH(K9,반배정!$N$7:$N$86,0))
A10: =IF($L10="","",INDEX(반배정!H$7:H$86,$L10)) | B10: =IF($L10="","",INDEX(반배정!B$7:B$86,$L10)) | C10: =IF($L10="","",INDEX(반배정!C$7:C$86,$L10)) | D10: =IF($L10="","",INDEX(반배정!D$7:D$86,$L10)) | E10: =IF($L10="","",INDEX(반배정!E$7:E$86,$L10)) | F10: =IF($L10="","",INDEX(반배정!F$7:F$86,$L10)) | G10: =IF($L10="","",INDEX(반배정!G$7:G$86,$L10)) | H10: =IF($L10="","",INDEX(반배정!L$7:L$86,$L10)) | I10: =IF($L10="","",INDEX(반배정!J$7:J$86,$L10)) | J10: =IF($L10="","",INDEX(반배정!M$7:M$86,$L10)) | K10: =IFERROR(SMALL(반배정!$N$7:$N$86,4),"") | L10: =IF(K10="","",MATCH(K10,반배정!$N$7:$N$86,0))
A11: =IF($L11="","",INDEX(반배정!H$7:H$86,$L11)) | B11: =IF($L11="","",INDEX(반배정!B$7:B$86,$L11)) | C11: =IF($L11="","",INDEX(반배정!C$7:C$86,$L11)) | D11: =IF($L11="","",INDEX(반배정!D$7:D$86,$L11)) | E11: =IF($L11="","",INDEX(반배정!E$7:E$86,$L11)) | F11: =IF($L11="","",INDEX(반배정!F$7:F$86,$L11)) | G11: =IF($L11="","",INDEX(반배정!G$7:G$86,$L11)) | H11: =IF($L11="","",INDEX(반배정!L$7:L$86,$L11)) | I11: =IF($L11="","",INDEX(반배정!J$7:J$86,$L11)) | J11: =IF($L11="","",INDEX(반배정!M$7:M$86,$L11)) | K11: =IFERROR(SMALL(반배정!$N$7:$N$86,5),"") | L11: =IF(K11="","",MATCH(K11,반배정!$N$7:$N$86,0))
A12: =IF($L12="","",INDEX(반배정!H$7:H$86,$L12)) | B12: =IF($L12="","",INDEX(반배정!B$7:B$86,$L12)) | C12: =IF($L12="","",INDEX(반배정!C$7:C$86,$L12)) | D12: =IF($L12="","",INDEX(반배정!D$7:D$86,$L12)) | E12: =IF($L12="","",INDEX(반배정!E$7:E$86,$L12)) | F12: =IF($L12="","",INDEX(반배정!F$7:F$86,$L12)) | G12: =IF($L12="","",INDEX(반배정!G$7:G$86,$L12)) | H12: =IF($L12="","",INDEX(반배정!L$7:L$86,$L12)) | I12: =IF($L12="","",INDEX(반배정!J$7:J$86,$L12)) | J12: =IF($L12="","",INDEX(반배정!M$7:M$86,$L12)) | K12: =IFERROR(SMALL(반배정!$N$7:$N$86,6),"") | L12: =IF(K12="","",MATCH(K12,반배정!$N$7:$N$86,0))
A13: =IF($L13="","",INDEX(반배정!H$7:H$86,$L13)) | B13: =IF($L13="","",INDEX(반배정!B$7:B$86,$L13)) | C13: =IF($L13="","",INDEX(반배정!C$7:C$86,$L13)) | D13: =IF($L13="","",INDEX(반배정!D$7:D$86,$L13)) | E13: =IF($L13="","",INDEX(반배정!E$7:E$86,$L13)) | F13: =IF($L13="","",INDEX(반배정!F$7:F$86,$L13)) | G13: =IF($L13="","",INDEX(반배정!G$7:G$86,$L13)) | H13: =IF($L13="","",INDEX(반배정!L$7:L$86,$L13)) | I13: =IF($L13="","",INDEX(반배정!J$7:J$86,$L13)) | J13: =IF($L13="","",INDEX(반배정!M$7:M$86,$L13)) | K13: =IFERROR(SMALL(반배정!$N$7:$N$86,7),"") | L13: =IF(K13="","",MATCH(K13,반배정!$N$7:$N$86,0))
A14: =IF($L14="","",INDEX(반배정!H$7:H$86,$L14)) | B14: =IF($L14="","",INDEX(반배정!B$7:B$86,$L14)) | C14: =IF($L14="","",INDEX(반배정!C$7:C$86,$L14)) | D14: =IF($L14="","",INDEX(반배정!D$7:D$86,$L14)) | E14: =IF($L14="","",INDEX(반배정!E$7:E$86,$L14)) | F14: =IF($L14="","",INDEX(반배정!F$7:F$86,$L14)) | G14: =IF($L14="","",INDEX(반배정!G$7:G$86,$L14)) | H14: =IF($L14="","",INDEX(반배정!L$7:L$86,$L14)) | I14: =IF($L14="","",INDEX(반배정!J$7:J$86,$L14)) | J14: =IF($L14="","",INDEX(반배정!M$7:M$86,$L14)) | K14: =IFERROR(SMALL(반배정!$N$7:$N$86,8),"") | L14: =IF(K14="","",MATCH(K14,반배정!$N$7:$N$86,0))
A15: =IF($L15="","",INDEX(반배정!H$7:H$86,$L15)) | B15: =IF($L15="","",INDEX(반배정!B$7:B$86,$L15)) | C15: =IF($L15="","",INDEX(반배정!C$7:C$86,$L15)) | D15: =IF($L15="","",INDEX(반배정!D$7:D$86,$L15)) | E15: =IF($L15="","",INDEX(반배정!E$7:E$86,$L15)) | F15: =IF($L15="","",INDEX(반배정!F$7:F$86,$L15)) | G15: =IF($L15="","",INDEX(반배정!G$7:G$86,$L15)) | H15: =IF($L15="","",INDEX(반배정!L$7:L$86,$L15)) | I15: =IF($L15="","",INDEX(반배정!J$7:J$86,$L15)) | J15: =IF($L15="","",INDEX(반배정!M$7:M$86,$L15)) | K15: =IFERROR(SMALL(반배정!$N$7:$N$86,9),"") | L15: =IF(K15="","",MATCH(K15,반배정!$N$7:$N$86,0))
A16: =IF($L16="","",INDEX(반배정!H$7:H$86,$L16)) | B16: =IF($L16="","",INDEX(반배정!B$7:B$86,$L16)) | C16: =IF($L16="","",INDEX(반배정!C$7:C$86,$L16)) | D16: =IF($L16="","",INDEX(반배정!D$7:D$86,$L16)) | E16: =IF($L16="","",INDEX(반배정!E$7:E$86,$L16)) | F16: =IF($L16="","",INDEX(반배정!F$7:F$86,$L16)) | G16: =IF($L16="","",INDEX(반배정!G$7:G$86,$L16)) | H16: =IF($L16="","",INDEX(반배정!L$7:L$86,$L16)) | I16: =IF($L16="","",INDEX(반배정!J$7:J$86,$L16)) | J16: =IF($L16="","",INDEX(반배정!M$7:M$86,$L16)) | K16: =IFERROR(SMALL(반배정!$N$7:$N$86,10),"") | L16: =IF(K16="","",MATCH(K16,반배정!$N$7:$N$86,0))
A17: =IF($L17="","",INDEX(반배정!H$7:H$86,$L17)) | B17: =IF($L17="","",INDEX(반배정!B$7:B$86,$L17)) | C17: =IF($L17="","",INDEX(반배정!C$7:C$86,$L17)) | D17: =IF($L17="","",INDEX(반배정!D$7:D$86,$L17)) | E17: =IF($L17="","",INDEX(반배정!E$7:E$86,$L17)) | F17: =IF($L17="","",INDEX(반배정!F$7:F$86,$L17)) | G17: =IF($L17="","",INDEX(반배정!G$7:G$86,$L17)) | H17: =IF($L17="","",INDEX(반배정!L$7:L$86,$L17)) | I17: =IF($L17="","",INDEX(반배정!J$7:J$86,$L17)) | J17: =IF($L17="","",INDEX(반배정!M$7:M$86,$L17)) | K17: =IFERROR(SMALL(반배정!$N$7:$N$86,11),"") | L17: =IF(K17="","",MATCH(K17,반배정!$N$7:$N$86,0))
A18: =IF($L18="","",INDEX(반배정!H$7:H$86,$L18)) | B18: =IF($L18="","",INDEX(반배정!B$7:B$86,$L18)) | C18: =IF($L18="","",INDEX(반배정!C$7:C$86,$L18)) | D18: =IF($L18="","",INDEX(반배정!D$7:D$86,$L18)) | E18: =IF($L18="","",INDEX(반배정!E$7:E$86,$L18)) | F18: =IF($L18="","",INDEX(반배정!F$7:F$86,$L18)) | G18: =IF($L18="","",INDEX(반배정!G$7:G$86,$L18)) | H18: =IF($L18="","",INDEX(반배정!L$7:L$86,$L18)) | I18: =IF($L18="","",INDEX(반배정!J$7:J$86,$L18)) | J18: =IF($L18="","",INDEX(반배정!M$7:M$86,$L18)) | K18: =IFERROR(SMALL(반배정!$N$7:$N$86,12),"") | L18: =IF(K18="","",MATCH(K18,반배정!$N$7:$N$86,0))
A19: =IF($L19="","",INDEX(반배정!H$7:H$86,$L19)) | B19: =IF($L19="","",INDEX(반배정!B$7:B$86,$L19)) | C19: =IF($L19="","",INDEX(반배정!C$7:C$86,$L19)) | D19: =IF($L19="","",INDEX(반배정!D$7:D$86,$L19)) | E19: =IF($L19="","",INDEX(반배정!E$7:E$86,$L19)) | F19: =IF($L19="","",INDEX(반배정!F$7:F$86,$L19)) | G19: =IF($L19="","",INDEX(반배정!G$7:G$86,$L19)) | H19: =IF($L19="","",INDEX(반배정!L$7:L$86,$L19)) | I19: =IF($L19="","",INDEX(반배정!J$7:J$86,$L19)) | J19: =IF($L19="","",INDEX(반배정!M$7:M$86,$L19)) | K19: =IFERROR(SMALL(반배정!$N$7:$N$86,13),"") | L19: =IF(K19="","",MATCH(K19,반배정!$N$7:$N$86,0))
A20: =IF($L20="","",INDEX(반배정!H$7:H$86,$L20)) | B20: =IF($L20="","",INDEX(반배정!B$7:B$86,$L20)) | C20: =IF($L20="","",INDEX(반배정!C$7:C$86,$L20)) | D20: =IF($L20="","",INDEX(반배정!D$7:D$86,$L20)) | E20: =IF($L20="","",INDEX(반배정!E$7:E$86,$L20)) | F20: =IF($L20="","",INDEX(반배정!F$7:F$86,$L20)) | G20: =IF($L20="","",INDEX(반배정!G$7:G$86,$L20)) | H20: =IF($L20="","",INDEX(반배정!L$7:L$86,$L20)) | I20: =IF($L20="","",INDEX(반배정!J$7:J$86,$L20)) | J20: =IF($L20="","",INDEX(반배정!M$7:M$86,$L20)) | K20: =IFERROR(SMALL(반배정!$N$7:$N$86,14),"") | L20: =IF(K20="","",MATCH(K20,반배정!$N$7:$N$86,0))
A21: =IF($L21="","",INDEX(반배정!H$7:H$86,$L21)) | B21: =IF($L21="","",INDEX(반배정!B$7:B$86,$L21)) | C21: =IF($L21="","",INDEX(반배정!C$7:C$86,$L21)) | D21: =IF($L21="","",INDEX(반배정!D$7:D$86,$L21)) | E21: =IF($L21="","",INDEX(반배정!E$7:E$86,$L21)) | F21: =IF($L21="","",INDEX(반배정!F$7:F$86,$L21)) | G21: =IF($L21="","",INDEX(반배정!G$7:G$86,$L21)) | H21: =IF($L21="","",INDEX(반배정!L$7:L$86,$L21)) | I21: =IF($L21="","",INDEX(반배정!J$7:J$86,$L21)) | J21: =IF($L21="","",INDEX(반배정!M$7:M$86,$L21)) | K21: =IFERROR(SMALL(반배정!$N$7:$N$86,15),"") | L21: =IF(K21="","",MATCH(K21,반배정!$N$7:$N$86,0))
A22: =IF($L22="","",INDEX(반배정!H$7:H$86,$L22)) | B22: =IF($L22="","",INDEX(반배정!B$7:B$86,$L22)) | C22: =IF($L22="","",INDEX(반배정!C$7:C$86,$L22)) | D22: =IF($L22="","",INDEX(반배정!D$7:D$86,$L22)) | E22: =IF($L22="","",INDEX(반배정!E$7:E$86,$L22)) | F22: =IF($L22="","",INDEX(반배정!F$7:F$86,$L22)) | G22: =IF($L22="","",INDEX(반배정!G$7:G$86,$L22)) | H22: =IF($L22="","",INDEX(반배정!L$7:L$86,$L22)) | I22: =IF($L22="","",INDEX(반배정!J$7:J$86,$L22)) | J22: =IF($L22="","",INDEX(반배정!M$7:M$86,$L22)) | K22: =IFERROR(SMALL(반배정!$N$7:$N$86,16),"") | L22: =IF(K22="","",MATCH(K22,반배정!$N$7:$N$86,0))
A23: =IF($L23="","",INDEX(반배정!H$7:H$86,$L23)) | B23: =IF($L23="","",INDEX(반배정!B$7:B$86,$L23)) | C23: =IF($L23="","",INDEX(반배정!C$7:C$86,$L23)) | D23: =IF($L23="","",INDEX(반배정!D$7:D$86,$L23)) | E23: =IF($L23="","",INDEX(반배정!E$7:E$86,$L23)) | F23: =IF($L23="","",INDEX(반배정!F$7:F$86,$L23)) | G23: =IF($L23="","",INDEX(반배정!G$7:G$86,$L23)) | H23: =IF($L23="","",INDEX(반배정!L$7:L$86,$L23)) | I23: =IF($L23="","",INDEX(반배정!J$7:J$86,$L23)) | J23: =IF($L23="","",INDEX(반배정!M$7:M$86,$L23)) | K23: =IFERROR(SMALL(반배정!$N$7:$N$86,17),"") | L23: =IF(K23="","",MATCH(K23,반배정!$N$7:$N$86,0))
A24: =IF($L24="","",INDEX(반배정!H$7:H$86,$L24)) | B24: =IF($L24="","",INDEX(반배정!B$7:B$86,$L24)) | C24: =IF($L24="","",INDEX(반배정!C$7:C$86,$L24)) | D24: =IF($L24="","",INDEX(반배정!D$7:D$86,$L24)) | E24: =IF($L24="","",INDEX(반배정!E$7:E$86,$L24)) | F24: =IF($L24="","",INDEX(반배정!F$7:F$86,$L24)) | G24: =IF($L24="","",INDEX(반배정!G$7:G$86,$L24)) | H24: =IF($L24="","",INDEX(반배정!L$7:L$86,$L24)) | I24: =IF($L24="","",INDEX(반배정!J$7:J$86,$L24)) | J24: =IF($L24="","",INDEX(반배정!M$7:M$86,$L24)) | K24: =IFERROR(SMALL(반배정!$N$7:$N$86,18),"") | L24: =IF(K24="","",MATCH(K24,반배정!$N$7:$N$86,0))
A25: =IF($L25="","",INDEX(반배정!H$7:H$86,$L25)) | B25: =IF($L25="","",INDEX(반배정!B$7:B$86,$L25)) | C25: =IF($L25="","",INDEX(반배정!C$7:C$86,$L25)) | D25: =IF($L25="","",INDEX(반배정!D$7:D$86,$L25)) | E25: =IF($L25="","",INDEX(반배정!E$7:E$86,$L25)) | F25: =IF($L25="","",INDEX(반배정!F$7:F$86,$L25)) | G25: =IF($L25="","",INDEX(반배정!G$7:G$86,$L25)) | H25: =IF($L25="","",INDEX(반배정!L$7:L$86,$L25)) | I25: =IF($L25="","",INDEX(반배정!J$7:J$86,$L25)) | J25: =IF($L25="","",INDEX(반배정!M$7:M$86,$L25)) | K25: =IFERROR(SMALL(반배정!$N$7:$N$86,19),"") | L25: =IF(K25="","",MATCH(K25,반배정!$N$7:$N$86,0))
A26: =IF($L26="","",INDEX(반배정!H$7:H$86,$L26)) | B26: =IF($L26="","",INDEX(반배정!B$7:B$86,$L26)) | C26: =IF($L26="","",INDEX(반배정!C$7:C$86,$L26)) | D26: =IF($L26="","",INDEX(반배정!D$7:D$86,$L26)) | E26: =IF($L26="","",INDEX(반배정!E$7:E$86,$L26)) | F26: =IF($L26="","",INDEX(반배정!F$7:F$86,$L26)) | G26: =IF($L26="","",INDEX(반배정!G$7:G$86,$L26)) | H26: =IF($L26="","",INDEX(반배정!L$7:L$86,$L26)) | I26: =IF($L26="","",INDEX(반배정!J$7:J$86,$L26)) | J26: =IF($L26="","",INDEX(반배정!M$7:M$86,$L26)) | K26: =IFERROR(SMALL(반배정!$N$7:$N$86,20),"") | L26: =IF(K26="","",MATCH(K26,반배정!$N$7:$N$86,0))
A27: =IF($L27="","",INDEX(반배정!H$7:H$86,$L27)) | B27: =IF($L27="","",INDEX(반배정!B$7:B$86,$L27)) | C27: =IF($L27="","",INDEX(반배정!C$7:C$86,$L27)) | D27: =IF($L27="","",INDEX(반배정!D$7:D$86,$L27)) | E27: =IF($L27="","",INDEX(반배정!E$7:E$86,$L27)) | F27: =IF($L27="","",INDEX(반배정!F$7:F$86,$L27)) | G27: =IF($L27="","",INDEX(반배정!G$7:G$86,$L27)) | H27: =IF($L27="","",INDEX(반배정!L$7:L$86,$L27)) | I27: =IF($L27="","",INDEX(반배정!J$7:J$86,$L27)) | J27: =IF($L27="","",INDEX(반배정!M$7:M$86,$L27)) | K27: =IFERROR(SMALL(반배정!$N$7:$N$86,21),"") | L27: =IF(K27="","",MATCH(K27,반배정!$N$7:$N$86,0))
A28: =IF($L28="","",INDEX(반배정!H$7:H$86,$L28)) | B28: =IF($L28="","",INDEX(반배정!B$7:B$86,$L28)) | C28: =IF($L28="","",INDEX(반배정!C$7:C$86,$L28)) | D28: =IF($L28="","",INDEX(반배정!D$7:D$86,$L28)) | E28: =IF($L28="","",INDEX(반배정!E$7:E$86,$L28)) | F28: =IF($L28="","",INDEX(반배정!F$7:F$86,$L28)) | G28: =IF($L28="","",INDEX(반배정!G$7:G$86,$L28)) | H28: =IF($L28="","",INDEX(반배정!L$7:L$86,$L28)) | I28: =IF($L28="","",INDEX(반배정!J$7:J$86,$L28)) | J28: =IF($L28="","",INDEX(반배정!M$7:M$86,$L28)) | K28: =IFERROR(SMALL(반배정!$N$7:$N$86,22),"") | L28: =IF(K28="","",MATCH(K28,반배정!$N$7:$N$86,0))
A29: =IF($L29="","",INDEX(반배정!H$7:H$86,$L29)) | B29: =IF($L29="","",INDEX(반배정!B$7:B$86,$L29)) | C29: =IF($L29="","",INDEX(반배정!C$7:C$86,$L29)) | D29: =IF($L29="","",INDEX(반배정!D$7:D$86,$L29)) | E29: =IF($L29="","",INDEX(반배정!E$7:E$86,$L29)) | F29: =IF($L29="","",INDEX(반배정!F$7:F$86,$L29)) | G29: =IF($L29="","",INDEX(반배정!G$7:G$86,$L29)) | H29: =IF($L29="","",INDEX(반배정!L$7:L$86,$L29)) | I29: =IF($L29="","",INDEX(반배정!J$7:J$86,$L29)) | J29: =IF($L29="","",INDEX(반배정!M$7:M$86,$L29)) | K29: =IFERROR(SMALL(반배정!$N$7:$N$86,23),"") | L29: =IF(K29="","",MATCH(K29,반배정!$N$7:$N$86,0))
A30: =IF($L30="","",INDEX(반배정!H$7:H$86,$L30)) | B30: =IF($L30="","",INDEX(반배정!B$7:B$86,$L30)) | C30: =IF($L30="","",INDEX(반배정!C$7:C$86,$L30)) | D30: =IF($L30="","",INDEX(반배정!D$7:D$86,$L30)) | E30: =IF($L30="","",INDEX(반배정!E$7:E$86,$L30)) | F30: =IF($L30="","",INDEX(반배정!F$7:F$86,$L30)) | G30: =IF($L30="","",INDEX(반배정!G$7:G$86,$L30)) | H30: =IF($L30="","",INDEX(반배정!L$7:L$86,$L30)) | I30: =IF($L30="","",INDEX(반배정!J$7:J$86,$L30)) | J30: =IF($L30="","",INDEX(반배정!M$7:M$86,$L30)) | K30: =IFERROR(SMALL(반배정!$N$7:$N$86,24),"") | L30: =IF(K30="","",MATCH(K30,반배정!$N$7:$N$86,0))
A31: =IF($L31="","",INDEX(반배정!H$7:H$86,$L31)) | B31: =IF($L31="","",INDEX(반배정!B$7:B$86,$L31)) | C31: =IF($L31="","",INDEX(반배정!C$7:C$86,$L31)) | D31: =IF($L31="","",INDEX(반배정!D$7:D$86,$L31)) | E31: =IF($L31="","",INDEX(반배정!E$7:E$86,$L31)) | F31: =IF($L31="","",INDEX(반배정!F$7:F$86,$L31)) | G31: =IF($L31="","",INDEX(반배정!G$7:G$86,$L31)) | H31: =IF($L31="","",INDEX(반배정!L$7:L$86,$L31)) | I31: =IF($L31="","",INDEX(반배정!J$7:J$86,$L31)) | J31: =IF($L31="","",INDEX(반배정!M$7:M$86,$L31)) | K31: =IFERROR(SMALL(반배정!$N$7:$N$86,25),"") | L31: =IF(K31="","",MATCH(K31,반배정!$N$7:$N$86,0))
A32: =IF($L32="","",INDEX(반배정!H$7:H$86,$L32)) | B32: =IF($L32="","",INDEX(반배정!B$7:B$86,$L32)) | C32: =IF($L32="","",INDEX(반배정!C$7:C$86,$L32)) | D32: =IF($L32="","",INDEX(반배정!D$7:D$86,$L32)) | E32: =IF($L32="","",INDEX(반배정!E$7:E$86,$L32)) | F32: =IF($L32="","",INDEX(반배정!F$7:F$86,$L32)) | G32: =IF($L32="","",INDEX(반배정!G$7:G$86,$L32)) | H32: =IF($L32="","",INDEX(반배정!L$7:L$86,$L32)) | I32: =IF($L32="","",INDEX(반배정!J$7:J$86,$L32)) | J32: =IF($L32="","",INDEX(반배정!M$7:M$86,$L32)) | K32: =IFERROR(SMALL(반배정!$N$7:$N$86,26),"") | L32: =IF(K32="","",MATCH(K32,반배정!$N$7:$N$86,0))
A33: =IF($L33="","",INDEX(반배정!H$7:H$86,$L33)) | B33: =IF($L33="","",INDEX(반배정!B$7:B$86,$L33)) | C33: =IF($L33="","",INDEX(반배정!C$7:C$86,$L33)) | D33: =IF($L33="","",INDEX(반배정!D$7:D$86,$L33)) | E33: =IF($L33="","",INDEX(반배정!E$7:E$86,$L33)) | F33: =IF($L33="","",INDEX(반배정!F$7:F$86,$L33)) | G33: =IF($L33="","",INDEX(반배정!G$7:G$86,$L33)) | H33: =IF($L33="","",INDEX(반배정!L$7:L$86,$L33)) | I33: =IF($L33="","",INDEX(반배정!J$7:J$86,$L33)) | J33: =IF($L33="","",INDEX(반배정!M$7:M$86,$L33)) | K33: =IFERROR(SMALL(반배정!$N$7:$N$86,27),"") | L33: =IF(K33="","",MATCH(K33,반배정!$N$7:$N$86,0))
A34: =IF($L34="","",INDEX(반배정!H$7:H$86,$L34)) | B34: =IF($L34="","",INDEX(반배정!B$7:B$86,$L34)) | C34: =IF($L34="","",INDEX(반배정!C$7:C$86,$L34)) | D34: =IF($L34="","",INDEX(반배정!D$7:D$86,$L34)) | E34: =IF($L34="","",INDEX(반배정!E$7:E$86,$L34)) | F34: =IF($L34="","",INDEX(반배정!F$7:F$86,$L34)) | G34: =IF($L34="","",INDEX(반배정!G$7:G$86,$L34)) | H34: =IF($L34="","",INDEX(반배정!L$7:L$86,$L34)) | I34: =IF($L34="","",INDEX(반배정!J$7:J$86,$L34)) | J34: =IF($L34="","",INDEX(반배정!M$7:M$86,$L34)) | K34: =IFERROR(SMALL(반배정!$N$7:$N$86,28),"") | L34: =IF(K34="","",MATCH(K34,반배정!$N$7:$N$86,0))
A35: =IF($L35="","",INDEX(반배정!H$7:H$86,$L35)) | B35: =IF($L35="","",INDEX(반배정!B$7:B$86,$L35)) | C35: =IF($L35="","",INDEX(반배정!C$7:C$86,$L35)) | D35: =IF($L35="","",INDEX(반배정!D$7:D$86,$L35)) | E35: =IF($L35="","",INDEX(반배정!E$7:E$86,$L35)) | F35: =IF($L35="","",INDEX(반배정!F$7:F$86,$L35)) | G35: =IF($L35="","",INDEX(반배정!G$7:G$86,$L35)) | H35: =IF($L35="","",INDEX(반배정!L$7:L$86,$L35)) | I35: =IF($L35="","",INDEX(반배정!J$7:J$86,$L35)) | J35: =IF($L35="","",INDEX(반배정!M$7:M$86,$L35)) | K35: =IFERROR(SMALL(반배정!$N$7:$N$86,29),"") | L35: =IF(K35="","",MATCH(K35,반배정!$N$7:$N$86,0))
A36: =IF($L36="","",INDEX(반배정!H$7:H$86,$L36)) | B36: =IF($L36="","",INDEX(반배정!B$7:B$86,$L36)) | C36: =IF($L36="","",INDEX(반배정!C$7:C$86,$L36)) | D36: =IF($L36="","",INDEX(반배정!D$7:D$86,$L36)) | E36: =IF($L36="","",INDEX(반배정!E$7:E$86,$L36)) | F36: =IF($L36="","",INDEX(반배정!F$7:F$86,$L36)) | G36: =IF($L36="","",INDEX(반배정!G$7:G$86,$L36)) | H36: =IF($L36="","",INDEX(반배정!L$7:L$86,$L36)) | I36: =IF($L36="","",INDEX(반배정!J$7:J$86,$L36)) | J36: =IF($L36="","",INDEX(반배정!M$7:M$86,$L36)) | K36: =IFERROR(SMALL(반배정!$N$7:$N$86,30),"") | L36: =IF(K36="","",MATCH(K36,반배정!$N$7:$N$86,0))
A37: =IF($L37="","",INDEX(반배정!H$7:H$86,$L37)) | B37: =IF($L37="","",INDEX(반배정!B$7:B$86,$L37)) | C37: =IF($L37="","",INDEX(반배정!C$7:C$86,$L37)) | D37: =IF($L37="","",INDEX(반배정!D$7:D$86,$L37)) | E37: =IF($L37="","",INDEX(반배정!E$7:E$86,$L37)) | F37: =IF($L37="","",INDEX(반배정!F$7:F$86,$L37)) | G37: =IF($L37="","",INDEX(반배정!G$7:G$86,$L37)) | H37: =IF($L37="","",INDEX(반배정!L$7:L$86,$L37)) | I37: =IF($L37="","",INDEX(반배정!J$7:J$86,$L37)) | J37: =IF($L37="","",INDEX(반배정!M$7:M$86,$L37)) | K37: =IFERROR(SMALL(반배정!$N$7:$N$86,31),"") | L37: =IF(K37="","",MATCH(K37,반배정!$N$7:$N$86,0))
A38: =IF($L38="","",INDEX(반배정!H$7:H$86,$L38)) | B38: =IF($L38="","",INDEX(반배정!B$7:B$86,$L38)) | C38: =IF($L38="","",INDEX(반배정!C$7:C$86,$L38)) | D38: =IF($L38="","",INDEX(반배정!D$7:D$86,$L38)) | E38: =IF($L38="","",INDEX(반배정!E$7:E$86,$L38)) | F38: =IF($L38="","",INDEX(반배정!F$7:F$86,$L38)) | G38: =IF($L38="","",INDEX(반배정!G$7:G$86,$L38)) | H38: =IF($L38="","",INDEX(반배정!L$7:L$86,$L38)) | I38: =IF($L38="","",INDEX(반배정!J$7:J$86,$L38)) | J38: =IF($L38="","",INDEX(반배정!M$7:M$86,$L38)) | K38: =IFERROR(SMALL(반배정!$N$7:$N$86,32),"") | L38: =IF(K38="","",MATCH(K38,반배정!$N$7:$N$86,0))
A39: =IF($L39="","",INDEX(반배정!H$7:H$86,$L39)) | B39: =IF($L39="","",INDEX(반배정!B$7:B$86,$L39)) | C39: =IF($L39="","",INDEX(반배정!C$7:C$86,$L39)) | D39: =IF($L39="","",INDEX(반배정!D$7:D$86,$L39)) | E39: =IF($L39="","",INDEX(반배정!E$7:E$86,$L39)) | F39: =IF($L39="","",INDEX(반배정!F$7:F$86,$L39)) | G39: =IF($L39="","",INDEX(반배정!G$7:G$86,$L39)) | H39: =IF($L39="","",INDEX(반배정!L$7:L$86,$L39)) | I39: =IF($L39="","",INDEX(반배정!J$7:J$86,$L39)) | J39: =IF($L39="","",INDEX(반배정!M$7:M$86,$L39)) | K39: =IFERROR(SMALL(반배정!$N$7:$N$86,33),"") | L39: =IF(K39="","",MATCH(K39,반배정!$N$7:$N$86,0))
A40: =IF($L40="","",INDEX(반배정!H$7:H$86,$L40)) | B40: =IF($L40="","",INDEX(반배정!B$7:B$86,$L40)) | C40: =IF($L40="","",INDEX(반배정!C$7:C$86,$L40)) | D40: =IF($L40="","",INDEX(반배정!D$7:D$86,$L40)) | E40: =IF($L40="","",INDEX(반배정!E$7:E$86,$L40)) | F40: =IF($L40="","",INDEX(반배정!F$7:F$86,$L40)) | G40: =IF($L40="","",INDEX(반배정!G$7:G$86,$L40)) | H40: =IF($L40="","",INDEX(반배정!L$7:L$86,$L40)) | I40: =IF($L40="","",INDEX(반배정!J$7:J$86,$L40)) | J40: =IF($L40="","",INDEX(반배정!M$7:M$86,$L40)) | K40: =IFERROR(SMALL(반배정!$N$7:$N$86,34),"") | L40: =IF(K40="","",MATCH(K40,반배정!$N$7:$N$86,0))
A41: =IF($L41="","",INDEX(반배정!H$7:H$86,$L41)) | B41: =IF($L41="","",INDEX(반배정!B$7:B$86,$L41)) | C41: =IF($L41="","",INDEX(반배정!C$7:C$86,$L41)) | D41: =IF($L41="","",INDEX(반배정!D$7:D$86,$L41)) | E41: =IF($L41="","",INDEX(반배정!E$7:E$86,$L41)) | F41: =IF($L41="","",INDEX(반배정!F$7:F$86,$L41)) | G41: =IF($L41="","",INDEX(반배정!G$7:G$86,$L41)) | H41: =IF($L41="","",INDEX(반배정!L$7:L$86,$L41)) | I41: =IF($L41="","",INDEX(반배정!J$7:J$86,$L41)) | J41: =IF($L41="","",INDEX(반배정!M$7:M$86,$L41)) | K41: =IFERROR(SMALL(반배정!$N$7:$N$86,35),"") | L41: =IF(K41="","",MATCH(K41,반배정!$N$7:$N$86,0))
A42: =IF($L42="","",INDEX(반배정!H$7:H$86,$L42)) | B42: =IF($L42="","",INDEX(반배정!B$7:B$86,$L42)) | C42: =IF($L42="","",INDEX(반배정!C$7:C$86,$L42)) | D42: =IF($L42="","",INDEX(반배정!D$7:D$86,$L42)) | E42: =IF($L42="","",INDEX(반배정!E$7:E$86,$L42)) | F42: =IF($L42="","",INDEX(반배정!F$7:F$86,$L42)) | G42: =IF($L42="","",INDEX(반배정!G$7:G$86,$L42)) | H42: =IF($L42="","",INDEX(반배정!L$7:L$86,$L42)) | I42: =IF($L42="","",INDEX(반배정!J$7:J$86,$L42)) | J42: =IF($L42="","",INDEX(반배정!M$7:M$86,$L42)) | K42: =IFERROR(SMALL(반배정!$N$7:$N$86,36),"") | L42: =IF(K42="","",MATCH(K42,반배정!$N$7:$N$86,0))
A43: =IF($L43="","",INDEX(반배정!H$7:H$86,$L43)) | B43: =IF($L43="","",INDEX(반배정!B$7:B$86,$L43)) | C43: =IF($L43="","",INDEX(반배정!C$7:C$86,$L43)) | D43: =IF($L43="","",INDEX(반배정!D$7:D$86,$L43)) | E43: =IF($L43="","",INDEX(반배정!E$7:E$86,$L43)) | F43: =IF($L43="","",INDEX(반배정!F$7:F$86,$L43)) | G43: =IF($L43="","",INDEX(반배정!G$7:G$86,$L43)) | H43: =IF($L43="","",INDEX(반배정!L$7:L$86,$L43)) | I43: =IF($L43="","",INDEX(반배정!J$7:J$86,$L43)) | J43: =IF($L43="","",INDEX(반배정!M$7:M$86,$L43)) | K43: =IFERROR(SMALL(반배정!$N$7:$N$86,37),"") | L43: =IF(K43="","",MATCH(K43,반배정!$N$7:$N$86,0))
...

Sheet 문항분석
A1: 문항 분석
A2: 변별도 = 1반 정답률 − 3반 정답률 (0.3 이상이면 반을 잘 가르는 문항). 객관식은 선지별 선택 인원으로 매력적 오답을 확인하세요.
A4: 공통수학1
A5: 문항 | B5: 유형 | C5: 단원 | D5: 난이도 | E5: 배점 | F5: 정답 | G5: 응시 | H5: 정답자 | I5: 정답률 | J5: =설정!$B$6&" 정답률" -> 심화반 정답률 | K5: =설정!$B$7&" 정답률" -> 정규반 정답률 | L5: =설정!$B$8&" 정답률" -> 기본반 정답률 | M5: 변별도 | N5: 진단 | O5: ① | P5: ② | Q5: ③ | R5: ④ | S5: ⑤
A6: 1 | B6: 객관식 | C6: =공수1!D4 -> 다항식 | D6: =공수1!D5 -> 하 | E6: =공수1!D3 -> 5 | F6: =IF(공수1!$D$2="","",공수1!$D$2) | G6: =COUNT(공수1!$Y$7:$Y$86) -> 0 | H6: =IF(F6="","",SUMPRODUCT((공수1!$D$7:$D$86=공수1!$D$2)*(공수1!$D$7:$D$86<>""))) | I6: =IF(OR(F6="",G6=0),"",H6/G6) | J6: =IF(F6="","",IFERROR(SUMPRODUCT((공수1!$D$7:$D$86=공수1!$D$2)*(공수1!$D$7:$D$86<>"")*(반배정!$I$7:$I$86=설정!$B$6))/COUNTIFS(반배정!$I$7:$I$86,설정!$B$6,공수1!$Y$7:$Y$86,">=0"),"")) | K6: =IF(F6="","",IFERROR(SUMPRODUCT((공수1!$D$7:$D$86=공수1!$D$2)*(공수1!$D$7:$D$86<>"")*(반배정!$I$7:$I$86=설정!$B$7))/COUNTIFS(반배정!$I$7:$I$86,설정!$B$7,공수1!$Y$7:$Y$86,">=0"),"")) | L6: =IF(F6="","",IFERROR(SUMPRODUCT((공수1!$D$7:$D$86=공수1!$D$2)*(공수1!$D$7:$D$86<>"")*(반배정!$I$7:$I$86=설정!$B$8))/COUNTIFS(반배정!$I$7:$I$86,설정!$B$8,공수1!$Y$7:$Y$86,">=0"),"")) | M6: =IF(OR(J6="",L6=""),"",J6-L6) | N6: =IF(I6="","",IF(AND(M6<>"",M6<0),"역변별·문항검토",IF(I6>=0.9,"매우 쉬움",IF(I6<=0.15,"매우 어려움",IF(AND(M6<>"",M6<0.2),"변별력 낮음","양호"))))) | O6: =IF(G6=0,"",COUNTIF(공수1!$D$7:$D$86,1)) | P6: =IF(G6=0,"",COUNTIF(공수1!$D$7:$D$86,2)) | Q6: =IF(G6=0,"",COUNTIF(공수1!$D$7:$D$86,3)) | R6: =IF(G6=0,"",COUNTIF(공수1!$D$7:$D$86,4)) | S6: =IF(G6=0,"",COUNTIF(공수1!$D$7:$D$86,5))
A7: 2 | B7: 객관식 | C7: =공수1!E4 -> 다항식 | D7: =공수1!E5 -> 하 | E7: =공수1!E3 -> 5 | F7: =IF(공수1!$E$2="","",공수1!$E$2) | G7: =COUNT(공수1!$Y$7:$Y$86) -> 0 | H7: =IF(F7="","",SUMPRODUCT((공수1!$E$7:$E$86=공수1!$E$2)*(공수1!$E$7:$E$86<>""))) | I7: =IF(OR(F7="",G7=0),"",H7/G7) | J7: =IF(F7="","",IFERROR(SUMPRODUCT((공수1!$E$7:$E$86=공수1!$E$2)*(공수1!$E$7:$E$86<>"")*(반배정!$I$7:$I$86=설정!$B$6))/COUNTIFS(반배정!$I$7:$I$86,설정!$B$6,공수1!$Y$7:$Y$86,">=0"),"")) | K7: =IF(F7="","",IFERROR(SUMPRODUCT((공수1!$E$7:$E$86=공수1!$E$2)*(공수1!$E$7:$E$86<>"")*(반배정!$I$7:$I$86=설정!$B$7))/COUNTIFS(반배정!$I$7:$I$86,설정!$B$7,공수1!$Y$7:$Y$86,">=0"),"")) | L7: =IF(F7="","",IFERROR(SUMPRODUCT((공수1!$E$7:$E$86=공수1!$E$2)*(공수1!$E$7:$E$86<>"")*(반배정!$I$7:$I$86=설정!$B$8))/COUNTIFS(반배정!$I$7:$I$86,설정!$B$8,공수1!$Y$7:$Y$86,">=0"),"")) | M7: =IF(OR(J7="",L7=""),"",J7-L7) | N7: =IF(I7="","",IF(AND(M7<>"",M7<0),"역변별·문항검토",IF(I7>=0.9,"매우 쉬움",IF(I7<=0.15,"매우 어려움",IF(AND(M7<>"",M7<0.2),"변별력 낮음","양호"))))) | O7: =IF(G7=0,"",COUNTIF(공수1!$E$7:$E$86,1)) | P7: =IF(G7=0,"",COUNTIF(공수1!$E$7:$E$86,2)) | Q7: =IF(G7=0,"",COUNTIF(공수1!$E$7:$E$86,3)) | R7: =IF(G7=0,"",COUNTIF(공수1!$E$7:$E$86,4)) | S7: =IF(G7=0,"",COUNTIF(공수1!$E$7:$E$86,5))
A8: 3 | B8: 객관식 | C8: =공수1!F4 -> 다항식 | D8: =공수1!F5 -> 하 | E8: =공수1!F3 -> 5 | F8: =IF(공수1!$F$2="","",공수1!$F$2) | G8: =COUNT(공수1!$Y$7:$Y$86) -> 0 | H8: =IF(F8="","",SUMPRODUCT((공수1!$F$7:$F$86=공수1!$F$2)*(공수1!$F$7:$F$86<>""))) | I8: =IF(OR(F8="",G8=0),"",H8/G8) | J8: =IF(F8="","",IFERROR(SUMPRODUCT((공수1!$F$7:$F$86=공수1!$F$2)*(공수1!$F$7:$F$86<>"")*(반배정!$I$7:$I$86=설정!$B$6))/COUNTIFS(반배정!$I$7:$I$86,설정!$B$6,공수1!$Y$7:$Y$86,">=0"),"")) | K8: =IF(F8="","",IFERROR(SUMPRODUCT((공수1!$F$7:$F$86=공수1!$F$2)*(공수1!$F$7:$F$86<>"")*(반배정!$I$7:$I$86=설정!$B$7))/COUNTIFS(반배정!$I$7:$I$86,설정!$B$7,공수1!$Y$7:$Y$86,">=0"),"")) | L8: =IF(F8="","",IFERROR(SUMPRODUCT((공수1!$F$7:$F$86=공수1!$F$2)*(공수1!$F$7:$F$86<>"")*(반배정!$I$7:$I$86=설정!$B$8))/COUNTIFS(반배정!$I$7:$I$86,설정!$B$8,공수1!$Y$7:$Y$86,">=0"),"")) | M8: =IF(OR(J8="",L8=""),"",J8-L8) | N8: =IF(I8="","",IF(AND(M8<>"",M8<0),"역변별·문항검토",IF(I8>=0.9,"매우 쉬움",IF(I8<=0.15,"매우 어려움",IF(AND(M8<>"",M8<0.2),"변별력 낮음","양호"))))) | O8: =IF(G8=0,"",COUNTIF(공수1!$F$7:$F$86,1)) | P8: =IF(G8=0,"",COUNTIF(공수1!$F$7:$F$86,2)) | Q8: =IF(G8=0,"",COUNTIF(공수1!$F$7:$F$86,3)) | R8: =IF(G8=0,"",COUNTIF(공수1!$F$7:$F$86,4)) | S8: =IF(G8=0,"",COUNTIF(공수1!$F$7:$F$86,5))
A9: 4 | B9: 객관식 | C9: =공수1!G4 -> 다항식 | D9: =공수1!G5 -> 하 | E9: =공수1!G3 -> 5 | F9: =IF(공수1!$G$2="","",공수1!$G$2) | G9: =COUNT(공수1!$Y$7:$Y$86) -> 0 | H9: =IF(F9="","",SUMPRODUCT((공수1!$G$7:$G$86=공수1!$G$2)*(공수1!$G$7:$G$86<>""))) | I9: =IF(OR(F9="",G9=0),"",H9/G9) | J9: =IF(F9="","",IFERROR(SUMPRODUCT((공수1!$G$7:$G$86=공수1!$G$2)*(공수1!$G$7:$G$86<>"")*(반배정!$I$7:$I$86=설정!$B$6))/COUNTIFS(반배정!$I$7:$I$86,설정!$B$6,공수1!$Y$7:$Y$86,">=0"),"")) | K9: =IF(F9="","",IFERROR(SUMPRODUCT((공수1!$G$7:$G$86=공수1!$G$2)*(공수1!$G$7:$G$86<>"")*(반배정!$I$7:$I$86=설정!$B$7))/COUNTIFS(반배정!$I$7:$I$86,설정!$B$7,공수1!$Y$7:$Y$86,">=0"),"")) | L9: =IF(F9="","",IFERROR(SUMPRODUCT((공수1!$G$7:$G$86=공수1!$G$2)*(공수1!$G$7:$G$86<>"")*(반배정!$I$7:$I$86=설정!$B$8))/COUNTIFS(반배정!$I$7:$I$86,설정!$B$8,공수1!$Y$7:$Y$86,">=0"),"")) | M9: =IF(OR(J9="",L9=""),"",J9-L9) | N9: =IF(I9="","",IF(AND(M9<>"",M9<0),"역변별·문항검토",IF(I9>=0.9,"매우 쉬움",IF(I9<=0.15,"매우 어려움",IF(AND(M9<>"",M9<0.2),"변별력 낮음","양호"))))) | O9: =IF(G9=0,"",COUNTIF(공수1!$G$7:$G$86,1)) | P9: =IF(G9=0,"",COUNTIF(공수1!$G$7:$G$86,2)) | Q9: =IF(G9=0,"",COUNTIF(공수1!$G$7:$G$86,3)) | R9: =IF(G9=0,"",COUNTIF(공수1!$G$7:$G$86,4)) | S9: =IF(G9=0,"",COUNTIF(공수1!$G$7:$G$86,5))
