Workbook

Sheet 설정
A1: 예비고1 반편성고사 — 설정
A2: 노란 칸만 입력하세요. 반 이름·정원·반영비율·단원명을 바꾸면 모든 시트에 자동 반영됩니다. 정답·배점·단원·난이도는 '공수1', '공수2' 시트 위쪽(2~5행)에서 입력합니다.
A4: ① 반 배정 기준 (절대평가)
A5: 순서 | B5: 반 이름 | C5: 공수1 이상 | D5: 합계 이상 | E5: 한 과목 이하 | F5: 합계 이하 | H5: · 점수(100점 만점)로 판정. 한 줄 안의 조건은 '하나라도' 맞으면 그 반(또는) · 위 순위부터 차례로 확인해 처음 맞는 반에 배정, 조건이 모두 빈 줄은 '나머지' · 합계 = 공수1 + 공수2, 한 과목 이하 = 공수1·공수2 중 하나라도 그 점수 이하 · 예) TF1반: 공수1 51점 이상 또는 합계 120점 이상
A6: 1순위 | B6: TF1반 | C6: 51 | D6: 120
A7: 2순위 | B7: HF반 | E7: 20 | F7: 60
A8: 3순위 | B8: TF2반
A9: 그 외 | B9: 보류 | C9: 미응시 과목이 있어 위 기준으로 정할 수 없으면 보류 → 상담 후 수동 배정
A11: ② 점수 반영
B12: 항목 | C12: 값
B13: 공통수학1 반영비율 | C13: 1 | E13: 환산총점(석차·참고용) = 공수1 점수×비율 + 공수2 점수×비율
B14: 공통수학2 반영비율 | C14: 1 | E14: 반 배정은 ①의 기준(과목 점수·합계)으로만 결정
B15: 경계 범위(점) | C15: 3 | E15: 과목 점수나 합계가 ①의 기준 점수와 이 값 이내로 차이 나면 '경계'로 표시 → 상담·재검토 대상
A17: ③ 단원 목록 · 출제 설계 확인
A18: 과목 | B18: 단원 | C18: 문항 수 | D18: 배점 합 | E18: 포함 내용(2022 개정)
A19: 공통수학1 | B19: 다항식 | C19: =COUNTIF('공수1'!$D$4:$W$4,B19) | D19: =SUMIF('공수1'!$D$4:$W$4,B19,'공수1'!$D$3:$W$3) | E19: 다항식의 연산, 나머지정리, 인수분해
A20: 공통수학1 | B20: 방정식과 부등식 | C20: =COUNTIF('공수1'!$D$4:$W$4,B20) | D20: =SUMIF('공수1'!$D$4:$W$4,B20,'공수1'!$D$3:$W$3) | E20: 복소수, 이차방정식, 이차함수, 여러 가지 방정식·부등식
A21: 공통수학1 | B21: 경우의 수 | C21: =COUNTIF('공수1'!$D$4:$W$4,B21) | D21: =SUMIF('공수1'!$D$4:$W$4,B21,'공수1'!$D$3:$W$3) | E21: 합·곱의 법칙, 순열, 조합
A22: 공통수학1 | B22: 행렬 | C22: =COUNTIF('공수1'!$D$4:$W$4,B22) | D22: =SUMIF('공수1'!$D$4:$W$4,B22,'공수1'!$D$3:$W$3) | E22: 행렬과 그 연산
A23: 공통수학1 | B23: 합계 | C23: =SUM(C19:C22) | D23: =SUM(D19:D22) | E23: ← 문항 수 20, 배점 합 100인지 확인
A24: 공통수학2 | B24: 도형의 방정식 | C24: =COUNTIF('공수2'!$D$4:$W$4,B24) | D24: =SUMIF('공수2'!$D$4:$W$4,B24,'공수2'!$D$3:$W$3) | E24: 평면좌표, 직선·원의 방정식, 도형의 이동
A25: 공통수학2 | B25: 집합과 명제 | C25: =COUNTIF('공수2'!$D$4:$W$4,B25) | D25: =SUMIF('공수2'!$D$4:$W$4,B25,'공수2'!$D$3:$W$3) | E25: 집합, 명제
A26: 공통수학2 | B26: 함수와 그래프 | C26: =COUNTIF('공수2'!$D$4:$W$4,B26) | D26: =SUMIF('공수2'!$D$4:$W$4,B26,'공수2'!$D$3:$W$3) | E26: 함수, 합성·역함수, 유리·무리함수
A27: 공통수학2 | B27: 합계 | C27: =SUM(C24:C26) | D27: =SUM(D24:D26) | E27: ← 문항 수 20, 배점 합 100인지 확인
A30: ④ 학부모 보고서 설정
A31: 항목 | B31: 값
A32: 학원명 | B32: OO수학학원
A33: 보고서 제목 | B33: 예비고1 진단평가 결과 보고서
A34: 시험일 | B34: 2026년 12월 00일
A35: 전체 평균 표시 | B35: 표시 | F35: '숨김'이면 보고서에 평균을 싣지 않음
A36: '매우 우수' 기준(득점률 %) | B36: 85
A37: '우수' 기준(득점률 %) | B37: 70
A38: '양호' 기준(득점률 %) | B38: 50 | F38: 득점률이 '양호' 기준 미만이면 '보완 필요'
A39: 상담 안내 문구 | B39: 보고서를 받아보신 뒤 개별 상담을 진행합니다. 상담 일정은 담당 선생님께서 개별적으로 연락드리겠습니다.
A40: 학원 연락처 | B40: 02-000-0000
A43: ⑤ 단원별 학습 제언 (보완이 필요한 단원에 자동 기재)
A44: 단원 | B44: 학습 제언 문구
A45: =B19 | B45: 다항식의 연산과 나머지정리, 인수분해 공식을 정확하고 빠르게 적용하는 연습이 필요합니다.
A46: =B20 | B46: 복소수 계산과 이차방정식·이차함수의 관계를 그래프와 연결해 이해하는 학습이 필요합니다.
A47: =B21 | B47: 합·곱의 법칙과 순열·조합을 구분하는 기준을 정리하고, 빠짐없이 중복 없이 세는 연습이 필요합니다.
...

Sheet 학생명단
A1: 학생 명단
A2: 노란 칸에 학생 정보를 입력하세요. 여기 입력한 순서(행)가 공수1·공수2·반배정 시트의 행과 그대로 연결됩니다. 7행은 예시이니 지우고 사용하세요. 기존 반명: 재원생은 현재 반, 신규 학생은 '신규'.
A6: No | B6: 이름 | C6: 학교 | D6: 구분 | E6: 기존 반명 | F6: 학습 진도 | G6: 현재 등원 요일 | H6: 성취도 | I6: 공통수학1 | J6: 공통수학2 | K6: 자사/일반
A7: 1 | B7: 홍길동(예시) | C7: OO중 | D7: 외부 | E7: 신규 | F7: 공통수학까지 | G7: 월수금 | I7: =IF('공수1'!Y7="","",'공수1'!Y7) | J7: =IF('공수2'!Y7="","",'공수2'!Y7)
A8: 2 | I8: =IF('공수1'!Y8="","",'공수1'!Y8) | J8: =IF('공수2'!Y8="","",'공수2'!Y8)
A9: 3 | I9: =IF('공수1'!Y9="","",'공수1'!Y9) | J9: =IF('공수2'!Y9="","",'공수2'!Y9)
A10: 4 | I10: =IF('공수1'!Y10="","",'공수1'!Y10) | J10: =IF('공수2'!Y10="","",'공수2'!Y10)
A11: 5 | I11: =IF('공수1'!Y11="","",'공수1'!Y11) | J11: =IF('공수2'!Y11="","",'공수2'!Y11)
A12: 6 | I12: =IF('공수1'!Y12="","",'공수1'!Y12) | J12: =IF('공수2'!Y12="","",'공수2'!Y12)
A13: 7 | I13: =IF('공수1'!Y13="","",'공수1'!Y13) | J13: =IF('공수2'!Y13="","",'공수2'!Y13)
A14: 8 | I14: =IF('공수1'!Y14="","",'공수1'!Y14) | J14: =IF('공수2'!Y14="","",'공수2'!Y14)
A15: 9 | I15: =IF('공수1'!Y15="","",'공수1'!Y15) | J15: =IF('공수2'!Y15="","",'공수2'!Y15)
A16: 10 | I16: =IF('공수1'!Y16="","",'공수1'!Y16) | J16: =IF('공수2'!Y16="","",'공수2'!Y16)
A17: 11 | I17: =IF('공수1'!Y17="","",'공수1'!Y17) | J17: =IF('공수2'!Y17="","",'공수2'!Y17)
A18: 12 | I18: =IF('공수1'!Y18="","",'공수1'!Y18) | J18: =IF('공수2'!Y18="","",'공수2'!Y18)
A19: 13 | I19: =IF('공수1'!Y19="","",'공수1'!Y19) | J19: =IF('공수2'!Y19="","",'공수2'!Y19)
... A156: 150 | I156: =IF('공수1'!Y156="","",'공수1'!Y156) | J156: =IF('공수2'!Y156="","",'공수2'!Y156)

Sheet 공수1
A1: 공통수학1 채점표 | D1: 객관식 1~14번: 학생이 고른 번호(1~5, 답안지 스캔으로 자동 입력 가능) 단답형 15~20번: 직접 채점해 맞으면 1, 틀리면 0 → 틀린 칸은 빨간색, 점수 자동 계산. 결시생은 비워두면 미응시 처리.
A2: 정답 ▶ | D2: 4 | E2: 2 | F2: 3 | G2: 5 | H2: 1 | I2: 3 | J2: 4 | K2: 2 | L2: 5 | M2: 1 | N2: 2 | O2: 3 | P2: 4 | Q2: 5 | R2: 1 | S2: 1 | T2: 1 | U2: 1 | V2: 1 | W2: 1
A3: 배점 ▶ | D3: 3 | E3: 3 | F3: 3 | G3: 4 | H3: 4 | I3: 4 | J3: 5 | K3: 5 | L3: 5 | M3: 6 | N3: 6 | O3: 6 | P3: 6 | Q3: 6 | R3: 5 | S3: 5 | T3: 5 | U3: 6 | V3: 6 | W3: 7 | X3: =COUNT(D2:W2) | Y3: =SUM(D3:W3) | Z3: =SUMIF($D$4:$W$4,Z$6,$D$3:$W$3) | AA3: =SUMIF($D$4:$W$4,AA$6,$D$3:$W$3) | AB3: =SUMIF($D$4:$W$4,AB$6,$D$3:$W$3) | AC3: =SUMIF($D$4:$W$4,AC$6,$D$3:$W$3)
A4: 단원 ▶ | D4: 다항식 | E4: 행렬 | F4: 방정식과 부등식 | G4: 방정식과 부등식 | H4: 다항식 | I4: 방정식과 부등식 | J4: 방정식과 부등식 | K4: 경우의 수 | L4: 방정식과 부등식 | M4: 행렬 | N4: 경우의 수 | O4: 방정식과 부등식 | P4: 다항식 | Q4: 방정식과 부등식 | R4: 방정식과 부등식 | S4: 경우의 수 | T4: 다항식 | U4: 행렬 | V4: 방정식과 부등식 | W4: 다항식
A5: 난이도 ▶ | D5: 하 | E5: 하 | F5: 하 | G5: 중하 | H5: 중하 | I5: 중하 | J5: 중상 | K5: 중상 | L5: 중상 | M5: 상 | N5: 상 | O5: 상 | P5: 최상 | Q5: 최상 | R5: 중상 | S5: 중상 | T5: 중상 | U5: 상 | V5: 최상 | W5: 최상 | X5: 정답입력수▲ | Y5: 만점 ▲ | Z5: 만점 ▲ | AA5: 만점 ▲ | AB5: 만점 ▲ | AC5: 만점 ▲
A6: No | B6: 이름 | C6: 학교 | D6: 1 객관식 | E6: 2 객관식 | F6: 3 객관식 | G6: 4 객관식 | H6: 5 객관식 | I6: 6 객관식 | J6: 7 객관식 | K6: 8 객관식 | L6: 9 객관식 | M6: 10 객관식 | N6: 11 객관식 | O6: 12 객관식 | P6: 13 객관식 | Q6: 14 객관식 | R6: 15 단답형 답 24 | S6: 16 단답형 답 864 | T6: 17 단답형 답 8 | U6: 18 단답형 답 76 | V6: 19 단답형 답 27 | W6: 20 단답형 답 65 | X6: 맞힌 개수 | Y6: 총점 | Z6: ='설정'!B19 | AA6: ='설정'!B20 | AB6: ='설정'!B21 | AC6: ='설정'!B22
A7: 1 | B7: =IF('학생명단'!B7="","",'학생명단'!B7) | C7: =IF('학생명단'!C7="","",'학생명단'!C7) | X7: =IF(COUNTA(D7:W7)=0,"",SUMPRODUCT((D7:W7=$D$2:$W$2)*(D7:W7<>""))) | Y7: =IF(COUNTA(D7:W7)=0,"",SUMPRODUCT((D7:W7=$D$2:$W$2)*(D7:W7<>"")*$D$3:$W$3)) | Z7: =IF($Y7="","",SUMPRODUCT(($D7:$W7=$D$2:$W$2)*($D7:$W7<>"")*$D$3:$W$3*($D$4:$W$4=Z$6))) | AA7: =IF($Y7="","",SUMPRODUCT(($D7:$W7=$D$2:$W$2)*($D7:$W7<>"")*$D$3:$W$3*($D$4:$W$4=AA$6))) | AB7: =IF($Y7="","",SUMPRODUCT(($D7:$W7=$D$2:$W$2)*($D7:$W7<>"")*$D$3:$W$3*($D$4:$W$4=AB$6))) | AC7: =IF($Y7="","",SUMPRODUCT(($D7:$W7=$D$2:$W$2)*($D7:$W7<>"")*$D$3:$W$3*($D$4:$W$4=AC$6)))
A8: 2 | B8: =IF('학생명단'!B8="","",'학생명단'!B8) | C8: =IF('학생명단'!C8="","",'학생명단'!C8) | X8: =IF(COUNTA(D8:W8)=0,"",SUMPRODUCT((D8:W8=$D$2:$W$2)*(D8:W8<>""))) | Y8: =IF(COUNTA(D8:W8)=0,"",SUMPRODUCT((D8:W8=$D$2:$W$2)*(D8:W8<>"")*$D$3:$W$3)) | Z8: =IF($Y8="","",SUMPRODUCT(($D8:$W8=$D$2:$W$2)*($D8:$W8<>"")*$D$3:$W$3*($D$4:$W$4=Z$6))) | AA8: =IF($Y8="","",SUMPRODUCT(($D8:$W8=$D$2:$W$2)*($D8:$W8<>"")*$D$3:$W$3*($D$4:$W$4=AA$6))) | AB8: =IF($Y8="","",SUMPRODUCT(($D8:$W8=$D$2:$W$2)*($D8:$W8<>"")*$D$3:$W$3*($D$4:$W$4=AB$6))) | AC8: =IF($Y8="","",SUMPRODUCT(($D8:$W8=$D$2:$W$2)*($D8:$W8<>"")*$D$3:$W$3*($D$4:$W$4=AC$6)))
A9: 3 | B9: =IF('학생명단'!B9="","",'학생명단'!B9) | C9: =IF('학생명단'!C9="","",'학생명단'!C9) | X9: =IF(COUNTA(D9:W9)=0,"",SUMPRODUCT((D9:W9=$D$2:$W$2)*(D9:W9<>""))) | Y9: =IF(COUNTA(D9:W9)=0,"",SUMPRODUCT((D9:W9=$D$2:$W$2)*(D9:W9<>"")*$D$3:$W$3)) | Z9: =IF($Y9="","",SUMPRODUCT(($D9:$W9=$D$2:$W$2)*($D9:$W9<>"")*$D$3:$W$3*($D$4:$W$4=Z$6))) | AA9: =IF($Y9="","",SUMPRODUCT(($D9:$W9=$D$2:$W$2)*($D9:$W9<>"")*$D$3:$W$3*($D$4:$W$4=AA$6))) | AB9: =IF($Y9="","",SUMPRODUCT(($D9:$W9=$D$2:$W$2)*($D9:$W9<>"")*$D$3:$W$3*($D$4:$W$4=AB$6))) | AC9: =IF($Y9="","",SUMPRODUCT(($D9:$W9=$D$2:$W$2)*($D9:$W9<>"")*$D$3:$W$3*($D$4:$W$4=AC$6)))
A10: 4 | B10: =IF('학생명단'!B10="","",'학생명단'!B10) | C10: =IF('학생명단'!C10="","",'학생명단'!C10) | X10: =IF(COUNTA(D10:W10)=0,"",SUMPRODUCT((D10:W10=$D$2:$W$2)*(D10:W10<>""))) | Y10: =IF(COUNTA(D10:W10)=0,"",SUMPRODUCT((D10:W10=$D$2:$W$2)*(D10:W10<>"")*$D$3:$W$3)) | Z10: =IF($Y10="","",SUMPRODUCT(($D10:$W10=$D$2:$W$2)*($D10:$W10<>"")*$D$3:$W$3*($D$4:$W$4=Z$6))) | AA10: =IF($Y10="","",SUMPRODUCT(($D10:$W10=$D$2:$W$2)*($D10:$W10<>"")*$D$3:$W$3*($D$4:$W$4=AA$6))) | AB10: =IF($Y10="","",SUMPRODUCT(($D10:$W10=$D$2:$W$2)*($D10:$W10<>"")*$D$3:$W$3*($D$4:$W$4=AB$6))) | AC10: =IF($Y10="","",SUMPRODUCT(($D10:$W10=$D$2:$W$2)*($D10:$W10<>"")*$D$3:$W$3*($D$4:$W$4=AC$6)))
A11: 5 | B11: =IF('학생명단'!B11="","",'학생명단'!B11) | C11: =IF('학생명단'!C11="","",'학생명단'!C11) | X11: =IF(COUNTA(D11:W11)=0,"",SUMPRODUCT((D11:W11=$D$2:$W$2)*(D11:W11<>""))) | Y11: =IF(COUNTA(D11:W11)=0,"",SUMPRODUCT((D11:W11=$D$2:$W$2)*(D11:W11<>"")*$D$3:$W$3)) | Z11: =IF($Y11="","",SUMPRODUCT(($D11:$W11=$D$2:$W$2)*($D11:$W11<>"")*$D$3:$W$3*($D$4:$W$4=Z$6))) | AA11: =IF($Y11="","",SUMPRODUCT(($D11:$W11=$D$2:$W$2)*($D11:$W11<>"")*$D$3:$W$3*($D$4:$W$4=AA$6))) | AB11: =IF($Y11="","",SUMPRODUCT(($D11:$W11=$D$2:$W$2)*($D11:$W11<>"")*$D$3:$W$3*($D$4:$W$4=AB$6))) | AC11: =IF($Y11="","",SUMPRODUCT(($D11:$W11=$D$2:$W$2)*($D11:$W11<>"")*$D$3:$W$3*($D$4:$W$4=AC$6)))
A12: 6 | B12: =IF('학생명단'!B12="","",'학생명단'!B12) | C12: =IF('학생명단'!C12="","",'학생명단'!C12) | X12: =IF(COUNTA(D12:W12)=0,"",SUMPRODUCT((D12:W12=$D$2:$W$2)*(D12:W12<>""))) | Y12: =IF(COUNTA(D12:W12)=0,"",SUMPRODUCT((D12:W12=$D$2:$W$2)*(D12:W12<>"")*$D$3:$W$3)) | Z12: =IF($Y12="","",SUMPRODUCT(($D12:$W12=$D$2:$W$2)*($D12:$W12<>"")*$D$3:$W$3*($D$4:$W$4=Z$6))) | AA12: =IF($Y12="","",SUMPRODUCT(($D12:$W12=$D$2:$W$2)*($D12:$W12<>"")*$D$3:$W$3*($D$4:$W$4=AA$6))) | AB12: =IF($Y12="","",SUMPRODUCT(($D12:$W12=$D$2:$W$2)*($D12:$W12<>"")*$D$3:$W$3*($D$4:$W$4=AB$6))) | AC12: =IF($Y12="","",SUMPRODUCT(($D12:$W12=$D$2:$W$2)*($D12:$W12<>"")*$D$3:$W$3*($D$4:$W$4=AC$6)))
A13: 7 | B13: =IF('학생명단'!B13="","",'학생명단'!B13) | C13: =IF('학생명단'!C13="","",'학생명단'!C13) | X13: =IF(COUNTA(D13:W13)=0,"",SUMPRODUCT((D13:W13=$D$2:$W$2)*(D13:W13<>""))) | Y13: =IF(COUNTA(D13:W13)=0,"",SUMPRODUCT((D13:W13=$D$2:$W$2)*(D13:W13<>"")*$D$3:$W$3)) | Z13: =IF($Y13="","",SUMPRODUCT(($D13:$W13=$D$2:$W$2)*($D13:$W13<>"")*$D$3:$W$3*($D$4:$W$4=Z$6))) | AA13: =IF($Y13="","",SUMPRODUCT(($D13:$W13=$D$2:$W$2)*($D13:$W13<>"")*$D$3:$W$3*($D$4:$W$4=AA$6))) | AB13: =IF($Y13="","",SUMPRODUCT(($D13:$W13=$D$2:$W$2)*($D13:$W13<>"")*$D$3:$W$3*($D$4:$W$4=AB$6))) | AC13: =IF($Y13="","",SUMPRODUCT(($D13:$W13=$D$2:$W$2)*($D13:$W13<>"")*$D$3:$W$3*($D$4:$W$4=AC$6)))
A14: 8 | B14: =IF('학생명단'!B14="","",'학생명단'!B14) | C14: =IF('학생명단'!C14="","",'학생명단'!C14) | X14: =IF(COUNTA(D14:W14)=0,"",SUMPRODUCT((D14:W14=$D$2:$W$2)*(D14:W14<>""))) | Y14: =IF(COUNTA(D14:W14)=0,"",SUMPRODUCT((D14:W14=$D$2:$W$2)*(D14:W14<>"")*$D$3:$W$3)) | Z14: =IF($Y14="","",SUMPRODUCT(($D14:$W14=$D$2:$W$2)*($D14:$W14<>"")*$D$3:$W$3*($D$4:$W$4=Z$6))) | AA14: =IF($Y14="","",SUMPRODUCT(($D14:$W14=$D$2:$W$2)*($D14:$W14<>"")*$D$3:$W$3*($D$4:$W$4=AA$6))) | AB14: =IF($Y14="","",SUMPRODUCT(($D14:$W14=$D$2:$W$2)*($D14:$W14<>"")*$D$3:$W$3*($D$4:$W$4=AB$6))) | AC14: =IF($Y14="","",SUMPRODUCT(($D14:$W14=$D$2:$W$2)*($D14:$W14<>"")*$D$3:$W$3*($D$4:$W$4=AC$6)))
A15: 9 | B15: =IF('학생명단'!B15="","",'학생명단'!B15) | C15: =IF('학생명단'!C15="","",'학생명단'!C15) | X15: =IF(COUNTA(D15:W15)=0,"",SUMPRODUCT((D15:W15=$D$2:$W$2)*(D15:W15<>""))) | Y15: =IF(COUNTA(D15:W15)=0,"",SUMPRODUCT((D15:W15=$D$2:$W$2)*(D15:W15<>"")*$D$3:$W$3)) | Z15: =IF($Y15="","",SUMPRODUCT(($D15:$W15=$D$2:$W$2)*($D15:$W15<>"")*$D$3:$W$3*($D$4:$W$4=Z$6))) | AA15: =IF($Y15="","",SUMPRODUCT(($D15:$W15=$D$2:$W$2)*($D15:$W15<>"")*$D$3:$W$3*($D$4:$W$4=AA$6))) | AB15: =IF($Y15="","",SUMPRODUCT(($D15:$W15=$D$2:$W$2)*($D15:$W15<>"")*$D$3:$W$3*($D$4:$W$4=AB$6))) | AC15: =IF($Y15="","",SUMPRODUCT(($D15:$W15=$D$2:$W$2)*($D15:$W15<>"")*$D$3:$W$3*($D$4:$W$4=AC$6)))
A16: 10 | B16: =IF('학생명단'!B16="","",'학생명단'!B16) | C16: =IF('학생명단'!C16="","",'학생명단'!C16) | X16: =IF(COUNTA(D16:W16)=0,"",SUMPRODUCT((D16:W16=$D$2:$W$2)*(D16:W16<>""))) | Y16: =IF(COUNTA(D16:W16)=0,"",SUMPRODUCT((D16:W16=$D$2:$W$2)*(D16:W16<>"")*$D$3:$W$3)) | Z16: =IF($Y16="","",SUMPRODUCT(($D16:$W16=$D$2:$W$2)*($D16:$W16<>"")*$D$3:$W$3*($D$4:$W$4=Z$6))) | AA16: =IF($Y16="","",SUMPRODUCT(($D16:$W16=$D$2:$W$2)*($D16:$W16<>"")*$D$3:$W$3*($D$4:$W$4=AA$6))) | AB16: =IF($Y16="","",SUMPRODUCT(($D16:$W16=$D$2:$W$2)*($D16:$W16<>"")*$D$3:$W$3*($D$4:$W$4=AB$6))) | AC16: =IF($Y16="","",SUMPRODUCT(($D16:$W16=$D$2:$W$2)*($D16:$W16<>"")*$D$3:$W$3*($D$4:$W$4=AC$6)))
A17: 11 | B17: =IF('학생명단'!B17="","",'학생명단'!B17) | C17: =IF('학생명단'!C17="","",'학생명단'!C17) | X17: =IF(COUNTA(D17:W17)=0,"",SUMPRODUCT((D17:W17=$D$2:$W$2)*(D17:W17<>""))) | Y17: =IF(COUNTA(D17:W17)=0,"",SUMPRODUCT((D17:W17=$D$2:$W$2)*(D17:W17<>"")*$D$3:$W$3)) | Z17: =IF($Y17="","",SUMPRODUCT(($D17:$W17=$D$2:$W$2)*($D17:$W17<>"")*$D$3:$W$3*($D$4:$W$4=Z$6))) | AA17: =IF($Y17="","",SUMPRODUCT(($D17:$W17=$D$2:$W$2)*($D17:$W17<>"")*$D$3:$W$3*($D$4:$W$4=AA$6))) | AB17: =IF($Y17="","",SUMPRODUCT(($D17:$W17=$D$2:$W$2)*($D17:$W17<>"")*$D$3:$W$3*($D$4:$W$4=AB$6))) | AC17: =IF($Y17="","",SUMPRODUCT(($D17:$W17=$D$2:$W$2)*($D17:$W17<>"")*$D$3:$W$3*($D$4:$W$4=AC$6)))
A18: 12 | B18: =IF('학생명단'!B18="","",'학생명단'!B18) | C18: =IF('학생명단'!C18="","",'학생명단'!C18) | X18: =IF(COUNTA(D18:W18)=0,"",SUMPRODUCT((D18:W18=$D$2:$W$2)*(D18:W18<>""))) | Y18: =IF(COUNTA(D18:W18)=0,"",SUMPRODUCT((D18:W18=$D$2:$W$2)*(D18:W18<>"")*$D$3:$W$3)) | Z18: =IF($Y18="","",SUMPRODUCT(($D18:$W18=$D$2:$W$2)*($D18:$W18<>"")*$D$3:$W$3*($D$4:$W$4=Z$6))) | AA18: =IF($Y18="","",SUMPRODUCT(($D18:$W18=$D$2:$W$2)*($D18:$W18<>"")*$D$3:$W$3*($D$4:$W$4=AA$6))) | AB18: =IF($Y18="","",SUMPRODUCT(($D18:$W18=$D$2:$W$2)*($D18:$W18<>"")*$D$3:$W$3*($D$4:$W$4=AB$6))) | AC18: =IF($Y18="","",SUMPRODUCT(($D18:$W18=$D$2:$W$2)*($D18:$W18<>"")*$D$3:$W$3*($D$4:$W$4=AC$6)))
... A156: 150 | B156: =IF('학생명단'!B156="","",'학생명단'!B156) | C156: =IF('학생명단'!C156="","",'학생명단'!C156) | X156: =IF(COUNTA(D156:W156)=0,"",SUMPRODUCT((D156:W156=$D$2:$W$2)*(D156:W156<>""))) | Y156: =IF(COUNTA(D156:W156)=0,"",SUMPRODUCT((D156:W156=$D$2:$W$2)*(D156:W156<>"")*$D$3:$W$3)) | Z156: =IF($Y156="","",SUMPRODUCT(($D156:$W156=$D$2:$W$2)*($D156:$W156<>"")*$D$3:$W$3*($D$4:$W$4=Z$6))) | AA156: =IF($Y156="","",SUMPRODUCT(($D156:$W156=$D$2:$W$2)*($D156:$W156<>"")*$D$3:$W$3*($D$4:$W$4=AA$6))) | AB156: =IF($Y156="","",SUMPRODUCT(($D156:$W156=$D$2:$W$2)*($D156:$W156<>"")*$D$3:$W$3*($D$4:$W$4=AB$6))) | AC156: =IF($Y156="","",SUMPRODUCT(($D156:$W156=$D$2:$W$2)*($D156:$W156<>"")*$D$3:$W$3*($D$4:$W$4=AC$6)))

Sheet 공수2
A1: 공통수학2 채점표 | D1: 객관식 1~14번: 학생이 고른 번호(1~5, 답안지 스캔으로 자동 입력 가능) 단답형 15~20번: 직접 채점해 맞으면 1, 틀리면 0 → 틀린 칸은 빨간색, 점수 자동 계산. 결시생은 비워두면 미응시 처리.
A2: 정답 ▶ | D2: 2 | E2: 4 | F2: 1 | G2: 3 | H2: 5 | I2: 2 | J2: 5 | K2: 2 | L2: 4 | M2: 4 | N2: 5 | O2: 3 | P2: 1 | Q2: 1 | R2: 1 | S2: 1 | T2: 1 | U2: 1 | V2: 1 | W2: 1
A3: 배점 ▶ | D3: 4 | E3: 4 | F3: 4 | G3: 4 | H3: 4 | I3: 4 | J3: 5 | K3: 5 | L3: 5 | M3: 5 | N3: 6 | O3: 6 | P3: 6 | Q3: 7 | R3: 4 | S3: 4 | T3: 5 | U3: 5 | V3: 6 | W3: 7 | X3: =COUNT(D2:W2) | Y3: =SUM(D3:W3) | Z3: =SUMIF($D$4:$W$4,Z$6,$D$3:$W$3) | AA3: =SUMIF($D$4:$W$4,AA$6,$D$3:$W$3) | AB3: =SUMIF($D$4:$W$4,AB$6,$D$3:$W$3)
A4: 단원 ▶ | D4: 도형의 방정식 | E4: 함수와 그래프 | F4: 도형의 방정식 | G4: 도형의 방정식 | H4: 도형의 방정식 | I4: 집합과 명제 | J4: 집합과 명제 | K4: 도형의 방정식 | L4: 도형의 방정식 | M4: 함수와 그래프 | N4: 함수와 그래프 | O4: 함수와 그래프 | P4: 도형의 방정식 | Q4: 도형의 방정식 | R4: 집합과 명제 | S4: 도형의 방정식 | T4: 집합과 명제 | U4: 함수와 그래프 | V4: 집합과 명제 | W4: 함수와 그래프
A5: 난이도 ▶ | D5: 하 | E5: 하 | F5: 하 | G5: 중하 | H5: 중하 | I5: 중하 | J5: 중상 | K5: 상 | L5: 중상 | M5: 상 | N5: 상 | O5: 상 | P5: 상 | Q5: 최상 | R5: 중상 | S5: 중상 | T5: 중상 | U5: 상 | V5: 최상 | W5: 최상 | X5: 정답입력수▲ | Y5: 만점 ▲ | Z5: 만점 ▲ | AA5: 만점 ▲ | AB5: 만점 ▲
A6: No | B6: 이름 | C6: 학교 | D6: 1 객관식 | E6: 2 객관식 | F6: 3 객관식 | G6: 4 객관식 | H6: 5 객관식 | I6: 6 객관식 | J6: 7 객관식 | K6: 8 객관식 | L6: 9 객관식 | M6: 10 객관식 | N6: 11 객관식 | O6: 12 객관식 | P6: 13 객관식 | Q6: 14 객관식 | R6: 15 단답형 답 9 | S6: 16 단답형 답 160 | T6: 17 단답형 답 12 | U6: 18 단답형 답 14 | V6: 19 단답형 답 15 | W6: 20 단답형 답 13 | X6: 맞힌 개수 | Y6: 총점 | Z6: ='설정'!B24 | AA6: ='설정'!B25 | AB6: ='설정'!B26
A7: 1 | B7: =IF('학생명단'!B7="","",'학생명단'!B7) | C7: =IF('학생명단'!C7="","",'학생명단'!C7) | X7: =IF(COUNTA(D7:W7)=0,"",SUMPRODUCT((D7:W7=$D$2:$W$2)*(D7:W7<>""))) | Y7: =IF(COUNTA(D7:W7)=0,"",SUMPRODUCT((D7:W7=$D$2:$W$2)*(D7:W7<>"")*$D$3:$W$3)) | Z7: =IF($Y7="","",SUMPRODUCT(($D7:$W7=$D$2:$W$2)*($D7:$W7<>"")*$D$3:$W$3*($D$4:$W$4=Z$6))) | AA7: =IF($Y7="","",SUMPRODUCT(($D7:$W7=$D$2:$W$2)*($D7:$W7<>"")*$D$3:$W$3*($D$4:$W$4=AA$6))) | AB7: =IF($Y7="","",SUMPRODUCT(($D7:$W7=$D$2:$W$2)*($D7:$W7<>"")*$D$3:$W$3*($D$4:$W$4=AB$6)))
A8: 2 | B8: =IF('학생명단'!B8="","",'학생명단'!B8) | C8: =IF('학생명단'!C8="","",'학생명단'!C8) | X8: =IF(COUNTA(D8:W8)=0,"",SUMPRODUCT((D8:W8=$D$2:$W$2)*(D8:W8<>""))) | Y8: =IF(COUNTA(D8:W8)=0,"",SUMPRODUCT((D8:W8=$D$2:$W$2)*(D8:W8<>"")*$D$3:$W$3)) | Z8: =IF($Y8="","",SUMPRODUCT(($D8:$W8=$D$2:$W$2)*($D8:$W8<>"")*$D$3:$W$3*($D$4:$W$4=Z$6))) | AA8: =IF($Y8="","",SUMPRODUCT(($D8:$W8=$D$2:$W$2)*($D8:$W8<>"")*$D$3:$W$3*($D$4:$W$4=AA$6))) | AB8: =IF($Y8="","",SUMPRODUCT(($D8:$W8=$D$2:$W$2)*($D8:$W8<>"")*$D$3:$W$3*($D$4:$W$4=AB$6)))
A9: 3 | B9: =IF('학생명단'!B9="","",'학생명단'!B9) | C9: =IF('학생명단'!C9="","",'학생명단'!C9) | X9: =IF(COUNTA(D9:W9)=0,"",SUMPRODUCT((D9:W9=$D$2:$W$2)*(D9:W9<>""))) | Y9: =IF(COUNTA(D9:W9)=0,"",SUMPRODUCT((D9:W9=$D$2:$W$2)*(D9:W9<>"")*$D$3:$W$3)) | Z9: =IF($Y9="","",SUMPRODUCT(($D9:$W9=$D$2:$W$2)*($D9:$W9<>"")*$D$3:$W$3*($D$4:$W$4=Z$6))) | AA9: =IF($Y9="","",SUMPRODUCT(($D9:$W9=$D$2:$W$2)*($D9:$W9<>"")*$D$3:$W$3*($D$4:$W$4=AA$6))) | AB9: =IF($Y9="","",SUMPRODUCT(($D9:$W9=$D$2:$W$2)*($D9:$W9<>"")*$D$3:$W$3*($D$4:$W$4=AB$6)))
A10: 4 | B10: =IF('학생명단'!B10="","",'학생명단'!B10) | C10: =IF('학생명단'!C10="","",'학생명단'!C10) | X10: =IF(COUNTA(D10:W10)=0,"",SUMPRODUCT((D10:W10=$D$2:$W$2)*(D10:W10<>""))) | Y10: =IF(COUNTA(D10:W10)=0,"",SUMPRODUCT((D10:W10=$D$2:$W$2)*(D10:W10<>"")*$D$3:$W$3)) | Z10: =IF($Y10="","",SUMPRODUCT(($D10:$W10=$D$2:$W$2)*($D10:$W10<>"")*$D$3:$W$3*($D$4:$W$4=Z$6))) | AA10: =IF($Y10="","",SUMPRODUCT(($D10:$W10=$D$2:$W$2)*($D10:$W10<>"")*$D$3:$W$3*($D$4:$W$4=AA$6))) | AB10: =IF($Y10="","",SUMPRODUCT(($D10:$W10=$D$2:$W$2)*($D10:$W10<>"")*$D$3:$W$3*($D$4:$W$4=AB$6)))
A11: 5 | B11: =IF('학생명단'!B11="","",'학생명단'!B11) | C11: =IF('학생명단'!C11="","",'학생명단'!C11) | X11: =IF(COUNTA(D11:W11)=0,"",SUMPRODUCT((D11:W11=$D$2:$W$2)*(D11:W11<>""))) | Y11: =IF(COUNTA(D11:W11)=0,"",SUMPRODUCT((D11:W11=$D$2:$W$2)*(D11:W11<>"")*$D$3:$W$3)) | Z11: =IF($Y11="","",SUMPRODUCT(($D11:$W11=$D$2:$W$2)*($D11:$W11<>"")*$D$3:$W$3*($D$4:$W$4=Z$6))) | AA11: =IF($Y11="","",SUMPRODUCT(($D11:$W11=$D$2:$W$2)*($D11:$W11<>"")*$D$3:$W$3*($D$4:$W$4=AA$6))) | AB11: =IF($Y11="","",SUMPRODUCT(($D11:$W11=$D$2:$W$2)*($D11:$W11<>"")*$D$3:$W$3*($D$4:$W$4=AB$6)))
A12: 6 | B12: =IF('학생명단'!B12="","",'학생명단'!B12) | C12: =IF('학생명단'!C12="","",'학생명단'!C12) | X12: =IF(COUNTA(D12:W12)=0,"",SUMPRODUCT((D12:W12=$D$2:$W$2)*(D12:W12<>""))) | Y12: =IF(COUNTA(D12:W12)=0,"",SUMPRODUCT((D12:W12=$D$2:$W$2)*(D12:W12<>"")*$D$3:$W$3)) | Z12: =IF($Y12="","",SUMPRODUCT(($D12:$W12=$D$2:$W$2)*($D12:$W12<>"")*$D$3:$W$3*($D$4:$W$4=Z$6))) | AA12: =IF($Y12="","",SUMPRODUCT(($D12:$W12=$D$2:$W$2)*($D12:$W12<>"")*$D$3:$W$3*($D$4:$W$4=AA$6))) | AB12: =IF($Y12="","",SUMPRODUCT(($D12:$W12=$D$2:$W$2)*($D12:$W12<>"")*$D$3:$W$3*($D$4:$W$4=AB$6)))
A13: 7 | B13: =IF('학생명단'!B13="","",'학생명단'!B13) | C13: =IF('학생명단'!C13="","",'학생명단'!C13) | X13: =IF(COUNTA(D13:W13)=0,"",SUMPRODUCT((D13:W13=$D$2:$W$2)*(D13:W13<>""))) | Y13: =IF(COUNTA(D13:W13)=0,"",SUMPRODUCT((D13:W13=$D$2:$W$2)*(D13:W13<>"")*$D$3:$W$3)) | Z13: =IF($Y13="","",SUMPRODUCT(($D13:$W13=$D$2:$W$2)*($D13:$W13<>"")*$D$3:$W$3*($D$4:$W$4=Z$6))) | AA13: =IF($Y13="","",SUMPRODUCT(($D13:$W13=$D$2:$W$2)*($D13:$W13<>"")*$D$3:$W$3*($D$4:$W$4=AA$6))) | AB13: =IF($Y13="","",SUMPRODUCT(($D13:$W13=$D$2:$W$2)*($D13:$W13<>"")*$D$3:$W$3*($D$4:$W$4=AB$6)))
A14: 8 | B14: =IF('학생명단'!B14="","",'학생명단'!B14) | C14: =IF('학생명단'!C14="","",'학생명단'!C14) | X14: =IF(COUNTA(D14:W14)=0,"",SUMPRODUCT((D14:W14=$D$2:$W$2)*(D14:W14<>""))) | Y14: =IF(COUNTA(D14:W14)=0,"",SUMPRODUCT((D14:W14=$D$2:$W$2)*(D14:W14<>"")*$D$3:$W$3)) | Z14: =IF($Y14="","",SUMPRODUCT(($D14:$W14=$D$2:$W$2)*($D14:$W14<>"")*$D$3:$W$3*($D$4:$W$4=Z$6))) | AA14: =IF($Y14="","",SUMPRODUCT(($D14:$W14=$D$2:$W$2)*($D14:$W14<>"")*$D$3:$W$3*($D$4:$W$4=AA$6))) | AB14: =IF($Y14="","",SUMPRODUCT(($D14:$W14=$D$2:$W$2)*($D14:$W14<>"")*$D$3:$W$3*($D$4:$W$4=AB$6)))
A15: 9 | B15: =IF('학생명단'!B15="","",'학생명단'!B15) | C15: =IF('학생명단'!C15="","",'학생명단'!C15) | X15: =IF(COUNTA(D15:W15)=0,"",SUMPRODUCT((D15:W15=$D$2:$W$2)*(D15:W15<>""))) | Y15: =IF(COUNTA(D15:W15)=0,"",SUMPRODUCT((D15:W15=$D$2:$W$2)*(D15:W15<>"")*$D$3:$W$3)) | Z15: =IF($Y15="","",SUMPRODUCT(($D15:$W15=$D$2:$W$2)*($D15:$W15<>"")*$D$3:$W$3*($D$4:$W$4=Z$6))) | AA15: =IF($Y15="","",SUMPRODUCT(($D15:$W15=$D$2:$W$2)*($D15:$W15<>"")*$D$3:$W$3*($D$4:$W$4=AA$6))) | AB15: =IF($Y15="","",SUMPRODUCT(($D15:$W15=$D$2:$W$2)*($D15:$W15<>"")*$D$3:$W$3*($D$4:$W$4=AB$6)))
A16: 10 | B16: =IF('학생명단'!B16="","",'학생명단'!B16) | C16: =IF('학생명단'!C16="","",'학생명단'!C16) | X16: =IF(COUNTA(D16:W16)=0,"",SUMPRODUCT((D16:W16=$D$2:$W$2)*(D16:W16<>""))) | Y16: =IF(COUNTA(D16:W16)=0,"",SUMPRODUCT((D16:W16=$D$2:$W$2)*(D16:W16<>"")*$D$3:$W$3)) | Z16: =IF($Y16="","",SUMPRODUCT(($D16:$W16=$D$2:$W$2)*($D16:$W16<>"")*$D$3:$W$3*($D$4:$W$4=Z$6))) | AA16: =IF($Y16="","",SUMPRODUCT(($D16:$W16=$D$2:$W$2)*($D16:$W16<>"")*$D$3:$W$3*($D$4:$W$4=AA$6))) | AB16: =IF($Y16="","",SUMPRODUCT(($D16:$W16=$D$2:$W$2)*($D16:$W16<>"")*$D$3:$W$3*($D$4:$W$4=AB$6)))
A17: 11 | B17: =IF('학생명단'!B17="","",'학생명단'!B17) | C17: =IF('학생명단'!C17="","",'학생명단'!C17) | X17: =IF(COUNTA(D17:W17)=0,"",SUMPRODUCT((D17:W17=$D$2:$W$2)*(D17:W17<>""))) | Y17: =IF(COUNTA(D17:W17)=0,"",SUMPRODUCT((D17:W17=$D$2:$W$2)*(D17:W17<>"")*$D$3:$W$3)) | Z17: =IF($Y17="","",SUMPRODUCT(($D17:$W17=$D$2:$W$2)*($D17:$W17<>"")*$D$3:$W$3*($D$4:$W$4=Z$6))) | AA17: =IF($Y17="","",SUMPRODUCT(($D17:$W17=$D$2:$W$2)*($D17:$W17<>"")*$D$3:$W$3*($D$4:$W$4=AA$6))) | AB17: =IF($Y17="","",SUMPRODUCT(($D17:$W17=$D$2:$W$2)*($D17:$W17<>"")*$D$3:$W$3*($D$4:$W$4=AB$6)))
A18: 12 | B18: =IF('학생명단'!B18="","",'학생명단'!B18) | C18: =IF('학생명단'!C18="","",'학생명단'!C18) | X18: =IF(COUNTA(D18:W18)=0,"",SUMPRODUCT((D18:W18=$D$2:$W$2)*(D18:W18<>""))) | Y18: =IF(COUNTA(D18:W18)=0,"",SUMPRODUCT((D18:W18=$D$2:$W$2)*(D18:W18<>"")*$D$3:$W$3)) | Z18: =IF($Y18="","",SUMPRODUCT(($D18:$W18=$D$2:$W$2)*($D18:$W18<>"")*$D$3:$W$3*($D$4:$W$4=Z$6))) | AA18: =IF($Y18="","",SUMPRODUCT(($D18:$W18=$D$2:$W$2)*($D18:$W18<>"")*$D$3:$W$3*($D$4:$W$4=AA$6))) | AB18: =IF($Y18="","",SUMPRODUCT(($D18:$W18=$D$2:$W$2)*($D18:$W18<>"")*$D$3:$W$3*($D$4:$W$4=AB$6)))
... A156: 150 | B156: =IF('학생명단'!B156="","",'학생명단'!B156) | C156: =IF('학생명단'!C156="","",'학생명단'!C156) | X156: =IF(COUNTA(D156:W156)=0,"",SUMPRODUCT((D156:W156=$D$2:$W$2)*(D156:W156<>""))) | Y156: =IF(COUNTA(D156:W156)=0,"",SUMPRODUCT((D156:W156=$D$2:$W$2)*(D156:W156<>"")*$D$3:$W$3)) | Z156: =IF($Y156="","",SUMPRODUCT(($D156:$W156=$D$2:$W$2)*($D156:$W156<>"")*$D$3:$W$3*($D$4:$W$4=Z$6))) | AA156: =IF($Y156="","",SUMPRODUCT(($D156:$W156=$D$2:$W$2)*($D156:$W156<>"")*$D$3:$W$3*($D$4:$W$4=AA$6))) | AB156: =IF($Y156="","",SUMPRODUCT(($D156:$W156=$D$2:$W$2)*($D156:$W156<>"")*$D$3:$W$3*($D$4:$W$4=AB$6)))

Sheet 반배정
A1: 반 배정 (공통수학반 + 선행 과목반)
A2: 학생마다 2개 반 수강: ① 공통수학반 = 시험 결과 기준 자동배정('설정' ①, 해당 없으면 보류). 노란 칸 '공통수학반'에 적으면 그 반이 우선. ② 선행반 = 학습 진도를 보고 노란 칸 '선행반'에서 1과목 선택('설정' ⑦ 목록). 두 반 모두 학부모 보고서에 들어갑니다. 주황색 행 = 기준 점수 경계.
S5: 공통수학반별 요약 (최종 기준)
A6: No | B6: 이름 | C6: 학교 | D6: 구분 | E6: 기존 반 | F6: 학습 진도 | G6: 공수1 | H6: 공수2 | I6: 환산총점 | J6: 석차 | K6: 자동배정 | L6: 경계 | M6: 공통수학반 (입력) | N6: 선행반 (입력) | O6: 공통수학반 (최종) | P6: 비고 | S6: 반 | T6: 자동 인원 | U6: 최종 인원 | V6: 공수1 평균 | W6: 공수2 평균 | X6: 재원 | Y6: 외부
A7: 1 | B7: =IF('학생명단'!B7="","",'학생명단'!B7) | C7: =IF('학생명단'!C7="","",'학생명단'!C7) | D7: =IF('학생명단'!D7="","",'학생명단'!D7) | E7: =IF('학생명단'!E7="","",'학생명단'!E7) | F7: =IF('학생명단'!F7="","",'학생명단'!F7) | G7: ='공수1'!Y7 | H7: ='공수2'!Y7 | I7: =IF(AND(G7="",H7=""),"",N(G7)*'설정'!$C$13+N(H7)*'설정'!$C$14) | J7: =IF(I7="","",COUNTIF($I$7:$I$156,">"&I7)+1) | K7: =IF(I7="","",IF(IF(COUNT('설정'!$C$6:$F$6)=0,AND(G7<>"",H7<>""),OR(AND('설정'!$C$6<>"",G7<>"",N(G7)>='설정'!$C$6),AND('설정'!$D$6<>"",AND(G7<>"",H7<>""),(N(G7)+N(H7))>='설정'!$D$6),AND('설정'!$E$6<>"",OR(AND(G7<>"",N(G7)<='설정'!$E$6),AND(H7<>"",N(H7)<='설정'!$E$6))),AND('설정'!$F$6<>"",AND(G7<>"",H7<>""),(N(G7)+N(H7))<='설정'!$F$6))),'설정'!$B$6,IF(IF(COUNT('설정'!$C$7:$F$7)=0,AND(G7<>"",H7<>""),OR(AND('설정'!$C$7<>"",G7<>"",N(G7)>='설정'!$C$7),AND('설정'!$D$7<>"",AND(G7<>"",H7<>""),(N(G7)+N(H7))>='설정'!$D$7),AND('설정'!$E$7<>"",OR(AND(G7<>"",N(G7)<='설정'!$E$7),AND(H7<>"",N(H7)<='설정'!$E$7))),AND('설정'!$F$7<>"",AND(G7<>"",H7<>""),(N(G7)+N(H7))<='설정'!$F$7))),'설정'!$B$7,IF(IF(COUNT('설정'!$C$8:$F$8)=0,AND(G7<>"",H7<>""),OR(AND('설정'!$C$8<>"",G7<>"",N(G7)>='설정'!$C$8),AND('설정'!$D$8<>"",AND(G7<>"",H7<>""),(N(G7)+N(H7))>='설정'!$D$8),AND('설정'!$E$8<>"",OR(AND(G7<>"",N(G7)<='설정'!$E$8),AND(H7<>"",N(H7)<='설정'!$E$8))),AND('설정'!$F$8<>"",AND(G7<>"",H7<>""),(N(G7)+N(H7))<='설정'!$F$8))),'설정'!$B$8,'설정'!$B$9)))) | L7: =IF(OR(G7="",H7=""),"",IF(SUMPRODUCT(ISNUMBER('설정'!$C$6:$C$8)*(ABS(G7-'설정'!$C$6:$C$8)<='설정'!$C$15))+SUMPRODUCT(ISNUMBER('설정'!$D$6:$D$8)*(ABS((G7+H7)-'설정'!$D$6:$D$8)<='설정'!$C$15))+SUMPRODUCT(ISNUMBER('설정'!$F$6:$F$8)*(ABS((G7+H7)-'설정'!$F$6:$F$8)<='설정'!$C$15))+SUMPRODUCT(ISNUMBER('설정'!$E$6:$E$8)*(ABS(G7-'설정'!$E$6:$E$8)<='설정'!$C$15))+SUMPRODUCT(ISNUMBER('설정'!$E$6:$E$8)*(ABS(H7-'설정'!$E$6:$E$8)<='설정'!$C$15))>0,"경계","")) | O7: =IF(M7<>"",M7,K7) | P7: =IF(I7="","",IF(G7="","공수1 미응시",IF(H7="","공수2 미응시",""))) | Q7: =IF(J7="","",J7+ROW()/100000) | S7: ='설정'!$B$6 | T7: =COUNTIF($K$7:$K$156,S7) | U7: =COUNTIF($O$7:$O$156,S7) | V7: =IFERROR(AVERAGEIF($O$7:$O$156,S7,$G$7:$G$156),"") | W7: =IFERROR(AVERAGEIF($O$7:$O$156,S7,$H$7:$H$156),"") | X7: =COUNTIFS($O$7:$O$156,S7,$D$7:$D$156,"재원") | Y7: =COUNTIFS($O$7:$O$156,S7,$D$7:$D$156,"외부")
A8: 2 | B8: =IF('학생명단'!B8="","",'학생명단'!B8) | C8: =IF('학생명단'!C8="","",'학생명단'!C8) | D8: =IF('학생명단'!D8="","",'학생명단'!D8) | E8: =IF('학생명단'!E8="","",'학생명단'!E8) | F8: =IF('학생명단'!F8="","",'학생명단'!F8) | G8: ='공수1'!Y8 | H8: ='공수2'!Y8 | I8: =IF(AND(G8="",H8=""),"",N(G8)*'설정'!$C$13+N(H8)*'설정'!$C$14) | J8: =IF(I8="","",COUNTIF($I$7:$I$156,">"&I8)+1) | K8: =IF(I8="","",IF(IF(COUNT('설정'!$C$6:$F$6)=0,AND(G8<>"",H8<>""),OR(AND('설정'!$C$6<>"",G8<>"",N(G8)>='설정'!$C$6),AND('설정'!$D$6<>"",AND(G8<>"",H8<>""),(N(G8)+N(H8))>='설정'!$D$6),AND('설정'!$E$6<>"",OR(AND(G8<>"",N(G8)<='설정'!$E$6),AND(H8<>"",N(H8)<='설정'!$E$6))),AND('설정'!$F$6<>"",AND(G8<>"",H8<>""),(N(G8)+N(H8))<='설정'!$F$6))),'설정'!$B$6,IF(IF(COUNT('설정'!$C$7:$F$7)=0,AND(G8<>"",H8<>""),OR(AND('설정'!$C$7<>"",G8<>"",N(G8)>='설정'!$C$7),AND('설정'!$D$7<>"",AND(G8<>"",H8<>""),(N(G8)+N(H8))>='설정'!$D$7),AND('설정'!$E$7<>"",OR(AND(G8<>"",N(G8)<='설정'!$E$7),AND(H8<>"",N(H8)<='설정'!$E$7))),AND('설정'!$F$7<>"",AND(G8<>"",H8<>""),(N(G8)+N(H8))<='설정'!$F$7))),'설정'!$B$7,IF(IF(COUNT('설정'!$C$8:$F$8)=0,AND(G8<>"",H8<>""),OR(AND('설정'!$C$8<>"",G8<>"",N(G8)>='설정'!$C$8),AND('설정'!$D$8<>"",AND(G8<>"",H8<>""),(N(G8)+N(H8))>='설정'!$D$8),AND('설정'!$E$8<>"",OR(AND(G8<>"",N(G8)<='설정'!$E$8),AND(H8<>"",N(H8)<='설정'!$E$8))),AND('설정'!$F$8<>"",AND(G8<>"",H8<>""),(N(G8)+N(H8))<='설정'!$F$8))),'설정'!$B$8,'설정'!$B$9)))) | L8: =IF(OR(G8="",H8=""),"",IF(SUMPRODUCT(ISNUMBER('설정'!$C$6:$C$8)*(ABS(G8-'설정'!$C$6:$C$8)<='설정'!$C$15))+SUMPRODUCT(ISNUMBER('설정'!$D$6:$D$8)*(ABS((G8+H8)-'설정'!$D$6:$D$8)<='설정'!$C$15))+SUMPRODUCT(ISNUMBER('설정'!$F$6:$F$8)*(ABS((G8+H8)-'설정'!$F$6:$F$8)<='설정'!$C$15))+SUMPRODUCT(ISNUMBER('설정'!$E$6:$E$8)*(ABS(G8-'설정'!$E$6:$E$8)<='설정'!$C$15))+SUMPRODUCT(ISNUMBER('설정'!$E$6:$E$8)*(ABS(H8-'설정'!$E$6:$E$8)<='설정'!$C$15))>0,"경계","")) | O8: =IF(M8<>"",M8,K8) | P8: =IF(I8="","",IF(G8="","공수1 미응시",IF(H8="","공수2 미응시",""))) | Q8: =IF(J8="","",J8+ROW()/100000) | S8: ='설정'!$B$7 | T8: =COUNTIF($K$7:$K$156,S8) | U8: =COUNTIF($O$7:$O$156,S8) | V8: =IFERROR(AVERAGEIF($O$7:$O$156,S8,$G$7:$G$156),"") | W8: =IFERROR(AVERAGEIF($O$7:$O$156,S8,$H$7:$H$156),"") | X8: =COUNTIFS($O$7:$O$156,S8,$D$7:$D$156,"재원") | Y8: =COUNTIFS($O$7:$O$156,S8,$D$7:$D$156,"외부")
A9: 3 | B9: =IF('학생명단'!B9="","",'학생명단'!B9) | C9: =IF('학생명단'!C9="","",'학생명단'!C9) | D9: =IF('학생명단'!D9="","",'학생명단'!D9) | E9: =IF('학생명단'!E9="","",'학생명단'!E9) | F9: =IF('학생명단'!F9="","",'학생명단'!F9) | G9: ='공수1'!Y9 | H9: ='공수2'!Y9 | I9: =IF(AND(G9="",H9=""),"",N(G9)*'설정'!$C$13+N(H9)*'설정'!$C$14) | J9: =IF(I9="","",COUNTIF($I$7:$I$156,">"&I9)+1) | K9: =IF(I9="","",IF(IF(COUNT('설정'!$C$6:$F$6)=0,AND(G9<>"",H9<>""),OR(AND('설정'!$C$6<>"",G9<>"",N(G9)>='설정'!$C$6),AND('설정'!$D$6<>"",AND(G9<>"",H9<>""),(N(G9)+N(H9))>='설정'!$D$6),AND('설정'!$E$6<>"",OR(AND(G9<>"",N(G9)<='설정'!$E$6),AND(H9<>"",N(H9)<='설정'!$E$6))),AND('설정'!$F$6<>"",AND(G9<>"",H9<>""),(N(G9)+N(H9))<='설정'!$F$6))),'설정'!$B$6,IF(IF(COUNT('설정'!$C$7:$F$7)=0,AND(G9<>"",H9<>""),OR(AND('설정'!$C$7<>"",G9<>"",N(G9)>='설정'!$C$7),AND('설정'!$D$7<>"",AND(G9<>"",H9<>""),(N(G9)+N(H9))>='설정'!$D$7),AND('설정'!$E$7<>"",OR(AND(G9<>"",N(G9)<='설정'!$E$7),AND(H9<>"",N(H9)<='설정'!$E$7))),AND('설정'!$F$7<>"",AND(G9<>"",H9<>""),(N(G9)+N(H9))<='설정'!$F$7))),'설정'!$B$7,IF(IF(COUNT('설정'!$C$8:$F$8)=0,AND(G9<>"",H9<>""),OR(AND('설정'!$C$8<>"",G9<>"",N(G9)>='설정'!$C$8),AND('설정'!$D$8<>"",AND(G9<>"",H9<>""),(N(G9)+N(H9))>='설정'!$D$8),AND('설정'!$E$8<>"",OR(AND(G9<>"",N(G9)<='설정'!$E$8),AND(H9<>"",N(H9)<='설정'!$E$8))),AND('설정'!$F$8<>"",AND(G9<>"",H9<>""),(N(G9)+N(H9))<='설정'!$F$8))),'설정'!$B$8,'설정'!$B$9)))) | L9: =IF(OR(G9="",H9=""),"",IF(SUMPRODUCT(ISNUMBER('설정'!$C$6:$C$8)*(ABS(G9-'설정'!$C$6:$C$8)<='설정'!$C$15))+SUMPRODUCT(ISNUMBER('설정'!$D$6:$D$8)*(ABS((G9+H9)-'설정'!$D$6:$D$8)<='설정'!$C$15))+SUMPRODUCT(ISNUMBER('설정'!$F$6:$F$8)*(ABS((G9+H9)-'설정'!$F$6:$F$8)<='설정'!$C$15))+SUMPRODUCT(ISNUMBER('설정'!$E$6:$E$8)*(ABS(G9-'설정'!$E$6:$E$8)<='설정'!$C$15))+SUMPRODUCT(ISNUMBER('설정'!$E$6:$E$8)*(ABS(H9-'설정'!$E$6:$E$8)<='설정'!$C$15))>0,"경계","")) | O9: =IF(M9<>"",M9,K9) | P9: =IF(I9="","",IF(G9="","공수1 미응시",IF(H9="","공수2 미응시",""))) | Q9: =IF(J9="","",J9+ROW()/100000) | S9: ='설정'!$B$8 | T9: =COUNTIF($K$7:$K$156,S9) | U9: =COUNTIF($O$7:$O$156,S9) | V9: =IFERROR(AVERAGEIF($O$7:$O$156,S9,$G$7:$G$156),"") | W9: =IFERROR(AVERAGEIF($O$7:$O$156,S9,$H$7:$H$156),"") | X9: =COUNTIFS($O$7:$O$156,S9,$D$7:$D$156,"재원") | Y9: =COUNTIFS($O$7:$O$156,S9,$D$7:$D$156,"외부")
A10: 4 | B10: =IF('학생명단'!B10="","",'학생명단'!B10) | C10: =IF('학생명단'!C10="","",'학생명단'!C10) | D10: =IF('학생명단'!D10="","",'학생명단'!D10) | E10: =IF('학생명단'!E10="","",'학생명단'!E10) | F10: =IF('학생명단'!F10="","",'학생명단'!F10) | G10: ='공수1'!Y10 | H10: ='공수2'!Y10 | I10: =IF(AND(G10="",H10=""),"",N(G10)*'설정'!$C$13+N(H10)*'설정'!$C$14) | J10: =IF(I10="","",COUNTIF($I$7:$I$156,">"&I10)+1) | K10: =IF(I10="","",IF(IF(COUNT('설정'!$C$6:$F$6)=0,AND(G10<>"",H10<>""),OR(AND('설정'!$C$6<>"",G10<>"",N(G10)>='설정'!$C$6),AND('설정'!$D$6<>"",AND(G10<>"",H10<>""),(N(G10)+N(H10))>='설정'!$D$6),AND('설정'!$E$6<>"",OR(AND(G10<>"",N(G10)<='설정'!$E$6),AND(H10<>"",N(H10)<='설정'!$E$6))),AND('설정'!$F$6<>"",AND(G10<>"",H10<>""),(N(G10)+N(H10))<='설정'!$F$6))),'설정'!$B$6,IF(IF(COUNT('설정'!$C$7:$F$7)=0,AND(G10<>"",H10<>""),OR(AND('설정'!$C$7<>"",G10<>"",N(G10)>='설정'!$C$7),AND('설정'!$D$7<>"",AND(G10<>"",H10<>""),(N(G10)+N(H10))>='설정'!$D$7),AND('설정'!$E$7<>"",OR(AND(G10<>"",N(G10)<='설정'!$E$7),AND(H10<>"",N(H10)<='설정'!$E$7))),AND('설정'!$F$7<>"",AND(G10<>"",H10<>""),(N(G10)+N(H10))<='설정'!$F$7))),'설정'!$B$7,IF(IF(COUNT('설정'!$C$8:$F$8)=0,AND(G10<>"",H10<>""),OR(AND('설정'!$C$8<>"",G10<>"",N(G10)>='설정'!$C$8),AND('설정'!$D$8<>"",AND(G10<>"",H10<>""),(N(G10)+N(H10))>='설정'!$D$8),AND('설정'!$E$8<>"",OR(AND(G10<>"",N(G10)<='설정'!$E$8),AND(H10<>"",N(H10)<='설정'!$E$8))),AND('설정'!$F$8<>"",AND(G10<>"",H10<>""),(N(G10)+N(H10))<='설정'!$F$8))),'설정'!$B$8,'설정'!$B$9)))) | L10: =IF(OR(G10="",H10=""),"",IF(SUMPRODUCT(ISNUMBER('설정'!$C$6:$C$8)*(ABS(G10-'설정'!$C$6:$C$8)<='설정'!$C$15))+SUMPRODUCT(ISNUMBER('설정'!$D$6:$D$8)*(ABS((G10+H10)-'설정'!$D$6:$D$8)<='설정'!$C$15))+SUMPRODUCT(ISNUMBER('설정'!$F$6:$F$8)*(ABS((G10+H10)-'설정'!$F$6:$F$8)<='설정'!$C$15))+SUMPRODUCT(ISNUMBER('설정'!$E$6:$E$8)*(ABS(G10-'설정'!$E$6:$E$8)<='설정'!$C$15))+SUMPRODUCT(ISNUMBER('설정'!$E$6:$E$8)*(ABS(H10-'설정'!$E$6:$E$8)<='설정'!$C$15))>0,"경계","")) | O10: =IF(M10<>"",M10,K10) | P10: =IF(I10="","",IF(G10="","공수1 미응시",IF(H10="","공수2 미응시",""))) | Q10: =IF(J10="","",J10+ROW()/100000) | S10: ='설정'!$B$9 | T10: =COUNTIF($K$7:$K$156,S10) | U10: =COUNTIF($O$7:$O$156,S10) | V10: =IFERROR(AVERAGEIF($O$7:$O$156,S10,$G$7:$G$156),"") | W10: =IFERROR(AVERAGEIF($O$7:$O$156,S10,$H$7:$H$156),"") | X10: =COUNTIFS($O$7:$O$156,S10,$D$7:$D$156,"재원") | Y10: =COUNTIFS($O$7:$O$156,S10,$D$7:$D$156,"외부")
A11: 5 | B11: =IF('학생명단'!B11="","",'학생명단'!B11) | C11: =IF('학생명단'!C11="","",'학생명단'!C11) | D11: =IF('학생명단'!D11="","",'학생명단'!D11) | E11: =IF('학생명단'!E11="","",'학생명단'!E11) | F11: =IF('학생명단'!F11="","",'학생명단'!F11) | G11: ='공수1'!Y11 | H11: ='공수2'!Y11 | I11: =IF(AND(G11="",H11=""),"",N(G11)*'설정'!$C$13+N(H11)*'설정'!$C$14) | J11: =IF(I11="","",COUNTIF($I$7:$I$156,">"&I11)+1) | K11: =IF(I11="","",IF(IF(COUNT('설정'!$C$6:$F$6)=0,AND(G11<>"",H11<>""),OR(AND('설정'!$C$6<>"",G11<>"",N(G11)>='설정'!$C$6),AND('설정'!$D$6<>"",AND(G11<>"",H11<>""),(N(G11)+N(H11))>='설정'!$D$6),AND('설정'!$E$6<>"",OR(AND(G11<>"",N(G11)<='설정'!$E$6),AND(H11<>"",N(H11)<='설정'!$E$6))),AND('설정'!$F$6<>"",AND(G11<>"",H11<>""),(N(G11)+N(H11))<='설정'!$F$6))),'설정'!$B$6,IF(IF(COUNT('설정'!$C$7:$F$7)=0,AND(G11<>"",H11<>""),OR(AND('설정'!$C$7<>"",G11<>"",N(G11)>='설정'!$C$7),AND('설정'!$D$7<>"",AND(G11<>"",H11<>""),(N(G11)+N(H11))>='설정'!$D$7),AND('설정'!$E$7<>"",OR(AND(G11<>"",N(G11)<='설정'!$E$7),AND(H11<>"",N(H11)<='설정'!$E$7))),AND('설정'!$F$7<>"",AND(G11<>"",H11<>""),(N(G11)+N(H11))<='설정'!$F$7))),'설정'!$B$7,IF(IF(COUNT('설정'!$C$8:$F$8)=0,AND(G11<>"",H11<>""),OR(AND('설정'!$C$8<>"",G11<>"",N(G11)>='설정'!$C$8),AND('설정'!$D$8<>"",AND(G11<>"",H11<>""),(N(G11)+N(H11))>='설정'!$D$8),AND('설정'!$E$8<>"",OR(AND(G11<>"",N(G11)<='설정'!$E$8),AND(H11<>"",N(H11)<='설정'!$E$8))),AND('설정'!$F$8<>"",AND(G11<>"",H11<>""),(N(G11)+N(H11))<='설정'!$F$8))),'설정'!$B$8,'설정'!$B$9)))) | L11: =IF(OR(G11="",H11=""),"",IF(SUMPRODUCT(ISNUMBER('설정'!$C$6:$C$8)*(ABS(G11-'설정'!$C$6:$C$8)<='설정'!$C$15))+SUMPRODUCT(ISNUMBER('설정'!$D$6:$D$8)*(ABS((G11+H11)-'설정'!$D$6:$D$8)<='설정'!$C$15))+SUMPRODUCT(ISNUMBER('설정'!$F$6:$F$8)*(ABS((G11+H11)-'설정'!$F$6:$F$8)<='설정'!$C$15))+SUMPRODUCT(ISNUMBER('설정'!$E$6:$E$8)*(ABS(G11-'설정'!$E$6:$E$8)<='설정'!$C$15))+SUMPRODUCT(ISNUMBER('설정'!$E$6:$E$8)*(ABS(H11-'설정'!$E$6:$E$8)<='설정'!$C$15))>0,"경계","")) | O11: =IF(M11<>"",M11,K11) | P11: =IF(I11="","",IF(G11="","공수1 미응시",IF(H11="","공수2 미응시",""))) | Q11: =IF(J11="","",J11+ROW()/100000) | S11: 합계 | T11: =SUM(T7:T10) | U11: =SUM(U7:U10) | V11: =IFERROR(AVERAGE($G$7:$G$156),"") | W11: =IFERROR(AVERAGE($H$7:$H$156),"") | X11: =SUM(X7:X10) | Y11: =SUM(Y7:Y10)
A12: 6 | B12: =IF('학생명단'!B12="","",'학생명단'!B12) | C12: =IF('학생명단'!C12="","",'학생명단'!C12) | D12: =IF('학생명단'!D12="","",'학생명단'!D12) | E12: =IF('학생명단'!E12="","",'학생명단'!E12) | F12: =IF('학생명단'!F12="","",'학생명단'!F12) | G12: ='공수1'!Y12 | H12: ='공수2'!Y12 | I12: =IF(AND(G12="",H12=""),"",N(G12)*'설정'!$C$13+N(H12)*'설정'!$C$14) | J12: =IF(I12="","",COUNTIF($I$7:$I$156,">"&I12)+1) | K12: =IF(I12="","",IF(IF(COUNT('설정'!$C$6:$F$6)=0,AND(G12<>"",H12<>""),OR(AND('설정'!$C$6<>"",G12<>"",N(G12)>='설정'!$C$6),AND('설정'!$D$6<>"",AND(G12<>"",H12<>""),(N(G12)+N(H12))>='설정'!$D$6),AND('설정'!$E$6<>"",OR(AND(G12<>"",N(G12)<='설정'!$E$6),AND(H12<>"",N(H12)<='설정'!$E$6))),AND('설정'!$F$6<>"",AND(G12<>"",H12<>""),(N(G12)+N(H12))<='설정'!$F$6))),'설정'!$B$6,IF(IF(COUNT('설정'!$C$7:$F$7)=0,AND(G12<>"",H12<>""),OR(AND('설정'!$C$7<>"",G12<>"",N(G12)>='설정'!$C$7),AND('설정'!$D$7<>"",AND(G12<>"",H12<>""),(N(G12)+N(H12))>='설정'!$D$7),AND('설정'!$E$7<>"",OR(AND(G12<>"",N(G12)<='설정'!$E$7),AND(H12<>"",N(H12)<='설정'!$E$7))),AND('설정'!$F$7<>"",AND(G12<>"",H12<>""),(N(G12)+N(H12))<='설정'!$F$7))),'설정'!$B$7,IF(IF(COUNT('설정'!$C$8:$F$8)=0,AND(G12<>"",H12<>""),OR(AND('설정'!$C$8<>"",G12<>"",N(G12)>='설정'!$C$8),AND('설정'!$D$8<>"",AND(G12<>"",H12<>""),(N(G12)+N(H12))>='설정'!$D$8),AND('설정'!$E$8<>"",OR(AND(G12<>"",N(G12)<='설정'!$E$8),AND(H12<>"",N(H12)<='설정'!$E$8))),AND('설정'!$F$8<>"",AND(G12<>"",H12<>""),(N(G12)+N(H12))<='설정'!$F$8))),'설정'!$B$8,'설정'!$B$9)))) | L12: =IF(OR(G12="",H12=""),"",IF(SUMPRODUCT(ISNUMBER('설정'!$C$6:$C$8)*(ABS(G12-'설정'!$C$6:$C$8)<='설정'!$C$15))+SUMPRODUCT(ISNUMBER('설정'!$D$6:$D$8)*(ABS((G12+H12)-'설정'!$D$6:$D$8)<='설정'!$C$15))+SUMPRODUCT(ISNUMBER('설정'!$F$6:$F$8)*(ABS((G12+H12)-'설정'!$F$6:$F$8)<='설정'!$C$15))+SUMPRODUCT(ISNUMBER('설정'!$E$6:$E$8)*(ABS(G12-'설정'!$E$6:$E$8)<='설정'!$C$15))+SUMPRODUCT(ISNUMBER('설정'!$E$6:$E$8)*(ABS(H12-'설정'!$E$6:$E$8)<='설정'!$C$15))>0,"경계","")) | O12: =IF(M12<>"",M12,K12) | P12: =IF(I12="","",IF(G12="","공수1 미응시",IF(H12="","공수2 미응시",""))) | Q12: =IF(J12="","",J12+ROW()/100000)
A13: 7 | B13: =IF('학생명단'!B13="","",'학생명단'!B13) | C13: =IF('학생명단'!C13="","",'학생명단'!C13) | D13: =IF('학생명단'!D13="","",'학생명단'!D13) | E13: =IF('학생명단'!E13="","",'학생명단'!E13) | F13: =IF('학생명단'!F13="","",'학생명단'!F13) | G13: ='공수1'!Y13 | H13: ='공수2'!Y13 | I13: =IF(AND(G13="",H13=""),"",N(G13)*'설정'!$C$13+N(H13)*'설정'!$C$14) | J13: =IF(I13="","",COUNTIF($I$7:$I$156,">"&I13)+1) | K13: =IF(I13="","",IF(IF(COUNT('설정'!$C$6:$F$6)=0,AND(G13<>"",H13<>""),OR(AND('설정'!$C$6<>"",G13<>"",N(G13)>='설정'!$C$6),AND('설정'!$D$6<>"",AND(G13<>"",H13<>""),(N(G13)+N(H13))>='설정'!$D$6),AND('설정'!$E$6<>"",OR(AND(G13<>"",N(G13)<='설정'!$E$6),AND(H13<>"",N(H13)<='설정'!$E$6))),AND('설정'!$F$6<>"",AND(G13<>"",H13<>""),(N(G13)+N(H13))<='설정'!$F$6))),'설정'!$B$6,IF(IF(COUNT('설정'!$C$7:$F$7)=0,AND(G13<>"",H13<>""),OR(AND('설정'!$C$7<>"",G13<>"",N(G13)>='설정'!$C$7),AND('설정'!$D$7<>"",AND(G13<>"",H13<>""),(N(G13)+N(H13))>='설정'!$D$7),AND('설정'!$E$7<>"",OR(AND(G13<>"",N(G13)<='설정'!$E$7),AND(H13<>"",N(H13)<='설정'!$E$7))),AND('설정'!$F$7<>"",AND(G13<>"",H13<>""),(N(G13)+N(H13))<='설정'!$F$7))),'설정'!$B$7,IF(IF(COUNT('설정'!$C$8:$F$8)=0,AND(G13<>"",H13<>""),OR(AND('설정'!$C$8<>"",G13<>"",N(G13)>='설정'!$C$8),AND('설정'!$D$8<>"",AND(G13<>"",H13<>""),(N(G13)+N(H13))>='설정'!$D$8),AND('설정'!$E$8<>"",OR(AND(G13<>"",N(G13)<='설정'!$E$8),AND(H13<>"",N(H13)<='설정'!$E$8))),AND('설정'!$F$8<>"",AND(G13<>"",H13<>""),(N(G13)+N(H13))<='설정'!$F$8))),'설정'!$B$8,'설정'!$B$9)))) | L13: =IF(OR(G13="",H13=""),"",IF(SUMPRODUCT(ISNUMBER('설정'!$C$6:$C$8)*(ABS(G13-'설정'!$C$6:$C$8)<='설정'!$C$15))+SUMPRODUCT(ISNUMBER('설정'!$D$6:$D$8)*(ABS((G13+H13)-'설정'!$D$6:$D$8)<='설정'!$C$15))+SUMPRODUCT(ISNUMBER('설정'!$F$6:$F$8)*(ABS((G13+H13)-'설정'!$F$6:$F$8)<='설정'!$C$15))+SUMPRODUCT(ISNUMBER('설정'!$E$6:$E$8)*(ABS(G13-'설정'!$E$6:$E$8)<='설정'!$C$15))+SUMPRODUCT(ISNUMBER('설정'!$E$6:$E$8)*(ABS(H13-'설정'!$E$6:$E$8)<='설정'!$C$15))>0,"경계","")) | O13: =IF(M13<>"",M13,K13) | P13: =IF(I13="","",IF(G13="","공수1 미응시",IF(H13="","공수2 미응시",""))) | Q13: =IF(J13="","",J13+ROW()/100000) | S13: · 자동배정은 '설정' ①의 기준(공수1 점수·한 과목 점수·합계) · 경계 = 과목 점수나 합계가 기준 점수와 경계 범위 이내 · 공통수학반·선행반은 목록에서 고르거나 직접 입력('설정' ⑥·⑦에 반 소개 추가 가능) · 환산총점·석차는 참고용
A14: 8 | B14: =IF('학생명단'!B14="","",'학생명단'!B14) | C14: =IF('학생명단'!C14="","",'학생명단'!C14) | D14: =IF('학생명단'!D14="","",'학생명단'!D14) | E14: =IF('학생명단'!E14="","",'학생명단'!E14) | F14: =IF('학생명단'!F14="","",'학생명단'!F14) | G14: ='공수1'!Y14 | H14: ='공수2'!Y14 | I14: =IF(AND(G14="",H14=""),"",N(G14)*'설정'!$C$13+N(H14)*'설정'!$C$14) | J14: =IF(I14="","",COUNTIF($I$7:$I$156,">"&I14)+1) | K14: =IF(I14="","",IF(IF(COUNT('설정'!$C$6:$F$6)=0,AND(G14<>"",H14<>""),OR(AND('설정'!$C$6<>"",G14<>"",N(G14)>='설정'!$C$6),AND('설정'!$D$6<>"",AND(G14<>"",H14<>""),(N(G14)+N(H14))>='설정'!$D$6),AND('설정'!$E$6<>"",OR(AND(G14<>"",N(G14)<='설정'!$E$6),AND(H14<>"",N(H14)<='설정'!$E$6))),AND('설정'!$F$6<>"",AND(G14<>"",H14<>""),(N(G14)+N(H14))<='설정'!$F$6))),'설정'!$B$6,IF(IF(COUNT('설정'!$C$7:$F$7)=0,AND(G14<>"",H14<>""),OR(AND('설정'!$C$7<>"",G14<>"",N(G14)>='설정'!$C$7),AND('설정'!$D$7<>"",AND(G14<>"",H14<>""),(N(G14)+N(H14))>='설정'!$D$7),AND('설정'!$E$7<>"",OR(AND(G14<>"",N(G14)<='설정'!$E$7),AND(H14<>"",N(H14)<='설정'!$E$7))),AND('설정'!$F$7<>"",AND(G14<>"",H14<>""),(N(G14)+N(H14))<='설정'!$F$7))),'설정'!$B$7,IF(IF(COUNT('설정'!$C$8:$F$8)=0,AND(G14<>"",H14<>""),OR(AND('설정'!$C$8<>"",G14<>"",N(G14)>='설정'!$C$8),AND('설정'!$D$8<>"",AND(G14<>"",H14<>""),(N(G14)+N(H14))>='설정'!$D$8),AND('설정'!$E$8<>"",OR(AND(G14<>"",N(G14)<='설정'!$E$8),AND(H14<>"",N(H14)<='설정'!$E$8))),AND('설정'!$F$8<>"",AND(G14<>"",H14<>""),(N(G14)+N(H14))<='설정'!$F$8))),'설정'!$B$8,'설정'!$B$9)))) | L14: =IF(OR(G14="",H14=""),"",IF(SUMPRODUCT(ISNUMBER('설정'!$C$6:$C$8)*(ABS(G14-'설정'!$C$6:$C$8)<='설정'!$C$15))+SUMPRODUCT(ISNUMBER('설정'!$D$6:$D$8)*(ABS((G14+H14)-'설정'!$D$6:$D$8)<='설정'!$C$15))+SUMPRODUCT(ISNUMBER('설정'!$F$6:$F$8)*(ABS((G14+H14)-'설정'!$F$6:$F$8)<='설정'!$C$15))+SUMPRODUCT(ISNUMBER('설정'!$E$6:$E$8)*(ABS(G14-'설정'!$E$6:$E$8)<='설정'!$C$15))+SUMPRODUCT(ISNUMBER('설정'!$E$6:$E$8)*(ABS(H14-'설정'!$E$6:$E$8)<='설정'!$C$15))>0,"경계","")) | O14: =IF(M14<>"",M14,K14) | P14: =IF(I14="","",IF(G14="","공수1 미응시",IF(H14="","공수2 미응시",""))) | Q14: =IF(J14="","",J14+ROW()/100000)
A15: 9 | B15: =IF('학생명단'!B15="","",'학생명단'!B15) | C15: =IF('학생명단'!C15="","",'학생명단'!C15) | D15: =IF('학생명단'!D15="","",'학생명단'!D15) | E15: =IF('학생명단'!E15="","",'학생명단'!E15) | F15: =IF('학생명단'!F15="","",'학생명단'!F15) | G15: ='공수1'!Y15 | H15: ='공수2'!Y15 | I15: =IF(AND(G15="",H15=""),"",N(G15)*'설정'!$C$13+N(H15)*'설정'!$C$14) | J15: =IF(I15="","",COUNTIF($I$7:$I$156,">"&I15)+1) | K15: =IF(I15="","",IF(IF(COUNT('설정'!$C$6:$F$6)=0,AND(G15<>"",H15<>""),OR(AND('설정'!$C$6<>"",G15<>"",N(G15)>='설정'!$C$6),AND('설정'!$D$6<>"",AND(G15<>"",H15<>""),(N(G15)+N(H15))>='설정'!$D$6),AND('설정'!$E$6<>"",OR(AND(G15<>"",N(G15)<='설정'!$E$6),AND(H15<>"",N(H15)<='설정'!$E$6))),AND('설정'!$F$6<>"",AND(G15<>"",H15<>""),(N(G15)+N(H15))<='설정'!$F$6))),'설정'!$B$6,IF(IF(COUNT('설정'!$C$7:$F$7)=0,AND(G15<>"",H15<>""),OR(AND('설정'!$C$7<>"",G15<>"",N(G15)>='설정'!$C$7),AND('설정'!$D$7<>"",AND(G15<>"",H15<>""),(N(G15)+N(H15))>='설정'!$D$7),AND('설정'!$E$7<>"",OR(AND(G15<>"",N(G15)<='설정'!$E$7),AND(H15<>"",N(H15)<='설정'!$E$7))),AND('설정'!$F$7<>"",AND(G15<>"",H15<>""),(N(G15)+N(H15))<='설정'!$F$7))),'설정'!$B$7,IF(IF(COUNT('설정'!$C$8:$F$8)=0,AND(G15<>"",H15<>""),OR(AND('설정'!$C$8<>"",G15<>"",N(G15)>='설정'!$C$8),AND('설정'!$D$8<>"",AND(G15<>"",H15<>""),(N(G15)+N(H15))>='설정'!$D$8),AND('설정'!$E$8<>"",OR(AND(G15<>"",N(G15)<='설정'!$E$8),AND(H15<>"",N(H15)<='설정'!$E$8))),AND('설정'!$F$8<>"",AND(G15<>"",H15<>""),(N(G15)+N(H15))<='설정'!$F$8))),'설정'!$B$8,'설정'!$B$9)))) | L15: =IF(OR(G15="",H15=""),"",IF(SUMPRODUCT(ISNUMBER('설정'!$C$6:$C$8)*(ABS(G15-'설정'!$C$6:$C$8)<='설정'!$C$15))+SUMPRODUCT(ISNUMBER('설정'!$D$6:$D$8)*(ABS((G15+H15)-'설정'!$D$6:$D$8)<='설정'!$C$15))+SUMPRODUCT(ISNUMBER('설정'!$F$6:$F$8)*(ABS((G15+H15)-'설정'!$F$6:$F$8)<='설정'!$C$15))+SUMPRODUCT(ISNUMBER('설정'!$E$6:$E$8)*(ABS(G15-'설정'!$E$6:$E$8)<='설정'!$C$15))+SUMPRODUCT(ISNUMBER('설정'!$E$6:$E$8)*(ABS(H15-'설정'!$E$6:$E$8)<='설정'!$C$15))>0,"경계","")) | O15: =IF(M15<>"",M15,K15) | P15: =IF(I15="","",IF(G15="","공수1 미응시",IF(H15="","공수2 미응시",""))) | Q15: =IF(J15="","",J15+ROW()/100000)
A16: 10 | B16: =IF('학생명단'!B16="","",'학생명단'!B16) | C16: =IF('학생명단'!C16="","",'학생명단'!C16) | D16: =IF('학생명단'!D16="","",'학생명단'!D16) | E16: =IF('학생명단'!E16="","",'학생명단'!E16) | F16: =IF('학생명단'!F16="","",'학생명단'!F16) | G16: ='공수1'!Y16 | H16: ='공수2'!Y16 | I16: =IF(AND(G16="",H16=""),"",N(G16)*'설정'!$C$13+N(H16)*'설정'!$C$14) | J16: =IF(I16="","",COUNTIF($I$7:$I$156,">"&I16)+1) | K16: =IF(I16="","",IF(IF(COUNT('설정'!$C$6:$F$6)=0,AND(G16<>"",H16<>""),OR(AND('설정'!$C$6<>"",G16<>"",N(G16)>='설정'!$C$6),AND('설정'!$D$6<>"",AND(G16<>"",H16<>""),(N(G16)+N(H16))>='설정'!$D$6),AND('설정'!$E$6<>"",OR(AND(G16<>"",N(G16)<='설정'!$E$6),AND(H16<>"",N(H16)<='설정'!$E$6))),AND('설정'!$F$6<>"",AND(G16<>"",H16<>""),(N(G16)+N(H16))<='설정'!$F$6))),'설정'!$B$6,IF(IF(COUNT('설정'!$C$7:$F$7)=0,AND(G16<>"",H16<>""),OR(AND('설정'!$C$7<>"",G16<>"",N(G16)>='설정'!$C$7),AND('설정'!$D$7<>"",AND(G16<>"",H16<>""),(N(G16)+N(H16))>='설정'!$D$7),AND('설정'!$E$7<>"",OR(AND(G16<>"",N(G16)<='설정'!$E$7),AND(H16<>"",N(H16)<='설정'!$E$7))),AND('설정'!$F$7<>"",AND(G16<>"",H16<>""),(N(G16)+N(H16))<='설정'!$F$7))),'설정'!$B$7,IF(IF(COUNT('설정'!$C$8:$F$8)=0,AND(G16<>"",H16<>""),OR(AND('설정'!$C$8<>"",G16<>"",N(G16)>='설정'!$C$8),AND('설정'!$D$8<>"",AND(G16<>"",H16<>""),(N(G16)+N(H16))>='설정'!$D$8),AND('설정'!$E$8<>"",OR(AND(G16<>"",N(G16)<='설정'!$E$8),AND(H16<>"",N(H16)<='설정'!$E$8))),AND('설정'!$F$8<>"",AND(G16<>"",H16<>""),(N(G16)+N(H16))<='설정'!$F$8))),'설정'!$B$8,'설정'!$B$9)))) | L16: =IF(OR(G16="",H16=""),"",IF(SUMPRODUCT(ISNUMBER('설정'!$C$6:$C$8)*(ABS(G16-'설정'!$C$6:$C$8)<='설정'!$C$15))+SUMPRODUCT(ISNUMBER('설정'!$D$6:$D$8)*(ABS((G16+H16)-'설정'!$D$6:$D$8)<='설정'!$C$15))+SUMPRODUCT(ISNUMBER('설정'!$F$6:$F$8)*(ABS((G16+H16)-'설정'!$F$6:$F$8)<='설정'!$C$15))+SUMPRODUCT(ISNUMBER('설정'!$E$6:$E$8)*(ABS(G16-'설정'!$E$6:$E$8)<='설정'!$C$15))+SUMPRODUCT(ISNUMBER('설정'!$E$6:$E$8)*(ABS(H16-'설정'!$E$6:$E$8)<='설정'!$C$15))>0,"경계","")) | O16: =IF(M16<>"",M16,K16) | P16: =IF(I16="","",IF(G16="","공수1 미응시",IF(H16="","공수2 미응시",""))) | Q16: =IF(J16="","",J16+ROW()/100000)
A17: 11 | B17: =IF('학생명단'!B17="","",'학생명단'!B17) | C17: =IF('학생명단'!C17="","",'학생명단'!C17) | D17: =IF('학생명단'!D17="","",'학생명단'!D17) | E17: =IF('학생명단'!E17="","",'학생명단'!E17) | F17: =IF('학생명단'!F17="","",'학생명단'!F17) | G17: ='공수1'!Y17 | H17: ='공수2'!Y17 | I17: =IF(AND(G17="",H17=""),"",N(G17)*'설정'!$C$13+N(H17)*'설정'!$C$14) | J17: =IF(I17="","",COUNTIF($I$7:$I$156,">"&I17)+1) | K17: =IF(I17="","",IF(IF(COUNT('설정'!$C$6:$F$6)=0,AND(G17<>"",H17<>""),OR(AND('설정'!$C$6<>"",G17<>"",N(G17)>='설정'!$C$6),AND('설정'!$D$6<>"",AND(G17<>"",H17<>""),(N(G17)+N(H17))>='설정'!$D$6),AND('설정'!$E$6<>"",OR(AND(G17<>"",N(G17)<='설정'!$E$6),AND(H17<>"",N(H17)<='설정'!$E$6))),AND('설정'!$F$6<>"",AND(G17<>"",H17<>""),(N(G17)+N(H17))<='설정'!$F$6))),'설정'!$B$6,IF(IF(COUNT('설정'!$C$7:$F$7)=0,AND(G17<>"",H17<>""),OR(AND('설정'!$C$7<>"",G17<>"",N(G17)>='설정'!$C$7),AND('설정'!$D$7<>"",AND(G17<>"",H17<>""),(N(G17)+N(H17))>='설정'!$D$7),AND('설정'!$E$7<>"",OR(AND(G17<>"",N(G17)<='설정'!$E$7),AND(H17<>"",N(H17)<='설정'!$E$7))),AND('설정'!$F$7<>"",AND(G17<>"",H17<>""),(N(G17)+N(H17))<='설정'!$F$7))),'설정'!$B$7,IF(IF(COUNT('설정'!$C$8:$F$8)=0,AND(G17<>"",H17<>""),OR(AND('설정'!$C$8<>"",G17<>"",N(G17)>='설정'!$C$8),AND('설정'!$D$8<>"",AND(G17<>"",H17<>""),(N(G17)+N(H17))>='설정'!$D$8),AND('설정'!$E$8<>"",OR(AND(G17<>"",N(G17)<='설정'!$E$8),AND(H17<>"",N(H17)<='설정'!$E$8))),AND('설정'!$F$8<>"",AND(G17<>"",H17<>""),(N(G17)+N(H17))<='설정'!$F$8))),'설정'!$B$8,'설정'!$B$9)))) | L17: =IF(OR(G17="",H17=""),"",IF(SUMPRODUCT(ISNUMBER('설정'!$C$6:$C$8)*(ABS(G17-'설정'!$C$6:$C$8)<='설정'!$C$15))+SUMPRODUCT(ISNUMBER('설정'!$D$6:$D$8)*(ABS((G17+H17)-'설정'!$D$6:$D$8)<='설정'!$C$15))+SUMPRODUCT(ISNUMBER('설정'!$F$6:$F$8)*(ABS((G17+H17)-'설정'!$F$6:$F$8)<='설정'!$C$15))+SUMPRODUCT(ISNUMBER('설정'!$E$6:$E$8)*(ABS(G17-'설정'!$E$6:$E$8)<='설정'!$C$15))+SUMPRODUCT(ISNUMBER('설정'!$E$6:$E$8)*(ABS(H17-'설정'!$E$6:$E$8)<='설정'!$C$15))>0,"경계","")) | O17: =IF(M17<>"",M17,K17) | P17: =IF(I17="","",IF(G17="","공수1 미응시",IF(H17="","공수2 미응시",""))) | Q17: =IF(J17="","",J17+ROW()/100000)
A18: 12 | B18: =IF('학생명단'!B18="","",'학생명단'!B18) | C18: =IF('학생명단'!C18="","",'학생명단'!C18) | D18: =IF('학생명단'!D18="","",'학생명단'!D18) | E18: =IF('학생명단'!E18="","",'학생명단'!E18) | F18: =IF('학생명단'!F18="","",'학생명단'!F18) | G18: ='공수1'!Y18 | H18: ='공수2'!Y18 | I18: =IF(AND(G18="",H18=""),"",N(G18)*'설정'!$C$13+N(H18)*'설정'!$C$14) | J18: =IF(I18="","",COUNTIF($I$7:$I$156,">"&I18)+1) | K18: =IF(I18="","",IF(IF(COUNT('설정'!$C$6:$F$6)=0,AND(G18<>"",H18<>""),OR(AND('설정'!$C$6<>"",G18<>"",N(G18)>='설정'!$C$6),AND('설정'!$D$6<>"",AND(G18<>"",H18<>""),(N(G18)+N(H18))>='설정'!$D$6),AND('설정'!$E$6<>"",OR(AND(G18<>"",N(G18)<='설정'!$E$6),AND(H18<>"",N(H18)<='설정'!$E$6))),AND('설정'!$F$6<>"",AND(G18<>"",H18<>""),(N(G18)+N(H18))<='설정'!$F$6))),'설정'!$B$6,IF(IF(COUNT('설정'!$C$7:$F$7)=0,AND(G18<>"",H18<>""),OR(AND('설정'!$C$7<>"",G18<>"",N(G18)>='설정'!$C$7),AND('설정'!$D$7<>"",AND(G18<>"",H18<>""),(N(G18)+N(H18))>='설정'!$D$7),AND('설정'!$E$7<>"",OR(AND(G18<>"",N(G18)<='설정'!$E$7),AND(H18<>"",N(H18)<='설정'!$E$7))),AND('설정'!$F$7<>"",AND(G18<>"",H18<>""),(N(G18)+N(H18))<='설정'!$F$7))),'설정'!$B$7,IF(IF(COUNT('설정'!$C$8:$F$8)=0,AND(G18<>"",H18<>""),OR(AND('설정'!$C$8<>"",G18<>"",N(G18)>='설정'!$C$8),AND('설정'!$D$8<>"",AND(G18<>"",H18<>""),(N(G18)+N(H18))>='설정'!$D$8),AND('설정'!$E$8<>"",OR(AND(G18<>"",N(G18)<='설정'!$E$8),AND(H18<>"",N(H18)<='설정'!$E$8))),AND('설정'!$F$8<>"",AND(G18<>"",H18<>""),(N(G18)+N(H18))<='설정'!$F$8))),'설정'!$B$8,'설정'!$B$9)))) | L18: =IF(OR(G18="",H18=""),"",IF(SUMPRODUCT(ISNUMBER('설정'!$C$6:$C$8)*(ABS(G18-'설정'!$C$6:$C$8)<='설정'!$C$15))+SUMPRODUCT(ISNUMBER('설정'!$D$6:$D$8)*(ABS((G18+H18)-'설정'!$D$6:$D$8)<='설정'!$C$15))+SUMPRODUCT(ISNUMBER('설정'!$F$6:$F$8)*(ABS((G18+H18)-'설정'!$F$6:$F$8)<='설정'!$C$15))+SUMPRODUCT(ISNUMBER('설정'!$E$6:$E$8)*(ABS(G18-'설정'!$E$6:$E$8)<='설정'!$C$15))+SUMPRODUCT(ISNUMBER('설정'!$E$6:$E$8)*(ABS(H18-'설정'!$E$6:$E$8)<='설정'!$C$15))>0,"경계","")) | O18: =IF(M18<>"",M18,K18) | P18: =IF(I18="","",IF(G18="","공수1 미응시",IF(H18="","공수2 미응시",""))) | Q18: =IF(J18="","",J18+ROW()/100000)
A19: 13 | B19: =IF('학생명단'!B19="","",'학생명단'!B19) | C19: =IF('학생명단'!C19="","",'학생명단'!C19) | D19: =IF('학생명단'!D19="","",'학생명단'!D19) | E19: =IF('학생명단'!E19="","",'학생명단'!E19) | F19: =IF('학생명단'!F19="","",'학생명단'!F19) | G19: ='공수1'!Y19 | H19: ='공수2'!Y19 | I19: =IF(AND(G19="",H19=""),"",N(G19)*'설정'!$C$13+N(H19)*'설정'!$C$14) | J19: =IF(I19="","",COUNTIF($I$7:$I$156,">"&I19)+1) | K19: =IF(I19="","",IF(IF(COUNT('설정'!$C$6:$F$6)=0,AND(G19<>"",H19<>""),OR(AND('설정'!$C$6<>"",G19<>"",N(G19)>='설정'!$C$6),AND('설정'!$D$6<>"",AND(G19<>"",H19<>""),(N(G19)+N(H19))>='설정'!$D$6),AND('설정'!$E$6<>"",OR(AND(G19<>"",N(G19)<='설정'!$E$6),AND(H19<>"",N(H19)<='설정'!$E$6))),AND('설정'!$F$6<>"",AND(G19<>"",H19<>""),(N(G19)+N(H19))<='설정'!$F$6))),'설정'!$B$6,IF(IF(COUNT('설정'!$C$7:$F$7)=0,AND(G19<>"",H19<>""),OR(AND('설정'!$C$7<>"",G19<>"",N(G19)>='설정'!$C$7),AND('설정'!$D$7<>"",AND(G19<>"",H19<>""),(N(G19)+N(H19))>='설정'!$D$7),AND('설정'!$E$7<>"",OR(AND(G19<>"",N(G19)<='설정'!$E$7),AND(H19<>"",N(H19)<='설정'!$E$7))),AND('설정'!$F$7<>"",AND(G19<>"",H19<>""),(N(G19)+N(H19))<='설정'!$F$7))),'설정'!$B$7,IF(IF(COUNT('설정'!$C$8:$F$8)=0,AND(G19<>"",H19<>""),OR(AND('설정'!$C$8<>"",G19<>"",N(G19)>='설정'!$C$8),AND('설정'!$D$8<>"",AND(G19<>"",H19<>""),(N(G19)+N(H19))>='설정'!$D$8),AND('설정'!$E$8<>"",OR(AND(G19<>"",N(G19)<='설정'!$E$8),AND(H19<>"",N(H19)<='설정'!$E$8))),AND('설정'!$F$8<>"",AND(G19<>"",H19<>""),(N(G19)+N(H19))<='설정'!$F$8))),'설정'!$B$8,'설정'!$B$9)))) | L19: =IF(OR(G19="",H19=""),"",IF(SUMPRODUCT(ISNUMBER('설정'!$C$6:$C$8)*(ABS(G19-'설정'!$C$6:$C$8)<='설정'!$C$15))+SUMPRODUCT(ISNUMBER('설정'!$D$6:$D$8)*(ABS((G19+H19)-'설정'!$D$6:$D$8)<='설정'!$C$15))+SUMPRODUCT(ISNUMBER('설정'!$F$6:$F$8)*(ABS((G19+H19)-'설정'!$F$6:$F$8)<='설정'!$C$15))+SUMPRODUCT(ISNUMBER('설정'!$E$6:$E$8)*(ABS(G19-'설정'!$E$6:$E$8)<='설정'!$C$15))+SUMPRODUCT(ISNUMBER('설정'!$E$6:$E$8)*(ABS(H19-'설정'!$E$6:$E$8)<='설정'!$C$15))>0,"경계","")) | O19: =IF(M19<>"",M19,K19) | P19: =IF(I19="","",IF(G19="","공수1 미응시",IF(H19="","공수2 미응시",""))) | Q19: =IF(J19="","",J19+ROW()/100000)
A20: 14 | B20: =IF('학생명단'!B20="","",'학생명단'!B20) | C20: =IF('학생명단'!C20="","",'학생명단'!C20) | D20: =IF('학생명단'!D20="","",'학생명단'!D20) | E20: =IF('학생명단'!E20="","",'학생명단'!E20) | F20: =IF('학생명단'!F20="","",'학생명단'!F20) | G20: ='공수1'!Y20 | H20: ='공수2'!Y20 | I20: =IF(AND(G20="",H20=""),"",N(G20)*'설정'!$C$13+N(H20)*'설정'!$C$14) | J20: =IF(I20="","",COUNTIF($I$7:$I$156,">"&I20)+1) | K20: =IF(I20="","",IF(IF(COUNT('설정'!$C$6:$F$6)=0,AND(G20<>"",H20<>""),OR(AND('설정'!$C$6<>"",G20<>"",N(G20)>='설정'!$C$6),AND('설정'!$D$6<>"",AND(G20<>"",H20<>""),(N(G20)+N(H20))>='설정'!$D$6),AND('설정'!$E$6<>"",OR(AND(G20<>"",N(G20)<='설정'!$E$6),AND(H20<>"",N(H20)<='설정'!$E$6))),AND('설정'!$F$6<>"",AND(G20<>"",H20<>""),(N(G20)+N(H20))<='설정'!$F$6))),'설정'!$B$6,IF(IF(COUNT('설정'!$C$7:$F$7)=0,AND(G20<>"",H20<>""),OR(AND('설정'!$C$7<>"",G20<>"",N(G20)>='설정'!$C$7),AND('설정'!$D$7<>"",AND(G20<>"",H20<>""),(N(G20)+N(H20))>='설정'!$D$7),AND('설정'!$E$7<>"",OR(AND(G20<>"",N(G20)<='설정'!$E$7),AND(H20<>"",N(H20)<='설정'!$E$7))),AND('설정'!$F$7<>"",AND(G20<>"",H20<>""),(N(G20)+N(H20))<='설정'!$F$7))),'설정'!$B$7,IF(IF(COUNT('설정'!$C$8:$F$8)=0,AND(G20<>"",H20<>""),OR(AND('설정'!$C$8<>"",G20<>"",N(G20)>='설정'!$C$8),AND('설정'!$D$8<>"",AND(G20<>"",H20<>""),(N(G20)+N(H20))>='설정'!$D$8),AND('설정'!$E$8<>"",OR(AND(G20<>"",N(G20)<='설정'!$E$8),AND(H20<>"",N(H20)<='설정'!$E$8))),AND('설정'!$F$8<>"",AND(G20<>"",H20<>""),(N(G20)+N(H20))<='설정'!$F$8))),'설정'!$B$8,'설정'!$B$9)))) | L20: =IF(OR(G20="",H20=""),"",IF(SUMPRODUCT(ISNUMBER('설정'!$C$6:$C$8)*(ABS(G20-'설정'!$C$6:$C$8)<='설정'!$C$15))+SUMPRODUCT(ISNUMBER('설정'!$D$6:$D$8)*(ABS((G20+H20)-'설정'!$D$6:$D$8)<='설정'!$C$15))+SUMPRODUCT(ISNUMBER('설정'!$F$6:$F$8)*(ABS((G20+H20)-'설정'!$F$6:$F$8)<='설정'!$C$15))+SUMPRODUCT(ISNUMBER('설정'!$E$6:$E$8)*(ABS(G20-'설정'!$E$6:$E$8)<='설정'!$C$15))+SUMPRODUCT(ISNUMBER('설정'!$E$6:$E$8)*(ABS(H20-'설정'!$E$6:$E$8)<='설정'!$C$15))>0,"경계","")) | O20: =IF(M20<>"",M20,K20) | P20: =IF(I20="","",IF(G20="","공수1 미응시",IF(H20="","공수2 미응시",""))) | Q20: =IF(J20="","",J20+ROW()/100000)
A21: 15 | B21: =IF('학생명단'!B21="","",'학생명단'!B21) | C21: =IF('학생명단'!C21="","",'학생명단'!C21) | D21: =IF('학생명단'!D21="","",'학생명단'!D21) | E21: =IF('학생명단'!E21="","",'학생명단'!E21) | F21: =IF('학생명단'!F21="","",'학생명단'!F21) | G21: ='공수1'!Y21 | H21: ='공수2'!Y21 | I21: =IF(AND(G21="",H21=""),"",N(G21)*'설정'!$C$13+N(H21)*'설정'!$C$14) | J21: =IF(I21="","",COUNTIF($I$7:$I$156,">"&I21)+1) | K21: =IF(I21="","",IF(IF(COUNT('설정'!$C$6:$F$6)=0,AND(G21<>"",H21<>""),OR(AND('설정'!$C$6<>"",G21<>"",N(G21)>='설정'!$C$6),AND('설정'!$D$6<>"",AND(G21<>"",H21<>""),(N(G21)+N(H21))>='설정'!$D$6),AND('설정'!$E$6<>"",OR(AND(G21<>"",N(G21)<='설정'!$E$6),AND(H21<>"",N(H21)<='설정'!$E$6))),AND('설정'!$F$6<>"",AND(G21<>"",H21<>""),(N(G21)+N(H21))<='설정'!$F$6))),'설정'!$B$6,IF(IF(COUNT('설정'!$C$7:$F$7)=0,AND(G21<>"",H21<>""),OR(AND('설정'!$C$7<>"",G21<>"",N(G21)>='설정'!$C$7),AND('설정'!$D$7<>"",AND(G21<>"",H21<>""),(N(G21)+N(H21))>='설정'!$D$7),AND('설정'!$E$7<>"",OR(AND(G21<>"",N(G21)<='설정'!$E$7),AND(H21<>"",N(H21)<='설정'!$E$7))),AND('설정'!$F$7<>"",AND(G21<>"",H21<>""),(N(G21)+N(H21))<='설정'!$F$7))),'설정'!$B$7,IF(IF(COUNT('설정'!$C$8:$F$8)=0,AND(G21<>"",H21<>""),OR(AND('설정'!$C$8<>"",G21<>"",N(G21)>='설정'!$C$8),AND('설정'!$D$8<>"",AND(G21<>"",H21<>""),(N(G21)+N(H21))>='설정'!$D$8),AND('설정'!$E$8<>"",OR(AND(G21<>"",N(G21)<='설정'!$E$8),AND(H21<>"",N(H21)<='설정'!$E$8))),AND('설정'!$F$8<>"",AND(G21<>"",H21<>""),(N(G21)+N(H21))<='설정'!$F$8))),'설정'!$B$8,'설정'!$B$9)))) | L21: =IF(OR(G21="",H21=""),"",IF(SUMPRODUCT(ISNUMBER('설정'!$C$6:$C$8)*(ABS(G21-'설정'!$C$6:$C$8)<='설정'!$C$15))+SUMPRODUCT(ISNUMBER('설정'!$D$6:$D$8)*(ABS((G21+H21)-'설정'!$D$6:$D$8)<='설정'!$C$15))+SUMPRODUCT(ISNUMBER('설정'!$F$6:$F$8)*(ABS((G21+H21)-'설정'!$F$6:$F$8)<='설정'!$C$15))+SUMPRODUCT(ISNUMBER('설정'!$E$6:$E$8)*(ABS(G21-'설정'!$E$6:$E$8)<='설정'!$C$15))+SUMPRODUCT(ISNUMBER('설정'!$E$6:$E$8)*(ABS(H21-'설정'!$E$6:$E$8)<='설정'!$C$15))>0,"경계","")) | O21: =IF(M21<>"",M21,K21) | P21: =IF(I21="","",IF(G21="","공수1 미응시",IF(H21="","공수2 미응시",""))) | Q21: =IF(J21="","",J21+ROW()/100000)
A22: 16 | B22: =IF('학생명단'!B22="","",'학생명단'!B22) | C22: =IF('학생명단'!C22="","",'학생명단'!C22) | D22: =IF('학생명단'!D22="","",'학생명단'!D22) | E22: =IF('학생명단'!E22="","",'학생명단'!E22) | F22: =IF('학생명단'!F22="","",'학생명단'!F22) | G22: ='공수1'!Y22 | H22: ='공수2'!Y22 | I22: =IF(AND(G22="",H22=""),"",N(G22)*'설정'!$C$13+N(H22)*'설정'!$C$14) | J22: =IF(I22="","",COUNTIF($I$7:$I$156,">"&I22)+1) | K22: =IF(I22="","",IF(IF(COUNT('설정'!$C$6:$F$6)=0,AND(G22<>"",H22<>""),OR(AND('설정'!$C$6<>"",G22<>"",N(G22)>='설정'!$C$6),AND('설정'!$D$6<>"",AND(G22<>"",H22<>""),(N(G22)+N(H22))>='설정'!$D$6),AND('설정'!$E$6<>"",OR(AND(G22<>"",N(G22)<='설정'!$E$6),AND(H22<>"",N(H22)<='설정'!$E$6))),AND('설정'!$F$6<>"",AND(G22<>"",H22<>""),(N(G22)+N(H22))<='설정'!$F$6))),'설정'!$B$6,IF(IF(COUNT('설정'!$C$7:$F$7)=0,AND(G22<>"",H22<>""),OR(AND('설정'!$C$7<>"",G22<>"",N(G22)>='설정'!$C$7),AND('설정'!$D$7<>"",AND(G22<>"",H22<>""),(N(G22)+N(H22))>='설정'!$D$7),AND('설정'!$E$7<>"",OR(AND(G22<>"",N(G22)<='설정'!$E$7),AND(H22<>"",N(H22)<='설정'!$E$7))),AND('설정'!$F$7<>"",AND(G22<>"",H22<>""),(N(G22)+N(H22))<='설정'!$F$7))),'설정'!$B$7,IF(IF(COUNT('설정'!$C$8:$F$8)=0,AND(G22<>"",H22<>""),OR(AND('설정'!$C$8<>"",G22<>"",N(G22)>='설정'!$C$8),AND('설정'!$D$8<>"",AND(G22<>"",H22<>""),(N(G22)+N(H22))>='설정'!$D$8),AND('설정'!$E$8<>"",OR(AND(G22<>"",N(G22)<='설정'!$E$8),AND(H22<>"",N(H22)<='설정'!$E$8))),AND('설정'!$F$8<>"",AND(G22<>"",H22<>""),(N(G22)+N(H22))<='설정'!$F$8))),'설정'!$B$8,'설정'!$B$9)))) | L22: =IF(OR(G22="",H22=""),"",IF(SUMPRODUCT(ISNUMBER('설정'!$C$6:$C$8)*(ABS(G22-'설정'!$C$6:$C$8)<='설정'!$C$15))+SUMPRODUCT(ISNUMBER('설정'!$D$6:$D$8)*(ABS((G22+H22)-'설정'!$D$6:$D$8)<='설정'!$C$15))+SUMPRODUCT(ISNUMBER('설정'!$F$6:$F$8)*(ABS((G22+H22)-'설정'!$F$6:$F$8)<='설정'!$C$15))+SUMPRODUCT(ISNUMBER('설정'!$E$6:$E$8)*(ABS(G22-'설정'!$E$6:$E$8)<='설정'!$C$15))+SUMPRODUCT(ISNUMBER('설정'!$E$6:$E$8)*(ABS(H22-'설정'!$E$6:$E$8)<='설정'!$C$15))>0,"경계","")) | O22: =IF(M22<>"",M22,K22) | P22: =IF(I22="","",IF(G22="","공수1 미응시",IF(H22="","공수2 미응시",""))) | Q22: =IF(J22="","",J22+ROW()/100000)
A23: 17 | B23: =IF('학생명단'!B23="","",'학생명단'!B23) | C23: =IF('학생명단'!C23="","",'학생명단'!C23) | D23: =IF('학생명단'!D23="","",'학생명단'!D23) | E23: =IF('학생명단'!E23="","",'학생명단'!E23) | F23: =IF('학생명단'!F23="","",'학생명단'!F23) | G23: ='공수1'!Y23 | H23: ='공수2'!Y23 | I23: =IF(AND(G23="",H23=""),"",N(G23)*'설정'!$C$13+N(H23)*'설정'!$C$14) | J23: =IF(I23="","",COUNTIF($I$7:$I$156,">"&I23)+1) | K23: =IF(I23="","",IF(IF(COUNT('설정'!$C$6:$F$6)=0,AND(G23<>"",H23<>""),OR(AND('설정'!$C$6<>"",G23<>"",N(G23)>='설정'!$C$6),AND('설정'!$D$6<>"",AND(G23<>"",H23<>""),(N(G23)+N(H23))>='설정'!$D$6),AND('설정'!$E$6<>"",OR(AND(G23<>"",N(G23)<='설정'!$E$6),AND(H23<>"",N(H23)<='설정'!$E$6))),AND('설정'!$F$6<>"",AND(G23<>"",H23<>""),(N(G23)+N(H23))<='설정'!$F$6))),'설정'!$B$6,IF(IF(COUNT('설정'!$C$7:$F$7)=0,AND(G23<>"",H23<>""),OR(AND('설정'!$C$7<>"",G23<>"",N(G23)>='설정'!$C$7),AND('설정'!$D$7<>"",AND(G23<>"",H23<>""),(N(G23)+N(H23))>='설정'!$D$7),AND('설정'!$E$7<>"",OR(AND(G23<>"",N(G23)<='설정'!$E$7),AND(H23<>"",N(H23)<='설정'!$E$7))),AND('설정'!$F$7<>"",AND(G23<>"",H23<>""),(N(G23)+N(H23))<='설정'!$F$7))),'설정'!$B$7,IF(IF(COUNT('설정'!$C$8:$F$8)=0,AND(G23<>"",H23<>""),OR(AND('설정'!$C$8<>"",G23<>"",N(G23)>='설정'!$C$8),AND('설정'!$D$8<>"",AND(G23<>"",H23<>""),(N(G23)+N(H23))>='설정'!$D$8),AND('설정'!$E$8<>"",OR(AND(G23<>"",N(G23)<='설정'!$E$8),AND(H23<>"",N(H23)<='설정'!$E$8))),AND('설정'!$F$8<>"",AND(G23<>"",H23<>""),(N(G23)+N(H23))<='설정'!$F$8))),'설정'!$B$8,'설정'!$B$9)))) | L23: =IF(OR(G23="",H23=""),"",IF(SUMPRODUCT(ISNUMBER('설정'!$C$6:$C$8)*(ABS(G23-'설정'!$C$6:$C$8)<='설정'!$C$15))+SUMPRODUCT(ISNUMBER('설정'!$D$6:$D$8)*(ABS((G23+H23)-'설정'!$D$6:$D$8)<='설정'!$C$15))+SUMPRODUCT(ISNUMBER('설정'!$F$6:$F$8)*(ABS((G23+H23)-'설정'!$F$6:$F$8)<='설정'!$C$15))+SUMPRODUCT(ISNUMBER('설정'!$E$6:$E$8)*(ABS(G23-'설정'!$E$6:$E$8)<='설정'!$C$15))+SUMPRODUCT(ISNUMBER('설정'!$E$6:$E$8)*(ABS(H23-'설정'!$E$6:$E$8)<='설정'!$C$15))>0,"경계","")) | O23: =IF(M23<>"",M23,K23) | P23: =IF(I23="","",IF(G23="","공수1 미응시",IF(H23="","공수2 미응시",""))) | Q23: =IF(J23="","",J23+ROW()/100000)
A24: 18 | B24: =IF('학생명단'!B24="","",'학생명단'!B24) | C24: =IF('학생명단'!C24="","",'학생명단'!C24) | D24: =IF('학생명단'!D24="","",'학생명단'!D24) | E24: =IF('학생명단'!E24="","",'학생명단'!E24) | F24: =IF('학생명단'!F24="","",'학생명단'!F24) | G24: ='공수1'!Y24 | H24: ='공수2'!Y24 | I24: =IF(AND(G24="",H24=""),"",N(G24)*'설정'!$C$13+N(H24)*'설정'!$C$14) | J24: =IF(I24="","",COUNTIF($I$7:$I$156,">"&I24)+1) | K24: =IF(I24="","",IF(IF(COUNT('설정'!$C$6:$F$6)=0,AND(G24<>"",H24<>""),OR(AND('설정'!$C$6<>"",G24<>"",N(G24)>='설정'!$C$6),AND('설정'!$D$6<>"",AND(G24<>"",H24<>""),(N(G24)+N(H24))>='설정'!$D$6),AND('설정'!$E$6<>"",OR(AND(G24<>"",N(G24)<='설정'!$E$6),AND(H24<>"",N(H24)<='설정'!$E$6))),AND('설정'!$F$6<>"",AND(G24<>"",H24<>""),(N(G24)+N(H24))<='설정'!$F$6))),'설정'!$B$6,IF(IF(COUNT('설정'!$C$7:$F$7)=0,AND(G24<>"",H24<>""),OR(AND('설정'!$C$7<>"",G24<>"",N(G24)>='설정'!$C$7),AND('설정'!$D$7<>"",AND(G24<>"",H24<>""),(N(G24)+N(H24))>='설정'!$D$7),AND('설정'!$E$7<>"",OR(AND(G24<>"",N(G24)<='설정'!$E$7),AND(H24<>"",N(H24)<='설정'!$E$7))),AND('설정'!$F$7<>"",AND(G24<>"",H24<>""),(N(G24)+N(H24))<='설정'!$F$7))),'설정'!$B$7,IF(IF(COUNT('설정'!$C$8:$F$8)=0,AND(G24<>"",H24<>""),OR(AND('설정'!$C$8<>"",G24<>"",N(G24)>='설정'!$C$8),AND('설정'!$D$8<>"",AND(G24<>"",H24<>""),(N(G24)+N(H24))>='설정'!$D$8),AND('설정'!$E$8<>"",OR(AND(G24<>"",N(G24)<='설정'!$E$8),AND(H24<>"",N(H24)<='설정'!$E$8))),AND('설정'!$F$8<>"",AND(G24<>"",H24<>""),(N(G24)+N(H24))<='설정'!$F$8))),'설정'!$B$8,'설정'!$B$9)))) | L24: =IF(OR(G24="",H24=""),"",IF(SUMPRODUCT(ISNUMBER('설정'!$C$6:$C$8)*(ABS(G24-'설정'!$C$6:$C$8)<='설정'!$C$15))+SUMPRODUCT(ISNUMBER('설정'!$D$6:$D$8)*(ABS((G24+H24)-'설정'!$D$6:$D$8)<='설정'!$C$15))+SUMPRODUCT(ISNUMBER('설정'!$F$6:$F$8)*(ABS((G24+H24)-'설정'!$F$6:$F$8)<='설정'!$C$15))+SUMPRODUCT(ISNUMBER('설정'!$E$6:$E$8)*(ABS(G24-'설정'!$E$6:$E$8)<='설정'!$C$15))+SUMPRODUCT(ISNUMBER('설정'!$E$6:$E$8)*(ABS(H24-'설정'!$E$6:$E$8)<='설정'!$C$15))>0,"경계","")) | O24: =IF(M24<>"",M24,K24) | P24: =IF(I24="","",IF(G24="","공수1 미응시",IF(H24="","공수2 미응시",""))) | Q24: =IF(J24="","",J24+ROW()/100000)
